Workbook

Sheet TUGAS
C1: 1 | D1: 2 | E1: 3
C2: 6. Horizontal Analysis
C3: 2024 | D3: 2023 | E3: Membaik vs Memburuk? Analisa!
B4: 1. Rasio Profitabilitas
B5: 1.1 ROE (Return on Equity) | C5: ='Income Statement'!F52/(('Balance Sheet'!E130+'Balance Sheet'!F130)/2) -> 0.082514751 | D5: ='Income Statement'!E52/(('Balance Sheet'!E130+'Balance Sheet'!D130)/2) -> 0.083951836 | E5: Memburuk, Perusahaan kurang baik dalam mengelola modal sendiri sehingga semakin kurang efisien dalam menghasilkan laba
B6: 1.2 ROA (Return on Asset) | C6: ='Income Statement'!F52/(('Balance Sheet'!F2+'Balance Sheet'!E2)/2) -> 0.044509831 | D6: ='Income Statement'!E52/(('Balance Sheet'!E2+'Balance Sheet'!D2)/2) -> 0.044395352 | E6: Membaik, Perusahaan lebih baik dalam memanfaatkan assetnya sehingga lebih efisien dalam menghasilkan laba
B7: 1.3 BEP (Basic Earning Power) | C7: ='Income Statement'!F27/'Balance Sheet'!F2 -> 0.11657169 | D7: ='Income Statement'!E27/'Balance Sheet'!E2 -> 0.107962 | E7: Membaik, Aset digunakan lebih efektif menghasilkan laba operasi sebelum pajak dan bunga. Operasional makin efisien.
B8: 1.4 Gross Profit Margin | C8: ='Income Statement'!F2/'Income Statement'!F3 -> 0.34664249 | D8: ='Income Statement'!E2/'Income Statement'!E3 -> 0.32273325 | E8: Membaik, artinya biaya pokok penjualan menurun atau harga jual meningkat sehingga laba yang dihasilkan lebih tinggi | F8: 7. Vertical Analysis Terhadap Penjualan 2024
B9: 1.5. Operating Profit Margin | C9: ='Income Statement'!F27/'Income Statement'!F3 -> 0.20308115 | D9: ='Income Statement'!E27/'Income Statement'!E3 -> 0.18033803 | E9: Membaik, artinya perusahaan berhasil menurunkan biaya operasioanalnya sehingga laba yang dihasilkan lebih tinggi
B10: 1.6 Net Profit Margin | C10: ='Income Statement'!F52/'Income Statement'!F3 -> 0.074634004 | D10: ='Income Statement'!E52/'Income Statement'!E3 -> 0.072934249 | E10: Membaik, artinya perusahaan berhasil dalam mengelola biaya dan beban bunga sehingga laba yang dihasilkan meningkat
B11: 2. Rasio Solvency
B12: 2.1 DER (Debt to Earning Ratio) | C12: ='Balance Sheet'!F84/'Balance Sheet'!F130 -> 0.85072886 | D12: ='Balance Sheet'!E84/'Balance Sheet'!E130 -> 0.8572454 | E12: Membaik artinya modal sendiri perusahaan menguat sehingga ketergantungan hutang menurun
B13: 2.2 DAR (Debt to Asset Ratio) | C13: ='Balance Sheet'!F84/'Balance Sheet'!F2 -> 0.45967234 | D13: ='Balance Sheet'!E84/'Balance Sheet'!E2 -> 0.46156819 | E13: Membaik, artinya proposi aset yang dibayarkan hutang menurun sehingga resiko keuangan menurun
B14: 3. Rasio Likuiditas
B15: 3.1 Current Ratio | C15: ='Balance Sheet'!F3/'Balance Sheet'!F85 -> 2.1503571 | D15: ='Balance Sheet'!E3/'Balance Sheet'!E85 -> 1.9171426 | E15: Membaik, artinya likuiditas pada asset lancar membaik sehingga semakin jauh dari resiko gagal bayar.
B16: 3.2 Quick Ratio | C16: =('Balance Sheet'!F3-'Balance Sheet'!F11)/'Balance Sheet'!F85 -> 1.6358268 | D16: =('Balance Sheet'!E3-'Balance Sheet'!E11)/'Balance Sheet'!E85 -> 1.4317057 | E16: Membaik, Likuiditas tanpa bergantung pada stok membaik. Perusahaan semakin mampu memenuhi kewajiban jangka pendeknya dengan kas dan piutang tanpa terlalu bergantung pada penjualan persediaan.
B17: 3.3 Cash Ratio | C17: ='Balance Sheet'!F4/'Balance Sheet'!F85 -> 1.3000729 | D17: ='Balance Sheet'!E4/'Balance Sheet'!E85 -> 1.1146866 | E17: Membaik, likuiditas pada kas dan setara kas semakin baik yang artinya perusahaaan semakin mampu melunasi hutang lancarnya tanpa bergantung pada penagihan piutang dan penjualan persediaan.
B18: 4. Rasio Efisiensi
B19: 4.1 Inventory Turnover Ratio | C19: =-'Income Statement'!F5/(('Balance Sheet'!F11+'Balance Sheet'!E11)/2) -> 4.3149754 | D19: =-'Income Statement'!E6/(('Balance Sheet'!D11+'Balance Sheet'!E11)/2) -> 4.5485239 | E19: Memburuk, kemampuan perusahaan dalam mengelola persediaan semakin lemah sehingga perputaran persediaan melambat stok barang lebih lama tersimpan, bisa menambah biaya penyimapannan | F19: Note: ITO tidak sama dengan Days in Inventory
B20: 4.2 Days Sales Outstanding | C20: =((SUM('Balance Sheet'!E18:F18)/2)/'Income Statement'!F3)*365 -> 27.207973 | D20: =((SUM('Balance Sheet'!D18:E18)/2)/'Income Statement'!E3)*365 -> 26.56376 | E20: Memburuk, Piutang lebih lama tertagih dari periode sebelumnya, risiko gagal bayar naik.
B21: 4.3 Fixed Asset Turnover Ratio | C21: ='Income Statement'!F3/(('Balance Sheet'!F26+'Balance Sheet'!E26)/2) -> 0.94352475 | D21: ='Income Statement'!E3/(('Balance Sheet'!D26+'Balance Sheet'!E26)/2) -> 0.89706359 | E21: Membaik, artinya perusahaan semakin efisien dalam memanfatkan aset tetapnya untuk memperoleh pendapatan
B22: 4.4 Total Asset Turnover Ratio | C22: ='Income Statement'!F3/(('Balance Sheet'!F2+'Balance Sheet'!E2)/2) -> 0.59637469 | D22: ='Income Statement'!E3/(('Balance Sheet'!D2+'Balance Sheet'!E2)/2) -> 0.60870377 | E22: Memburuk, artinya perusahaan semakin kurang efisien sedikit dalam memanfatkan total assetnya untuk memperoleh pendapatan
F23: 4
B24: 5. Rasio Valuasi (Berdasarkan data bulanan IDX, Sep 2025, Q2 2025)
C25: INDF | D25: Industry | E25: Sub Industry | F25: Bandingkan! Analisa
B26: 5.1 Price to Book Value (PBV) | C26: ='IDX Financial Data and Ratio'!W338 -> 0.56 | D26: ='Summary Financial Ratio by Indu'!F14 -> 1.96 | E26: ='Summary Financial Ratio by Indu'!F16 -> 1.87 | F26: PBV sebesar 0,56 sementara standart industri sebesar 1,96 dan standart sub industri sebesar 1,87. artinya secara aseet harga saham perusahaan lebih murah dibandingkan pesaingnya. PBV yang rendah bisa menjadi tanda undervalution, artinya harga saham mungkin diperdagangkan dibawah nilai wajarnya. Rendahnya PBV menunjukan rendahnya kepercayaan pasar teradap kemampuan perusahaan memaksimalkan asetnya atau menghadapi tantangan pertumbuhan
B27: 5.2 Price to Earning Ratio (PER) | C27: ='IDX Financial Data and Ratio'!V338 -> 5.97 | D27: ='Summary Financial Ratio by Indu'!E14 -> 14.31 | E27: ='Summary Financial Ratio by Indu'!E16 -> 13.61 | F27: PER INDF sebesar 5,97 , sementara sub industri sebesar 13,61 dan industri 14,31 artinya Investor membayar lebih murah untuk setiap laba dibanding saham saham lain di industri itu. PER yang rendah bisa menjadi indikasi saham undervalued, karena investor membayar lebih murah untuk setiap laba yang dihasilkan. Rendahnya PER juga berarti pasar meniilai pertumbuhan yang laba yang lambat atau mengadapi resiko bisnis yang lebih tinggi.
B30: Analisis Vertikal
A31: 5 | B31: Profitabilitas | C31: Disemua level mulai dari kinerja produksi, operasi, keuangan semua terlihat membaik dan ini indikasi bahwa protabilitas perusahaan meningkat dan strategi manajemen yang dijalakan berdampak positif bagi perusahaan

Sheet IDX Financial Data and Ratio
B2: Financial Data and Ratio - Sep 2025
B4: No. | C4: Sector | D4: Sub Industry Code | E4: Sub Industry | F4: Code | G4: Stock Name | H4: Sharia | I4: FS Date | J4: Fiscal Year End | K4: Type of FS | L4: Auditor's Opinion | M4: billion IDR | R4: Profit for the Period | S4: Profit attr.to owner's | T4: Trailing
M5: Assets, b.IDR | N5: Liabilities, b.IDR | O5: Equity, b.IDR | P5: Sales, b.IDR | Q5: EBT, b.IDR | T5: EPS, IDR | U5: Book Value, IDR | V5: P/E Ratio, x | W5: Price to BV, x | X5: D/E Ratio, x | Y5: ROA, % | Z5: ROE, % | AA5: NPM, %
B6: 1 | C6: Energy | D6: A121 | E6: Coal Production | F6: AADI | G6: PT Adaro Andalan Indonesia Tbk | H6: S | I6: 06/30/2025 | J6: Dec | K6: LR | M6: 98815.45 | N6: 38336.5 | O6: 60478.95 | P6: 38947.18 | Q6: 9667.05 | R6: 7811.66 | S6: 6957.95 | T6: 1598.13 | U6: 7766.76 | V6: 4.66 | W6: 0.96 | X6: 0.63 | Y6: 12.5937 | Z6: 20.5766 | AA6: 31.9522
B7: 2 | C7: Energy | D7: A121 | E7: Coal Production | F7: ABMM | G7: ABM Investama Tbk | H7: S | I7: 06/30/2025 | J7: Dec | K7: U | M7: 33670.44 | N7: 19876.44 | O7: 13794 | P7: 8227.35 | Q7: 398.16 | R7: 448.28 | S7: 450.35 | T7: 438.33 | U7: 5010.23 | V7: 6.62 | W7: 0.58 | X7: 1.44 | Y7: 3.5842 | Z7: 8.7488 | AA7: 14.6682
B8: 3 | C8: Energy | D8: A121 | E8: Coal Production | F8: ADMR | G8: Adaro Minerals Indonesia Tbk | H8: S | I8: 06/30/2025 | J8: Dec | K8: LR | L8: WTM | M8: 39661.61 | N8: 14468.66 | O8: 25192.94 | P8: 7205.64 | Q8: 2810.57 | R8: 2254.29 | S8: 2280.37 | T8: 128.64 | U8: 616.23 | V8: 8.16 | W8: 1.7 | X8: 0.57 | Y8: 13.2596 | Z8: 20.8748 | AA8: 72.9841
B9: 4 | C9: Energy | D9: A121 | E9: Coal Production | F9: ADRO | G9: Alamtri Resources Indonesia Tbk | H9: S | I9: 06/30/2025 | J9: Dec | K9: LR | M9: 104002.66 | N9: 23021.3 | O9: 80981.36 | P9: 13921.17 | Q9: 4038.68 | R9: 3164.04 | S9: 2839.5 | T9: 421.06 | U9: 2755.43 | V9: 4.01 | W9: 0.61 | X9: 0.28 | Y9: 11.8984 | Z9: 15.2809 | AA9: 88.8912
B10: 5 | C10: Energy | D10: A121 | E10: Coal Production | F10: AIMS | G10: PT Artha Mahiya Investama Tbk | H10: S | I10: 06/30/2025 | J10: Dec | K10: U | M10: 4.33 | N10: 4.84 | O10: -0.52 | P10: 0.08 | Q10: -0.86 | R10: -0.86 | S10: -0.86 | T10: -7.22 | U10: -2.35 | V10: -54.85 | W10: -168.47 | X10: -9.36 | Y10: -36.7199 | Z10: - | AA10: -2016.7688
B11: 6 | C11: Energy | D11: A112 | E11: Oil & Gas Storage & Distribution | F11: AKRA | G11: AKR Corporindo Tbk. | H11: S | I11: 06/30/2025 | J11: Dec | K11: U | M11: 31794.53 | N11: 16816.38 | O11: 14978.15 | P11: 21417.87 | Q11: 1565.43 | R11: 1329.8 | S11: 1180.08 | T11: 119.67 | U11: 746.17 | V11: 10.11 | W11: 1.62 | X11: 1.12 | Y11: 7.5554 | Z11: 16.0381 | AA11: 11.2159
B12: 7 | C12: Energy | D12: A122 | E12: Coal Distribution | F12: ALII | G12: PT Ancara Logistics Indonesia Tbk | H12: - | I12: 06/30/2025 | J12: Dec | K12: A | L12: WTM | M12: 2622.89 | N12: 642.36 | O12: 1980.53 | P12: 544.88 | Q12: 272.08 | R12: 233.49 | S12: 208.17 | T12: 19.95 | U12: 125.15 | V12: 27.07 | W12: 4.31 | X12: 0.32 | Y12: 12.0368 | Z12: 15.9408 | AA12: 57.9418
B13: 8 | C13: Energy | D13: A131 | E13: Oil & Gas Drilling Service | F13: APEX | G13: Apexindo Pratama Duta Tbk | H13: - | I13: 06/30/2025 | J13: Dec | K13: U | M13: 3986.3 | N13: 2917.3 | O13: 1069 | P13: 695.64 | Q13: 37.75 | R13: 12.19 | S13: 12.19 | T13: 4.36 | U13: 301.43 | V13: 27.06 | W13: 0.39 | X13: 2.73 | Y13: 0.388 | Z13: 1.4469 | AA13: 2.2235
B14: 9 | C14: Energy | D14: A121 | E14: Coal Production | F14: ARII | G14: Atlas Resources Tbk | H14: S | I14: 06/30/2025 | J14: Dec | K14: U | L14: WTM | M14: 10202.97 | N14: 8985.92 | O14: 1217.05 | P14: 2658.02 | Q14: 44.02 | R14: 55.54 | S14: 63.06 | T14: 30.21 | U14: 354.72 | V14: 9.87 | W14: 0.84 | X14: 7.38 | Y14: 1.0157 | Z14: 8.5153 | AA14: 3.899
B15: 10 | C15: Energy | D15: A132 | E15: Oil, Gas & Coal Equipment & Services | F15: ARTI | G15: Ratu Prabu Energi Tbk | H15: - | I15: 06/30/2025 | J15: Dec | K15: U | M15: 529.69 | N15: 748.67 | O15: -218.98 | P15: 0.1 | Q15: -4.34 | R15: -4.34 | S15: -4.22 | T15: -0.81 | U15: -27.93 | V15: -2.47 | W15: -0.07 | X15: -3.42 | Y15: -1.1994 | Z15: - | AA15: -6491.9974
B16: 11 | C16: Energy | D16: A132 | E16: Oil, Gas & Coal Equipment & Services | F16: ATLA | G16: PT Atlantis Subsea Indonesia Tbk | H16: S | I16: 06/30/2025 | J16: Dec | K16: U | M16: 174.42 | N16: 9.37 | O16: 165.04 | P16: 50.73 | Q16: 3.58 | R16: 2.72 | S16: 2.72 | T16: 0.72 | U16: 26.62 | V16: 102.4 | W16: 2.78 | X16: 0.06 | Y16: 2.5685 | Z16: 2.7144 | AA16: 8.8302
B17: 12 | C17: Energy | D17: A122 | E17: Coal Distribution | F17: BBRM | G17: Pelayaran Nasional Bina Buana Raya Tbk | H17: S | I17: 06/30/2025 | J17: Dec | K17: U | M17: 739.77 | N17: 78.81 | O17: 660.96 | P17: 111.72 | Q17: 45.49 | R17: 44.19 | S17: 44.19 | T17: 11.58 | U17: 77.17 | V17: 7.42 | W17: 1.11 | X17: 0.12 | Y17: 13.2784 | Z17: 14.8617 | AA17: 87.9276
B18: 13 | C18: Energy | D18: A122 | E18: Coal Distribution | F18: BESS | G18: Batulicin Nusantara Maritim Tbk | H18: S | I18: 06/30/2025 | J18: Dec | K18: U | M18: 702.79 | N18: 59.72 | O18: 643.07 | P18: 177.79 | Q18: 46.9 | R18: 46.9 | S18: 46.88 | T18: 26.04 | U18: 186.91 | V18: 41.28 | W18: 5.75 | X18: 0.09 | Y18: 12.7485 | Z18: 13.9324 | AA18: 50.3931
B19: 14 | C19: Energy | D19: A122 | E19: Coal Distribution | F19: BIPI | G19: Astrindo Nusantara Infrastruktur Tbk | H19: - | I19: 06/30/2025 | J19: Dec | K19: U | M19: 26774.44 | N19: 17327.46 | O19: 9446.98 | P19: 2350.89 | Q19: -53.01 | R19: -148.21 | S19: -160.7 | T19: -2.92 | U19: 148.28 | V19: -34.96 | W19: 0.69 | X19: 1.83 | Y19: -0.6942 | Z19: -1.9676 | AA19: -7.9068
B20: 15 | C20: Energy | D20: A132 | E20: Oil, Gas & Coal Equipment & Services | F20: BOAT | G20: PT Newport Marine Services Tbk | H20: S | I20: 06/30/2025 | J20: Dec | K20: U | M20: 578.25 | N20: 184.07 | O20: 394.18 | P20: 122.86 | Q20: 6.66 | R20: 5.18 | S20: 5.18 | T20: 6.76 | U20: 112.57 | V20: 18.8 | W20: 1.13 | X20: 0.47 | Y20: 4.0915 | Z20: 6.0021 | AA20: 19.2576
B21: 16 | C21: Energy | D21: A121 | E21: Coal Production | F21: BOSS | G21: Borneo Olah Sarana Sukses Tbk | H21: - | I21: 09/30/2023 | J21: Dec | K21: U | M21: 630.57 | N21: 797.31 | O21: -166.74 | P21: 141.97 | Q21: -127.36 | R21: -127.36 | S21: -127.36 | T21: -130.09 | U21: -119.1 | V21: -0.38 | W21: -0.42 | X21: -4.78 | Y21: -28.8821 | Z21: - | AA21: -128.2803
B22: 17 | C22: Energy | D22: A122 | E22: Coal Distribution | F22: BSML | G22: Bintang Samudera Mandiri Lines Tbk | H22: S | I22: 06/30/2025 | J22: Dec | K22: U | M22: 227.85 | N22: 96.9 | O22: 130.95 | P22: 45.05 | Q22: 2.54 | R22: 2.04 | S22: 2.04 | T22: 2.81 | U22: 70.78 | V22: 43.74 | W22: 1.74 | X22: 0.74 | Y22: 2.2836 | Z22: 3.9735 | AA22: 11.5489
B23: 18 | C23: Energy | D23: A121 | E23: Coal Production | F23: BSSR | G23: Baramulti Suksessarana Tbk | H23: S | I23: 06/30/2025 | J23: Dec | K23: LR | L23: WTM | M23: 6808.19 | N23: 2040.84 | O23: 4767.35 | P23: 5297.53 | Q23: 928.31 | R23: 806.27 | S23: 806.26 | T23: 617.2 | U23: 1803.81 | V23: 6.34 | W23: 2.17 | X23: 0.43 | Y23: 23.7199 | Z23: 33.8741 | AA23: 30.484
B24: 19 | C24: Energy | D24: A112 | E24: Oil & Gas Storage & Distribution | F24: BULL | G24: Buana Lintas Lautan Tbk | H24: - | I24: 06/30/2025 | J24: Dec | K24: U | M24: 5309.54 | N24: 2585.68 | O24: 2723.86 | P24: 1135.38 | Q24: 131.78 | R24: 131.54 | S24: 131.89 | T24: 2.74 | U24: 193.38 | V24: 66.16 | W24: 0.94 | X24: 0.95 | Y24: 0.7258 | Z24: 1.4148 | AA24: 3.3943
B25: 20 | C25: Energy | D25: A121 | E25: Coal Production | F25: BUMI | G25: Bumi Resources Tbk | H25: S | I25: 06/30/2025 | J25: Dec | K25: U | M25: 63599.43 | N25: 18064.96 | O25: 45534.47 | P25: 11003.52 | Q25: 813.1 | R25: 625.79 | S25: 331.21 | T25: 0.08 | U25: 122.62 | V25: 1865.68 | W25: 1.22 | X25: 0.4 | Y25: 0.0466 | Z25: 0.0651 | AA25: 0.2695
B26: 21 | C26: Energy | D26: A121 | E26: Coal Production | F26: BYAN | G26: Bayan Resources Tbk | H26: S | I26: 06/30/2025 | J26: Dec | K26: U | M26: 51848.76 | N26: 14995.58 | O26: 36853.18 | P26: 26324.34 | Q26: 7523.61 | R26: 5786.85 | S26: 5668.66 | T26: 432.08 | U26: 1105.6 | V26: 42.35 | W26: 16.55 | X26: 0.41 | Y26: 27.7783 | Z26: 39.0813 | AA26: 54.7126
B27: 22 | C27: Energy | D27: A122 | E27: Coal Distribution | F27: CANI | G27: Capitol Nusantara Indonesia Tbk | H27: S | I27: 06/30/2025 | J27: Jun | K27: A | L27: WTM | M27: 147.12 | N27: 691.3 | O27: -544.18 | P27: 53.66 | Q27: -36.5 | R27: -36.93 | S27: -36.93 | T27: -44.32 | U27: -652.93 | V27: -1.22 | W27: -0.08 | X27: -1.27 | Y27: -25.1054 | Z27: - | AA27: -68.8252
B28: 23 | C28: Energy | D28: A122 | E28: Coal Distribution | F28: CBRE | G28: PT Cakra Buana Resources Energi Tbk | H28: S | I28: 06/30/2025 | J28: Dec | K28: U | M28: 328.39 | N28: 210.36 | O28: 118.02 | P28: 29.08 | Q28: 1.25 | R28: 0.9 | S28: 0.9 | T28: -10.34 | U28: 26.01 | V28: -64.77 | W28: 25.76 | X28: 1.78 | Y28: -14.2948 | Z28: -39.7745 | AA28: -161.4137
B29: 24 | C29: Energy | D29: A112 | E29: Oil & Gas Storage & Distribution | F29: CGAS | G29: PT Citra Nusantara Gemilang Tbk. | H29: S | I29: 06/30/2025 | J29: Dec | K29: U | M29: 386.7 | N29: 122.59 | O29: 264.12 | P29: 265.48 | Q29: 3.2 | R29: 2.21 | S29: 1.86 | T29: 2.45 | U29: 149.09 | V29: 60.53 | W29: 0.99 | X29: 0.46 | Y29: 1.1202 | Z29: 1.6401 | AA29: 1.6317
B30: 25 | C30: Energy | D30: A122 | E30: Coal Distribution | F30: CNKO | G30: Exploitasi Energi Indonesia Tbk | H30: - | I30: 06/30/2025 | J30: Dec | K30: U | M30: 1084.36 | N30: 2215.03 | O30: -1130.67 | P30: 1046.87 | Q30: 162.81 | R30: 126.76 | S30: 125.72 | T30: 21.31 | U30: -126.24 | V30: 4.6 | W30: -0.78 | X30: -1.96 | Y30: 17.6023 | Z30: - | AA30: 18.2326
B31: 26 | C31: Energy | D31: A121 | E31: Coal Production | F31: COAL | G31: PT Black Diamond Resources Tbk | H31: S | I31: 06/30/2025 | J31: Dec | K31: U | M31: 865.01 | N31: 485.81 | O31: 379.2 | P31: 162.94 | Q31: 22.46 | R31: 17.52 | S31: 17.36 | T31: 3.85 | U31: 60.67 | V31: 14.79 | W31: 0.94 | X31: 1.28 | Y31: 2.7839 | Z31: 6.3506 | AA31: 14.7792
B32: 27 | C32: Energy | D32: A121 | E32: Coal Production | F32: CUAN | G32: PT Petrindo Jaya Kreasi Tbk | H32: S | I32: 06/30/2025 | J32: Dec | K32: U | M32: 34615.43 | N32: 25521.77 | O32: 9093.66 | P32: 7500.65 | Q32: 92.97 | R32: 45.27 | S32: 31.54 | T32: 19.08 | U32: 80.89 | V32: 84.9 | W32: 20.03 | X32: 2.81 | Y32: 6.1971 | Z32: 23.5897 | AA32: 28.5997
B33: 28 | C33: Energy | D33: A132 | E33: Oil, Gas & Coal Equipment & Services | F33: DEWA | G33: Darma Henwa Tbk | H33: S | I33: 06/30/2025 | J33: Dec | K33: U | M33: 10043.49 | N33: 5155.86 | O33: 4887.62 | P33: 3108.83 | Q33: 226.96 | R33: 168.01 | S33: 168 | T33: 4.18 | U33: 120.13 | V33: 65.06 | W33: 2.26 | X33: 1.05 | Y33: 1.6936 | Z33: 3.4802 | AA33: 5.4714
B34: 29 | C34: Energy | D34: A132 | E34: Oil, Gas & Coal Equipment & Services | F34: DOID | G34: Delta Dunia Makmur Tbk | H34: - | I34: 06/30/2025 | J34: Dec | K34: A | L34: WTM | M34: 25546.29 | N34: 23908.96 | O34: 1637.33 | P34: 11852.02 | Q34: -1573.21 | R34: -1293.61 | S34: -1204.46 | T34: -230.01 | U34: 214 | V34: -1.59 | W34: 1.71 | X34: 14.6 | Y34: -6.8887 | Z34: -107.4808 | AA34: -14.8482
B35: 30 | C35: Energy | D35: A121 | E35: Coal Production | F35: DSSA | G35: Dian Swastatika Sentosa Tbk | H35: S | I35: 06/30/2025 | J35: Dec | K35: A | L35: WTM | M35: 63005.92 | N35: 30186.32 | O35: 32819.6 | P35: 21473.6 | Q35: 3602.89 | R35: 2777.86 | S35: 1575.81 | T35: 448.69 | U35: 4259.23 | V35: 236.69 | W35: 24.93 | X35: 0.92 | Y35: 5.4874 | Z35: 10.5345 | AA35: 16.1005
B36: 31 | C36: Energy | D36: A122 | E36: Coal Distribution | F36: DWGL | G36: Dwi Guna Laksana Tbk | H36: S | I36: 06/30/2025 | J36: Dec | K36: U | M36: 2024.33 | N36: 1658.55 | O36: 365.79 | P36: 1736.35 | Q36: 120.09 | R36: 90.74 | S36: 90.74 | T36: 18.86 | U36: 39.53 | V36: 32.08 | W36: 15.3 | X36: 4.53 | Y36: 8.62 | Z36: 47.7045 | AA36: 10.0497
B37: 32 | C37: Energy | D37: A131 | E37: Oil & Gas Drilling Service | F37: ELSA | G37: Elnusa Tbk | H37: S | I37: 06/30/2025 | J37: Dec | K37: U | M37: 10551.78 | N37: 5597.26 | O37: 4954.51 | P37: 6965.19 | Q37: 440.32 | R37: 336.48 | S37: 336.48 | T37: 83.19 | U37: 678.84 | V37: 5.94 | W37: 0.73 | X37: 1.13 | Y37: 5.7542 | Z37: 12.2548 | AA37: 8.7172
B38: 33 | C38: Energy | D38: A111 | E38: Oil & Gas Production & Refinery | F38: ENRG | G38: Energi Mega Persada Tbk | H38: S | I38: 06/30/2025 | J38: Dec | K38: A | L38: WTM | M38: 26280.54 | N38: 15037.71 | O38: 11242.83 | P38: 3881 | Q38: 947.33 | R38: 580.84 | S38: 579.86 | T38: 48.03 | U38: 432.48 | V38: 16.76 | W38: 1.86 | X38: 1.34 | Y38: 4.7508 | Z38: 11.1053 | AA38: 32.1707
B39: 34 | C39: Energy | D39: A122 | E39: Coal Distribution | F39: FIRE | G39: Alfa Energi Investama Tbk | H39: S | I39: 06/30/2025 | J39: Dec | K39: U | M39: 331.22 | N39: 96.81 | O39: 234.41 | P39: 183.88 | Q39: 4.2 | R39: -5.46 | S39: -5.45 | T39: 1.08 | U39: 158.88 | V39: 88.53 | W39: 0.6 | X39: 0.41 | Y39: 0.483 | Z39: 0.6825 | AA39: 0.8701
B40: 35 | C40: Energy | D40: A121 | E40: Coal Production | F40: GEMS | G40: Golden Energy Mines Tbk | H40: S | I40: 06/30/2025 | J40: Dec | K40: A | L40: WTM | M40: 16910.91 | N40: 7163.03 | O40: 9747.88 | P40: 18575.03 | Q40: 3231.49 | R40: 2478.46 | S40: 2461.8 | T40: 836.99 | U40: 1657.14 | V40: 10.69 | W40: 5.4 | X40: 0.73 | Y40: 29.1141 | Z40: 50.508 | AA40: 26.5058
B41: 36 | C41: Energy | D41: A121 | E41: Coal Production | F41: GTBO | G41: Garda Tujuh Buana Tbk | H41: S | I41: 06/30/2025 | J41: Dec | K41: U | M41: 852.22 | N41: 122.68 | O41: 729.54 | P41: 121.61 | Q41: -13.73 | R41: -13.73 | S41: -13.73 | T41: -40.52 | U41: 291.81 | V41: -5.18 | W41: 0.72 | X41: 0.17 | Y41: -11.8861 | Z41: -13.8848 | AA41: -83.2948
B42: 37 | C42: Energy | D42: A112 | E42: Oil & Gas Storage & Distribution | F42: GTSI | G42: GTS Internasional Tbk | H42: S | I42: 06/30/2025 | J42: Dec | K42: U | M42: 2087.71 | N42: 939.54 | O42: 1148.17 | P42: 276.05 | Q42: 73.64 | R42: 69.16 | S42: 60.92 | T42: 7.9 | U42: 72.58 | V42: 11.52 | W42: 1.25 | X42: 0.82 | Y42: 5.9863 | Z42: 10.885 | AA42: 45.2741
...

Sheet Summary Financial Ratio by Indu
B2: Summary Financial Ratio by Industry - Sep 2025
B4: Sector/Sub Sector | C4: EPS, IDR | D4: Book Value, IDR | E4: P/E Ratio, X | F4: Price to BV, X | G4: D/E Ratio, X
B5: A. Energy | C5: 16.63 | D5: 226.7 | E5: 13.14 | F5: 3.63 | G5: 0.57
B6: A1. Oil, Gas & Coal | C6: 18.18 | D6: 249.64 | E6: 13.01 | F6: 3.63 | G6: 0.6
B7: A2. Alternative Energy | C7: -28.95 | D7: 58.18 | E7: 34.67 | F7: 1.6 | G7: -9.29
B8: B. Basic Materials | C8: 5.9 | D8: 276.32 | E8: 14.04 | F8: 2.77 | G8: 0.62
B9: B1. Basic Materials | C9: 5.9 | D9: 276.32 | E9: 14.04 | F9: 2.77 | G9: 0.62
B10: C. Industrials | C10: 4.33 | D10: 137.03 | E10: 12.31 | F10: 1.11 | G10: 0.48
B11: C1. Industrial Goods | C11: 6.66 | D11: 134.86 | E11: 8.34 | F11: 1.9 | G11: 0.48
B12: C2. Industrial Services | C12: 8.01 | D12: 135.38 | E12: 16.67 | F12: 1.67 | G12: 0.43
B13: C3. Multi-sector Holdings | C13: 1.38 | D13: 469.86 | E13: 16.89 | F13: 0.76 | G13: 0.75
B14: D. Consumer Non-Cyclicals | C14: 14.53 | D14: 138.75 | E14: 14.31 | F14: 1.96 | G14: 0.73
B15: D1. Food & Staples Retailing | C15: 14.38 | D15: 189.13 | E15: 14.59 | F15: 2.75 | G15: 1.2
B16: D2. Food & Beverage | C16: 12.03 | D16: 132.44 | E16: 13.61 | F16: 1.87 | G16: 0.73
... B48: K2. Logistics & Deliveries | C48: 3.04 | D48: 112.79 | E48: 12.32 | F48: 1.05 | G48: 0.66
B50: Market PER | C50: 14.55
B51: Market PBV | C51: 2.42

Sheet Income Statement
A1: INDF_income-statement_Annual_As_Originally_Reported | B1: 2020 | C1: 2021 | D1: 2022 | E1: 2023 | F1: 2024 | G1: TTM
A2: Gross Profit | B2: 26755152000000 | C2: 32576751000000 | D2: 33835567000000 | E2: 36050469000000 | F2: 40136529000000 | G2: 40158876000000
A3: Total Revenue | B3: 81731469000000 | C3: 99345618000000 | D3: 110830272000000 | E3: 111703611000000 | F3: 115786525000000 | G3: 118333462000000
A4: Business Revenue | B4: 81731469000000 | C4: 99345618000000 | D4: 110830272000000 | E4: 111703611000000 | F4: 115786525000000 | G4: 118333462000000
A5: Cost of Revenue | B5: -54976317000000 | C5: -66768867000000 | D5: -76994705000000 | E5: -75653142000000 | F5: -75649996000000 | G5: -78174586000000
A6: Cost of Goods and Services | B6: -54976317000000 | C6: -66768867000000 | D6: -76994705000000 | E6: -75653142000000 | F6: -75649996000000 | G6: -78174586000000
A7: Operating Income/Expenses | B7: -13925847000000 | C7: -15093666000000 | D7: -15042968000000 | E7: -15906060000000 | F7: -16622468000000 | G7: -16832855000000
A8: Selling, General and Administrative Expenses | B8: -12814650000000 | C8: -13785818000000 | D8: -13938602000000 | E8: -15175375000000 | F8: -16111677000000 | G8: -15998800000000
A9: Staff Costs | B9: -4539280000000 | C9: -5081040000000 | D9: -4710590000000 | E9: -5256523000000 | F9: -5653308000000 | G9: -5527921000000
A10: Wages and Salaries | F10: -5048296000000
A11: Directors' Remuneration | F11: -605012000000
A12: General and Administrative Expenses | B12: -1467274000000 | C12: -1058252000000 | D12: -999782000000 | E12: -1154241000000 | F12: -696520000000 | G12: -512906000000
A13: Rent Expense | B13: -135819000000 | C13: -259298000000 | D13: -216689000000 | E13: -200352000000 | F13: -187161000000 | G13: -207701000000
A14: Selling and Marketing Expenses | B14: -6672277000000 | C14: -7165359000000 | D14: -8011541000000 | E14: -8564259000000 | F14: -9574688000000 | G14: -9735960000000
A15: Legal, Accounting, Auditing and Consulting Fee | C15: -221869000000
A16: Operation and Maintenance Expenses | B16: -339986000000 | C16: -333228000000 | D16: -323745000000 | E16: -325936000000 | F16: -324449000000 | G16: -331140000000
A17: Depreciation, Amortization and Depletion | B17: -748281000000 | C17: -799718000000 | D17: -825673000000 | E17: -721863000000 | F17: -720272000000 | G17: -716018000000
A18: Depreciation and Amortization | B18: -748281000000 | C18: -799718000000 | D18: -825673000000 | E18: -721863000000 | F18: -720272000000 | G18: -716018000000
A19: Depreciation | B19: -615043000000 | C19: -666480000000 | D19: -692435000000 | E19: -588625000000 | F19: -587034000000 | G19: -582780000000
A20: Amortization | B20: -133238000000 | C20: -133238000000 | D20: -133238000000 | E20: -133238000000 | F20: -133238000000 | G20: -133238000000
A21: Taxes Other Than Income Taxes | B21: -262280000000 | C21: -578541000000 | D21: -333920000000 | E21: -281859000000 | F21: -283621000000 | G21: -306836000000
A22: Provisions | B22: -55197000000 | C22: -352527000000 | D22: -369384000000 | E22: -116256000000 | F22: -264453000000 | G22: -278893000000
A23: Provision for Doubtful Accounts | B23: -55197000000 | C23: -352527000000 | D23: -369384000000 | E23: -116256000000 | F23: -264453000000 | G23: -278893000000
A24: Other Income/Expense, Operating | B24: 294547000000 | C24: 756166000000 | D24: 748356000000 | E24: 715229000000 | F24: 1082004000000 | G24: 798832000000
A25: Other Income, Operating | B25: 669427000000 | C25: 873010000000 | D25: 933477000000 | E25: 962526000000 | F25: 1215375000000 | G25: 1106020000000
A26: Other Expenses, Operating | B26: -374880000000 | C26: -116844000000 | D26: -185121000000 | E26: -247297000000 | F26: -133371000000 | G26: -307188000000
A27: Total Operating Profit/Loss | B27: 12829305000000 | C27: 17483085000000 | D27: 18792599000000 | E27: 20144409000000 | F27: 23514061000000 | G27: 23326021000000
... A32: Interest Income | B32: 605772000000 | C32: 397344000000 | D32: 596234000000 | E32: 1148768000000 | F32: 1773991000000 | G32: 1644641000000
A33: Other Finance Income/Expenses
A34: Other Finance Income
A35: Net Investment Income | B35: 1006807000000 | C35: -80473000000 | D35: -3543547000000 | E35: -1878259000000 | F35: -3649306000000 | G35: -582562000000
A36: Income from Associates, JointVentures and Other Participating Interests | B36: -253641000000 | C36: 133927000000 | D36: 123181000000 | E36: -2314353000000 | F36: -1361608000000 | G36: -1406729000000
A37: Share of Profit and Interest from Associates
A38: Gain/Loss on Foreign Currency Exchange | B38: 1260448000000 | C38: -214400000000 | D38: -3666728000000 | E38: 436094000000 | F38: -2287698000000 | G38: 824167000000
A39: Fair Value or Unrealized Gain/Loss on Financial Assets
A40: Irregular Income/Expense | B40: -35898000000 | C40: -428250000000 | D40: -225558000000 | E40: -100579000000 | F40: -503556000000 | G40: -621838000000
A41: Disposal of Businesses | F41: 117256000000 | G41: 117256000000
A42: Fixed Asset Disposals | B42: 27143000000 | C42: 49590000000 | D42: 38468000000 | E42: 79996000000 | F42: 94447000000 | G42: 67557000000
A43: Impairment/Write Off/Write Down of Capital Assets | C43: -477840000000 | D43: -159341000000 | E43: -174471000000 | F43: -715259000000 | G43: -715259000000
A44: Goodwill Impairment/Write Off | D44: -104685000000 | E44: -6104000000
...

Sheet Cashflow Statement
A1: INDF_cash-flow_Annual_As_Originally_Reported | B1: 2020 | C1: 2021 | D1: 2022 | E1: 2023 | F1: 2024 | G1: TTM
A2: Cash Flows from/Used in Operating Activities, Direct | B2: 13855497000000 | C2: 14692641000000 | D2: 13587686000000 | E2: 18460624000000 | F2: 17507956000000 | G2: 18498022000000
A3: Net Cash Flow from Continuing Operating Activities, Direct | B3: 13855497000000 | C3: 14692641000000 | D3: 13587686000000 | E3: 18460624000000 | F3: 17507956000000 | G3: 18498022000000
A4: Cash Receipts from Operating Activities, Direct | B4: 82741551000000 | C4: 98996928000000 | D4: 111460656000000 | E4: 113343826000000 | F4: 116985957000000 | G4: 119512510000000
A5: Receipts from Customers, Direct | B5: 81974807000000 | C5: 98434144000000 | D5: 110669817000000 | E5: 112104124000000 | F5: 115014921000000 | G5: 117710681000000
A6: Interest Received, Direct | B6: 607230000000 | C6: 395950000000 | D6: 602816000000 | E6: 1163276000000 | F6: 1753911000000 | G6: 1623756000000
A7: Other Cash Receipts from Operating Activities, Direct | B7: 159514000000 | C7: 166834000000 | D7: 188023000000 | E7: 76426000000 | F7: 217125000000 | G7: 178073000000
A8: Cash Payments from Operating Activities, Direct | B8: -68886054000000 | C8: -84304287000000 | D8: -97872970000000 | E8: -94883202000000 | F8: -99478001000000 | G8: -101014488000000
A9: Payments to Suppliers for Goods and Services, Direct | B9: -39571039000000 | C9: -50101494000000 | D9: -61407297000000 | E9: -56028686000000 | F9: -58059224000000 | G9: -59406304000000
A10: Payments to Employees, Direct | B10: -7851131000000 | C10: -9468622000000 | D10: -9442157000000 | E10: -10389358000000 | F10: -10404798000000 | G10: -11048853000000
A11: Taxes Paid, Direct | B11: -2784615000000 | C11: -3577269000000 | D11: -3775947000000 | E11: -4325824000000 | F11: -5172128000000 | G11: -4745553000000
A12: Interest Paid, Direct | B12: -1840068000000 | C12: -2308523000000 | D12: -3143191000000 | E12: -3518728000000 | F12: -3840151000000 | G12: -3782820000000
A13: Other Cash Payments from Operating Activities, Direct | B13: -16839201000000 | C13: -18848379000000 | D13: -20104378000000 | E13: -20620606000000 | F13: -22001700000000 | G13: -22030958000000
... A21: Purchase/Acquisition of Business | B21: -33011855000000 | C21: -506714000000 | D21: -15242000000 | E21: -31016000000 | F21: -38376000000 | G21: -63163000000
A22: Sale of Business
A23: Purchase/Sale of Investments, Net | B23: 54371000000 | C23: -1152401000000 | D23: 177502000000 | E23: -7137255000000 | F23: -1425039000000 | G23: -17956000000
A24: Purchase of Investments | F24: -1425039000000 | G24: -17956000000
A25: Sale of Investments | B25: 54371000000
A26: Purchase/Sale of Equity Investments | B26: -129500000000 | C26: -117796000000 | D26: -157241000000 | E26: 0
A27: Purchase of Joint Venture/Associate | B27: -129500000000 | C27: -117796000000 | D27: -157241000000 | E27: 0
A28: Purchase/Sale of Intangibles, Net
A29: Purchase of Intangibles
A30: Increase/Decrease in Restricted Cash and Cash Equivalents
A31: Purchase/Sale of Other Non-Current Assets, Net
A32: Sales of Other Non-Current Assets
A33: Dividends Received/Paid, CFI
A34: Cash Flow from Financing Activities | B34: 27285509000000 | C34: 3852424000000 | D34: -14329188000000 | E34: -4889846000000 | F34: -680208000000 | G34: -6439433000000
A35: Cash Flow from Continuing Financing Activities | B35: 27285509000000 | C35: 3852424000000 | D35: -14329188000000 | E35: -4889846000000 | F35: -680208000000 | G35: -6439433000000
A36: Issuance of/Repayments for Debt, Net | B36: 31200680000000 | C36: 8320832000000 | D36: -386447000000 | E36: -648512000000 | F36: 3685430000000 | G36: -2128629000000
A37: Issuance of/Repayments for Short Term Debt, Net | B37: 767007000000 | C37: -410406000000 | D37: 1426178000000 | E37: 1061820000000 | F37: 4295425000000 | G37: -4572773000000
A38: Proceeds from Issuance of Short Term Debt | B38: 30031557000000 | C38: 25747645000000 | D38: 37880699000000 | E38: 34795471000000 | F38: 29578782000000 | G38: 26240748000000
A39: Repayments for Short Term Debt | B39: -29264550000000 | C39: -26158051000000 | D39: -36454521000000 | E39: -33733651000000 | F39: -25283357000000 | G39: -30813521000000
A40: Issuance of/Repayments for Long Term Debt, Net | B40: 30433673000000 | C40: 8731238000000 | D40: -1812625000000 | E40: -1710332000000 | F40: -609995000000 | G40: 2444144000000
A41: Proceeds from Issuance of Long Term Debt | B41: 31624693000000 | C41: 44079170000000 | D41: 4676743000000 | E41: 2588900000000 | F41: 1777184000000 | G41: 4954666000000
A42: Repayments for Long Term Debt | B42: -1191020000000 | C42: -35347932000000 | D42: -6489368000000 | E42: -4299232000000 | F42: -2387179000000 | G42: -2510522000000
A43: Issuance of/Repayments for Lease Financing | B43: -336408000000 | C43: -341770000000 | D43: -409845000000 | E43: -306974000000 | F43: -384298000000 | G43: -362054000000
A44: Repayments for Lease Financing | B44: -336408000000 | C44: -341770000000 | D44: -409845000000 | E44: -306974000000 | F44: -384298000000 | G44: -362054000000
A45: Net Movement in Non-Controlling/Minority Interest | F45: 377331000000
A46: Cash Dividends and Interest Paid | B46: -2440959000000 | C46: -2440959000000 | D46: -2440959000000 | E46: -2256570000000 | F46: -2344374000000
A47: Cash Dividends Paid | B47: -2440959000000 | C47: -2440959000000 | D47: -2440959000000 | E47: -2256570000000 | F47: -2344374000000
...

Sheet Balance Sheet
A1: INDF_balance-sheet_Annual_As_Originally_Reported | B1: 2020 | C1: 2021 | D1: 2022 | E1: 2023 | F1: 2024
A2: Total Assets | B2: 163136516000000 | C2: 179356193000000 | D2: 180433300000000 | E2: 186587957000000 | F2: 201713313000000
A3: Total Current Assets | B3: 38418238000000 | C3: 54183399000000 | D3: 54876668000000 | E3: 63101797000000 | F3: 79765476000000
A4: Cash, Cash Equivalents and Short Term Investments | B4: 17338235000000 | C4: 30631763000000 | D4: 26922050000000 | E4: 36689357000000 | F4: 48224984000000
A5: Cash and Cash Equivalents | B5: 17336960000000 | C5: 29478126000000 | D5: 25945916000000 | E5: 28575968000000 | F5: 38710056000000
A6: Cash | B6: 15079784000000 | C6: 26390158000000 | D6: 21051926000000 | E6: 21575281000000 | F6: 31904063000000
A7: Cash Equivalents | B7: 2257176000000 | C7: 3087968000000 | D7: 4893990000000 | E7: 7000687000000 | F7: 6805993000000
A8: Short Term Investments | B8: 1275000000 | C8: 1153637000000 | D8: 976134000000 | E8: 8113389000000 | F8: 9514928000000
A9: Trading/ Listed Investments, Current | B9: 1275000000 | C9: 1153637000000 | D9: 976134000000 | E9: 8113389000000 | F9: 9514928000000
A10: Other Short Term Investments
A11: Inventories | B11: 11927820000000 | C11: 13557229000000 | D11: 17287007000000 | E11: 15977913000000 | F11: 19086016000000
A12: Raw Materials, Consumables and Supplies | B12: 6267652000000 | C12: 6977688000000 | D12: 9620851000000 | E12: 8752232000000 | F12: 9920505000000
A13: Work-in-Process | B13: 167409000000 | C13: 242875000000 | D13: 234774000000 | E13: 247474000000 | F13: 354972000000
A14: Finished Goods and Merchandise | B14: 4328760000000 | C14: 4572745000000 | D14: 5801497000000 | E14: 4867607000000 | F14: 6066994000000
A15: Other Inventories | B15: 1440360000000 | C15: 2029684000000 | D15: 1947895000000 | E15: 2390429000000 | F15: 2995010000000
A16: Inventory Allowance/Adjustments | B16: -276361000000 | C16: -265763000000 | D16: -318010000000 | E16: -279829000000 | F16: -251465000000
A17: Trade and Other Receivables, Current | B17: 7451670000000 | C17: 8464306000000 | D17: 9000849000000 | E17: 8674000000000 | F17: 10017297000000
A18: Trade/Accounts Receivable, Current | B18: 6429130000000 | C18: 7626041000000 | D18: 8280536000000 | E18: 7978466000000 | F18: 9283543000000
A19: Gross Trade/Accounts Receivable, Current | B19: 6620815000000 | C19: 7770244000000 | D19: 8421277000000 | E19: 8126726000000 | F19: 9475380000000
A20: Allowance/Adjustments for Trade/Accounts Receivable, Current | B20: -191685000000 | C20: -144203000000 | D20: -140741000000 | E20: -148260000000 | F20: -191837000000
A21: Amount Due From Related Parties, Current | B21: 601605000000 | C21: 644187000000 | D21: 418341000000 | E21: 412658000000 | F21: 426153000000
A22: Other Receivables, Current | B22: 420935000000 | C22: 194078000000 | D22: 301972000000 | E22: 282876000000 | F22: 307601000000
... A24: Other Current Assets | B24: 106187000000 | C24: 118576000000 | D24: 153814000000 | E24: 102425000000 | F24: 96762000000
A25: Assets Held for Sale/Discontinued Operations, Current
A26: Total Non-Current Assets | B26: 124718278000000 | C26: 125172794000000 | D26: 125556632000000 | E26: 123486160000000 | F26: 121947837000000
A27: Net Property, Plant and Equipment | B27: 37206691000000 | C27: 38028431000000 | D27: 38662201000000 | E27: 38435528000000 | F27: 38550387000000
A28: Gross Property, Plant and Equipment | B28: 66179334000000 | C28: 70415673000000 | D28: 74230000000000 | E28: 76795926000000 | F28: 80033909000000
A29: Properties | B29: 15642411000000 | C29: 15992707000000 | D29: 16660512000000 | E29: 17693217000000 | F29: 18183598000000
A30: Buildings and Improvements | B30: 15578574000000 | C30: 15933899000000 | D30: 16602455000000 | E30: 17632911000000 | F30: 18123839000000
A31: Leasehold and Improvements | B31: 63837000000 | C31: 58808000000 | D31: 58057000000 | E31: 60306000000 | F31: 59759000000
A32: Land and Improvements
A33: Machinery, Furniture and Equipment | B33: 32771714000000 | C33: 35763589000000 | D33: 37959723000000 | E33: 39364601000000 | F33: 42972781000000
A34: Plant and Machinery | B34: 21321369000000 | C34: 23174303000000 | D34: 24615873000000 | E34: 26478024000000 | F34: 27606194000000
A35: Furniture, Fixtures and Office Equipment | B35: 2055486000000 | C35: 2177096000000 | D35: 2314484000000 | E35: 2440009000000 | F35: 2539158000000
A36: Flight, Fleet, Vehicle and Related Equipment | B36: 9394859000000 | C36: 10412190000000 | D36: 11029366000000 | E36: 10446568000000 | F36: 12827429000000
A37: Construction in Progress and Advance Payments | B37: 2194366000000 | C37: 2574156000000 | D37: 2878287000000 | E37: 2405384000000 | F37: 1619189000000
A38: Leased Property, Plant and Equipment | B38: 14566000000 | C38: 8733000000 | D38: 19892000000 | E38: 18356000000 | F38: 13331000000
A39: Other Property, Plant and Equipment | B39: 15556277000000 | C39: 16076488000000 | D39: 16711586000000 | E39: 17314368000000 | F39: 17245010000000
A40: Accumulated Depreciation and Impairment | B40: -28972643000000 | C40: -32387242000000 | D40: -35567799000000 | E40: -38360398000000 | F40: -41483522000000
A41: Accumulated Depreciation | B41: -28972643000000 | C41: -31951917000000 | D41: -34989298000000 | E41: -37615197000000 | F41: -40479365000000
...
