Workbook
Name BS: 'Study Case 1_Working Paper'!$A$5:$G$39

Sheet Background
B2: Case Study: Talentiv Bootcamp
B3: Business Profile:
B4: Type | C4: : | D4: Professional Training Bootcamp Provider
B5: Focus | C5: : | D5: 1-week courses in Data Analytics, Digital Marketing, HR, and Finance & Tax
B6: Model | C6: : | D6: Online & Offline (hybrid)
B7: Team | C7: : | D7: 8 people (Instructors, Ops, Marketing, Finance, Admin)
B8: Revenue Model | C8: : | D8: Fixed-price fee per participant (Rp200.000 – Rp500.000)
A10: A. | B10: Financial Statement 20X3 - 20X4
A12: 1 | B12: Financial Position
E13: 20X3 | F13: 20X4
B14: Assets
B15: Cash & Bank | E15: 150000 | F15: 245000
B16: Accounts Receivable | E16: 40000 | F16: 55000
B17: Prepaid Rent | E17: 20000 | F17: 15000
B18: Fixed Assets (net) | E18: 80000 | F18: 60000
B19: Total Assets | E19: =SUM(E15:E18) -> 290,000 | F19: =SUM(F15:F18) -> 375,000
B21: Liabilities & Equity
B22: Liabilities
B23: Accounts Payable | E23: 25000 | F23: 8000
B24: Bank Loan – Current (ST) | E24: 0 | F24: 30000
B25: Bank Loan – Non-current (LT) | E25: 60000 | F25: 0
B26: Total Liabilities | E26: =SUM(E23:E25) -> 85,000 | F26: =SUM(F23:F25) -> 38,000
B27: Equity
B28: Paid-in Capital | E28: 97000 | F28: 97000
B29: Retained Earnings | E29: =E45 -> 108,000 | F29: =E29+F45 -> 260,000
B30: Dividend | E30: 0 | F30: -20000
B31: Total Equity | E31: =SUM(E28:E29) -> 205,000 | F31: =SUM(F28:F30) -> 337,000
B32: Total Liabilities+Equity | E32: =E26+E31 -> 290,000 | F32: =F26+F31 -> 375,000
A34: 2 | B34: Profit & Loss
E35: 20X3 | F35: 20X4
B36: Revenue | E36: 400000 | F36: 520000
B37: Cost of Service | E37: 120000 | F37: 150000
B38: Gross Profit | E38: =E36-E37 -> 280,000 | F38: =F36-F37 -> 370,000
B40: Operating Expenses | E40: 150000 | F40: 190000
B41: Depreciation | E41: 20000 | F41: 20000
B42: EBIT | E42: =E38-SUM(E40:E41) -> 110,000 | F42: =F38-SUM(F40:F41) -> 160,000
B44: Interest Expense | E44: 2000 | F44: 8000
B45: Net Profit | E45: 108000 | F45: 152000
A50: B. | B50: Additional Information
A51: 1 | B51: Loan schedule
...

Sheet Study Case 1_20X5 Transaction
A1: *in thousand rupiah
A2: Period | B2: No | C2: Description | D2: Amount | F2: Periode | G2: Akun | H2: Dr | I2: Akun | J2: Cr | M2: COA Impact | N2: Q1 | O2: Q2 | P2: Q3 | Q2: Q4
A3: Q1 | B3: 1 | C3: Collected AR from 20X4 corporate clients | D3: 40000 | F3: Q1 | G3: Cash and cash equivalents | H3: =D3 -> 40,000 | I3: Account receivable | J3: =-H3 -> (40,000) | M3: Cash and cash equivalents | N3: =SUMIFS($H:$H,$G:$G,$M3,$F:$F,N$2)+SUMIFS($J:$J,$I:$I,$M3,$F:$F,N$2) -> 95,000 | O3: =SUMIFS($H:$H,$G:$G,$M3,$F:$F,O$2)+SUMIFS($J:$J,$I:$I,$M3,$F:$F,O$2) -> 111,000 | P3: =SUMIFS($H:$H,$G:$G,$M3,$F:$F,P$2)+SUMIFS($J:$J,$I:$I,$M3,$F:$F,P$2) -> 93,000 | Q3: =SUMIFS($H:$H,$G:$G,$M3,$F:$F,Q$2)+SUMIFS($J:$J,$I:$I,$M3,$F:$F,Q$2) -> (31,500)
B4: 2 | C4: Received cash from new training participants | D4: 150000 | F4: Q1 | G4: Cash and cash equivalents | H4: =D4 -> 150,000 | I4: Sales | J4: =-H4 -> (150,000) | M4: Account receivable | N4: =SUMIFS($H:$H,$G:$G,$M4,$F:$F,N$2)+SUMIFS($J:$J,$I:$I,$M4,$F:$F,N$2) -> (40,000) | O4: =SUMIFS($H:$H,$G:$G,$M4,$F:$F,O$2)+SUMIFS($J:$J,$I:$I,$M4,$F:$F,O$2) -> (15,000) | P4: =SUMIFS($H:$H,$G:$G,$M4,$F:$F,P$2)+SUMIFS($J:$J,$I:$I,$M4,$F:$F,P$2) -> 35,000 | Q4: =SUMIFS($H:$H,$G:$G,$M4,$F:$F,Q$2)+SUMIFS($J:$J,$I:$I,$M4,$F:$F,Q$2) -> 105,000
B5: 3 | C5: Paid instructor fees for Q1 programs | D5: 40000 | F5: Q1 | G5: Instructors | H5: =D5 -> 40,000 | I5: Cash and cash equivalents | J5: =-H5 -> (40,000) | M5: Prepaid Expense and advances | N5: =SUMIFS($H:$H,$G:$G,$M5,$F:$F,N$2)+SUMIFS($J:$J,$I:$I,$M5,$F:$F,N$2) -> (3,750) | O5: =SUMIFS($H:$H,$G:$G,$M5,$F:$F,O$2)+SUMIFS($J:$J,$I:$I,$M5,$F:$F,O$2) -> (3,750) | P5: =SUMIFS($H:$H,$G:$G,$M5,$F:$F,P$2)+SUMIFS($J:$J,$I:$I,$M5,$F:$F,P$2) -> (3,750) | Q5: =SUMIFS($H:$H,$G:$G,$M5,$F:$F,Q$2)+SUMIFS($J:$J,$I:$I,$M5,$F:$F,Q$2) -> (3,750)
B6: 4 | C6: Paid utilities for office | D6: 5000 | F6: Q1 | G6: General and Administrative Expenses | H6: =D6 -> 5,000 | I6: Cash and cash equivalents | J6: =-H6 -> (5,000) | M6: Fixed assets | N6: =SUMIFS($H:$H,$G:$G,$M6,$F:$F,N$2)+SUMIFS($J:$J,$I:$I,$M6,$F:$F,N$2) -> 25,000 | O6: =SUMIFS($H:$H,$G:$G,$M6,$F:$F,O$2)+SUMIFS($J:$J,$I:$I,$M6,$F:$F,O$2) -> - | P6: =SUMIFS($H:$H,$G:$G,$M6,$F:$F,P$2)+SUMIFS($J:$J,$I:$I,$M6,$F:$F,P$2) -> - | Q6: =SUMIFS($H:$H,$G:$G,$M6,$F:$F,Q$2)+SUMIFS($J:$J,$I:$I,$M6,$F:$F,Q$2) -> -
B7: 5 | C7: Paid marketing campaigns | D7: 10000 | F7: Q1 | G7: Selling & Marketing Expenses | H7: =D7 -> 10,000 | I7: Cash and cash equivalents | J7: =-H7 -> (10,000) | M7: Accumulated Depr. - Fixed assets | N7: =SUMIFS($H:$H,$G:$G,$M7,$F:$F,N$2)+SUMIFS($J:$J,$I:$I,$M7,$F:$F,N$2) -> (11,250) | O7: =SUMIFS($H:$H,$G:$G,$M7,$F:$F,O$2)+SUMIFS($J:$J,$I:$I,$M7,$F:$F,O$2) -> (11,250) | P7: =SUMIFS($H:$H,$G:$G,$M7,$F:$F,P$2)+SUMIFS($J:$J,$I:$I,$M7,$F:$F,P$2) -> (11,250) | Q7: =SUMIFS($H:$H,$G:$G,$M7,$F:$F,Q$2)+SUMIFS($J:$J,$I:$I,$M7,$F:$F,Q$2) -> (11,250)
B8: 6 | C8: Purchased laptops for training | D8: 25000 | F8: Q1 | G8: Fixed assets | H8: =D8 -> 25,000 | I8: Cash and cash equivalents | J8: =-H8 -> (25,000) | M8: Account payables | N8: =-SUMIFS($H:$H,$G:$G,$M8,$F:$F,N$2)+SUMIFS($J:$J,$I:$I,$M8,$F:$F,N$2) -> (8,000) | O8: =SUMIFS($H:$H,$G:$G,$M8,$F:$F,O$2)+SUMIFS($J:$J,$I:$I,$M8,$F:$F,O$2) -> - | P8: =SUMIFS($H:$H,$G:$G,$M8,$F:$F,P$2)+SUMIFS($J:$J,$I:$I,$M8,$F:$F,P$2) -> - | Q8: =SUMIFS($H:$H,$G:$G,$M8,$F:$F,Q$2)+SUMIFS($J:$J,$I:$I,$M8,$F:$F,Q$2) -> -
B9: 7 | C9: Paid interest for bank loan | D9: 2000 | F9: Q1 | G9: Interest expense | H9: =D9 -> 2,000 | I9: Cash and cash equivalents | J9: =-H9 -> (2,000) | M9: Unearned revenue | N9: =SUMIFS($H:$H,$G:$G,$M9,$F:$F,N$2)+SUMIFS($J:$J,$I:$I,$M9,$F:$F,N$2) -> - | O9: =-SUMIFS($H:$H,$G:$G,$M9,$F:$F,O$2)+SUMIFS($J:$J,$I:$I,$M9,$F:$F,O$2) -> (50,000) | P9: =SUMIFS($H:$H,$G:$G,$M9,$F:$F,P$2)+SUMIFS($J:$J,$I:$I,$M9,$F:$F,P$2) -> - | Q9: =SUMIFS($H:$H,$G:$G,$M9,$F:$F,Q$2)+SUMIFS($J:$J,$I:$I,$M9,$F:$F,Q$2) -> -
B10: 8 | C10: Paid AP from 20X4 vendors | D10: 8000 | F10: Q1 | G10: Account payables | H10: =D10 -> 8,000 | I10: Cash and cash equivalents | J10: =-H10 -> (8,000) | M10: Short term loan | N10: =SUMIFS($H:$H,$G:$G,$M10,$F:$F,N$2)+SUMIFS($J:$J,$I:$I,$M10,$F:$F,N$2) -> - | O10: =SUMIFS($H:$H,$G:$G,$M10,$F:$F,O$2)+SUMIFS($J:$J,$I:$I,$M10,$F:$F,O$2) -> 15,000 | P10: =SUMIFS($H:$H,$G:$G,$M10,$F:$F,P$2)+SUMIFS($J:$J,$I:$I,$M10,$F:$F,P$2) -> 7,500 | Q10: =SUMIFS($H:$H,$G:$G,$M10,$F:$F,Q$2)+SUMIFS($J:$J,$I:$I,$M10,$F:$F,Q$2) -> 7,500
B11: 9 | C11: Purchased learning kits for Q1 sessions (COGS) | D11: 5000 | F11: Q1 | G11: Learning Kits | H11: =D11 -> 5,000 | I11: Cash and cash equivalents | J11: =-H11 -> (5,000) | M11: Sales | N11: =SUMIFS($H:$H,$G:$G,$M11,$F:$F,N$2)+SUMIFS($J:$J,$I:$I,$M11,$F:$F,N$2) -> (150,000) | O11: =SUMIFS($H:$H,$G:$G,$M11,$F:$F,O$2)+SUMIFS($J:$J,$I:$I,$M11,$F:$F,O$2) -> (250,000) | P11: =SUMIFS($H:$H,$G:$G,$M11,$F:$F,P$2)+SUMIFS($J:$J,$I:$I,$M11,$F:$F,P$2) -> (215,000) | Q11: =SUMIFS($H:$H,$G:$G,$M11,$F:$F,Q$2)+SUMIFS($J:$J,$I:$I,$M11,$F:$F,Q$2) -> (185,000)
B12: 10 | C12: Amortization of 20X4 prepaid expense | D12: 3750 | F12: Q1 | G12: Amortization expense | H12: =D12 -> 3,750 | I12: Prepaid Expense and advances | J12: =-H12 -> (3,750) | M12: Instructors | N12: =SUMIFS($H:$H,$G:$G,$M12,$F:$F,N$2)+SUMIFS($J:$J,$I:$I,$M12,$F:$F,N$2) -> 40,000 | O12: =SUMIFS($H:$H,$G:$G,$M12,$F:$F,O$2)+SUMIFS($J:$J,$I:$I,$M12,$F:$F,O$2) -> 60,000 | P12: =SUMIFS($H:$H,$G:$G,$M12,$F:$F,P$2)+SUMIFS($J:$J,$I:$I,$M12,$F:$F,P$2) -> 55,000 | Q12: =SUMIFS($H:$H,$G:$G,$M12,$F:$F,Q$2)+SUMIFS($J:$J,$I:$I,$M12,$F:$F,Q$2) -> 70,000
B13: 11 | C13: Depreciation of fixed assets 20X3 | D13: =Background!H68 -> 5,000 | F13: Q1 | G13: Depreciation expense | H13: =D13 -> 5,000 | I13: Accumulated Depr. - Fixed assets | J13: =-H13 -> (5,000) | M13: Learning Kits | N13: =SUMIFS($H:$H,$G:$G,$M13,$F:$F,N$2)+SUMIFS($J:$J,$I:$I,$M13,$F:$F,N$2) -> 5,000 | O13: =SUMIFS($H:$H,$G:$G,$M13,$F:$F,O$2)+SUMIFS($J:$J,$I:$I,$M13,$F:$F,O$2) -> 6,000 | P13: =SUMIFS($H:$H,$G:$G,$M13,$F:$F,P$2)+SUMIFS($J:$J,$I:$I,$M13,$F:$F,P$2) -> 4,000 | Q13: =SUMIFS($H:$H,$G:$G,$M13,$F:$F,Q$2)+SUMIFS($J:$J,$I:$I,$M13,$F:$F,Q$2) -> 5,000
B14: 12 | C14: Depreciation of fixed assets 20X5 | D14: =Background!H70 -> 6,250 | F14: Q1 | G14: Depreciation expense | H14: =D14 -> 6,250 | I14: Accumulated Depr. - Fixed assets | J14: =-H14 -> (6,250) | M14: Selling & Marketing Expenses | N14: =SUMIFS($H:$H,$G:$G,$M14,$F:$F,N$2)+SUMIFS($J:$J,$I:$I,$M14,$F:$F,N$2) -> 10,000 | O14: =SUMIFS($H:$H,$G:$G,$M14,$F:$F,O$2)+SUMIFS($J:$J,$I:$I,$M14,$F:$F,O$2) -> 15,000 | P14: =SUMIFS($H:$H,$G:$G,$M14,$F:$F,P$2)+SUMIFS($J:$J,$I:$I,$M14,$F:$F,P$2) -> 12,000 | Q14: =SUMIFS($H:$H,$G:$G,$M14,$F:$F,Q$2)+SUMIFS($J:$J,$I:$I,$M14,$F:$F,Q$2) -> 20,000
A15: Q2 | B15: 1 | C15: Recognized revenue from Q1 advance | D15: 50000 | F15: Q2 | G15: Unearned revenue | H15: =D15 -> 50,000 | I15: Sales | J15: =-D15 -> (50,000) | M15: General and Administrative Expenses | N15: =SUMIFS($H:$H,$G:$G,$M15,$F:$F,N$2)+SUMIFS($J:$J,$I:$I,$M15,$F:$F,N$2) -> 5,000 | O15: =SUMIFS($H:$H,$G:$G,$M15,$F:$F,O$2)+SUMIFS($J:$J,$I:$I,$M15,$F:$F,O$2) -> 6,000 | P15: =SUMIFS($H:$H,$G:$G,$M15,$F:$F,P$2)+SUMIFS($J:$J,$I:$I,$M15,$F:$F,P$2) -> 6,500 | Q15: =SUMIFS($H:$H,$G:$G,$M15,$F:$F,Q$2)+SUMIFS($J:$J,$I:$I,$M15,$F:$F,Q$2) -> 7,000
B16: 2 | C16: Received cash from Q2 training participants | D16: 200000 | F16: Q2 | G16: Cash and cash equivalents | H16: =D16 -> 200,000 | I16: Sales | J16: =-D16 -> (200,000) | M16: Depreciation expense | N16: =SUMIFS($H:$H,$G:$G,$M16,$F:$F,N$2)+SUMIFS($J:$J,$I:$I,$M16,$F:$F,N$2) -> 11,250 | O16: =SUMIFS($H:$H,$G:$G,$M16,$F:$F,O$2)+SUMIFS($J:$J,$I:$I,$M16,$F:$F,O$2) -> 11,250 | P16: =SUMIFS($H:$H,$G:$G,$M16,$F:$F,P$2)+SUMIFS($J:$J,$I:$I,$M16,$F:$F,P$2) -> 11,250 | Q16: =SUMIFS($H:$H,$G:$G,$M16,$F:$F,Q$2)+SUMIFS($J:$J,$I:$I,$M16,$F:$F,Q$2) -> 11,250
B17: 3 | C17: Collected remaining AR from Q1 | D17: 15000 | F17: Q2 | G17: Cash and cash equivalents | H17: =D17 -> 15,000 | I17: Account receivable | J17: =-D17 -> (15,000) | M17: Amortization expense | N17: =SUMIFS($H:$H,$G:$G,$M17,$F:$F,N$2)+SUMIFS($J:$J,$I:$I,$M17,$F:$F,N$2) -> 3,750 | O17: =SUMIFS($H:$H,$G:$G,$M17,$F:$F,O$2)+SUMIFS($J:$J,$I:$I,$M17,$F:$F,O$2) -> 3,750 | P17: =SUMIFS($H:$H,$G:$G,$M17,$F:$F,P$2)+SUMIFS($J:$J,$I:$I,$M17,$F:$F,P$2) -> 3,750 | Q17: =SUMIFS($H:$H,$G:$G,$M17,$F:$F,Q$2)+SUMIFS($J:$J,$I:$I,$M17,$F:$F,Q$2) -> 3,750
B18: 4 | C18: Paid instructor fees for Q2 programs | D18: 60000 | F18: Q2 | G18: Instructors | H18: =D18 -> 60,000 | I18: Cash and cash equivalents | J18: =-D18 -> (60,000) | M18: Interest expense | N18: =SUMIFS($H:$H,$G:$G,$M18,$F:$F,N$2)+SUMIFS($J:$J,$I:$I,$M18,$F:$F,N$2) -> 2,000 | O18: =SUMIFS($H:$H,$G:$G,$M18,$F:$F,O$2)+SUMIFS($J:$J,$I:$I,$M18,$F:$F,O$2) -> 2,000 | P18: =SUMIFS($H:$H,$G:$G,$M18,$F:$F,P$2)+SUMIFS($J:$J,$I:$I,$M18,$F:$F,P$2) -> 2,000 | Q18: =SUMIFS($H:$H,$G:$G,$M18,$F:$F,Q$2)+SUMIFS($J:$J,$I:$I,$M18,$F:$F,Q$2) -> 2,000
B19: 5 | C19: Paid utilities | D19: 6000 | F19: Q2 | G19: General and Administrative Expenses | H19: =D19 -> 6,000 | I19: Cash and cash equivalents | J19: =-D19 -> (6,000)
B20: 6 | C20: Paid marketing campaigns | D20: 15000 | F20: Q2 | G20: Selling & Marketing Expenses | H20: =D20 -> 15,000 | I20: Cash and cash equivalents | J20: =-D20 -> (15,000)
B21: 7 | C21: Paid interest for bank loan | D21: 2000 | F21: Q2 | G21: Interest expense | H21: =D21 -> 2,000 | I21: Cash and cash equivalents | J21: =-D21 -> (2,000)
B22: 8 | C22: Paid Loan for Q1+Q2 loan | D22: 15000 | F22: Q2 | G22: Short term loan | H22: =D22 -> 15,000 | I22: Cash and cash equivalents | J22: =-D22 -> (15,000)
B23: 9 | C23: Amortization of 20X4 prepaid expense | D23: 3750 | F23: Q2 | G23: Amortization expense | H23: =D23 -> 3,750 | I23: Prepaid Expense and advances | J23: =-D23 -> (3,750)
B24: 10 | C24: Purchased learning kits for Q2 sessions (COGS) | D24: 6000 | F24: Q2 | G24: Learning Kits | H24: =D24 -> 6,000 | I24: Cash and cash equivalents | J24: =-D24 -> (6,000)
B25: 11 | C25: Depreciation of fixed assets 20X3 | D25: =D13 -> 5,000 | F25: Q2 | G25: Depreciation expense | H25: =D25 -> 5,000 | I25: Accumulated Depr. - Fixed assets | J25: =-H25 -> (5,000)
B26: 12 | C26: Depreciation of fixed assets 20X5 | D26: =D14 -> 6,250 | F26: Q2 | G26: Depreciation expense | H26: =D26 -> 6,250 | I26: Accumulated Depr. - Fixed assets | J26: =-H26 -> (6,250)
A27: Q3 | B27: 1 | C27: Sold corporate training on credit | D27: 70000 | F27: Q3 | G27: Account receivable | H27: =D27 -> 70,000 | I27: Sales | J27: =-H27 -> (70,000) | O27: =10000+-8000 -> 2000
B28: 2 | C28: Received cash from Q3 training participants | D28: 145000 | F28: =F27 -> Q3 | G28: Cash and cash equivalents | H28: =D28 -> 145,000 | I28: Sales | J28: =-H28 -> (145,000)
B29: 3 | C29: Collected AR from Q3 | D29: 35000 | F29: =F28 -> Q3 | G29: Cash and cash equivalents | H29: =D29 -> 35,000 | I29: Account receivable | J29: =-D29 -> (35,000)
B30: 4 | C30: Paid instructor fees for Q3 programs | D30: 55000 | F30: =F29 -> Q3 | G30: Instructors | H30: =D30 -> 55,000 | I30: Cash and cash equivalents | J30: =-D30 -> (55,000)
B31: 5 | C31: Paid utilities | D31: 6500 | F31: =F30 -> Q3 | G31: General and Administrative Expenses | H31: =D31 -> 6,500 | I31: Cash and cash equivalents | J31: =-D31 -> (6,500)
B32: 6 | C32: Paid marketing campaigns | D32: 12000 | F32: =F31 -> Q3 | G32: Selling & Marketing Expenses | H32: =D32 -> 12,000 | I32: Cash and cash equivalents | J32: =-D32 -> (12,000)
B33: 7 | C33: Paid interest for bank loan | D33: 2000 | F33: =F32 -> Q3 | G33: Interest expense | H33: =D33 -> 2,000 | I33: Cash and cash equivalents | J33: =-D33 -> (2,000)
B34: 8 | C34: Paid Loan for Q3 | D34: 7500 | F34: =F33 -> Q3 | G34: Short term loan | H34: =D34 -> 7,500 | I34: Cash and cash equivalents | J34: =-H34 -> (7,500)
B35: 9 | C35: Amortization of 20X4 prepaid expense | D35: 3750 | F35: =F34 -> Q3 | G35: Amortization expense | H35: =D35 -> 3,750 | I35: Prepaid Expense and advances | J35: =-H35 -> (3,750)
B36: 10 | C36: Purchased learning kits for Q3 sessions (COGS) | D36: 4000 | F36: =F35 -> Q3 | G36: Learning Kits | H36: =D36 -> 4,000 | I36: Cash and cash equivalents | J36: =-D36 -> (4,000)
B37: 11 | C37: Depreciation of fixed assets 20X3 | D37: =D25 -> 5,000 | F37: =F36 -> Q3 | G37: Depreciation expense | H37: =D37 -> 5,000 | I37: Accumulated Depr. - Fixed assets | J37: =-H37 -> (5,000)
B38: 12 | C38: Depreciation of fixed assets 20X5 | D38: =D26 -> 6,250 | F38: =F37 -> Q3 | G38: Depreciation expense | H38: =D38 -> 6,250 | I38: Accumulated Depr. - Fixed assets | J38: =-H38 -> (6,250)
A39: Q4 | B39: 1 | C39: Sold corporate training on credit | D39: 45000 | F39: Q4 | G39: Cash and cash equivalents | H39: =D39 -> 45,000 | I39: Account receivable | J39: =-D39 -> (45,000)
B40: 2 | C40: Received cash from Q4 training participants | D40: 185000 | F40: =F39 -> Q4 | G40: Account receivable | H40: =D40 -> 185,000 | I40: Sales | J40: =-D40 -> (185,000)
...

Sheet Study Case 1_Working Paper
A1: Statement of Financial Position | I1: Statement of Profit & Loss | P1: Statement of Cash Flow | W1: Financial Ratio
A2: in thousand Rupiah | I2: in thousand Rupiah | P2: in thousand Rupiah
A4: Description | C4: 20X4 | D4: 20X5 | I4: Description | J4: Q1 | K4: Q2 | L4: Q3 | M4: Q4 | N4: Annual | P4: Description | Q4: Q1 | R4: Q2 | S4: Q3 | T4: Q4 | V4: 2a | W4: Net Profit Margin | X4: = | Y4: Net Profit | Z4: = | AA4: =-N21 -> 405,500 | AB4: = | AC4: =AA4/AA5 -> 50.7%
D5: Q1 | E5: Q2 | F5: Q3 | G5: Q4 | Y5: Revenue | AA5: =-N7 -> 800,000
A6: ASSETS | I6: REVENUES | P6: OPERATING ACTIVITIES
A7: Current Assets | I7: Sales | J7: =SUMIF('Study Case 1_20X5 Transaction'!$M$3:$M$18,'Study Case 1_Working Paper'!$I7,'Study Case 1_20X5 Transaction'!N$3:N$18) -> (150,000) | K7: =SUMIF('Study Case 1_20X5 Transaction'!$M$3:$M$18,'Study Case 1_Working Paper'!$I7,'Study Case 1_20X5 Transaction'!O$3:O$18) -> (250,000) | L7: =SUMIF('Study Case 1_20X5 Transaction'!$M$3:$M$18,'Study Case 1_Working Paper'!$I7,'Study Case 1_20X5 Transaction'!P$3:P$18) -> (215,000) | M7: =SUMIF('Study Case 1_20X5 Transaction'!$M$3:$M$18,'Study Case 1_Working Paper'!$I7,'Study Case 1_20X5 Transaction'!Q$3:Q$18) -> (185,000) | N7: =SUM(J7:M7) -> (800,000) | P7: Net Income (loss) | Q7: =-J21 -> 73,000 | R7: =-K21 -> 146,000 | S7: =-L21 -> 120,500 | T7: =-M21 -> 66,000
A8: Cash and cash equivalents | C8: 245000 | D8: =SUMIF('Study Case 1_20X5 Transaction'!$M$3:$M$18,'Study Case 1_Working Paper'!$A8,'Study Case 1_20X5 Transaction'!N$3:N418)+'Study Case 1_Working Paper'!C8 -> 340,000 | E8: =SUMIF('Study Case 1_20X5 Transaction'!$M$3:$M$18,'Study Case 1_Working Paper'!$A8,'Study Case 1_20X5 Transaction'!O$3:O418)+'Study Case 1_Working Paper'!D8 -> 451,000 | F8: =SUMIF('Study Case 1_20X5 Transaction'!$M$3:$M$18,'Study Case 1_Working Paper'!$A8,'Study Case 1_20X5 Transaction'!P$3:P418)+'Study Case 1_Working Paper'!E8 -> 544,000 | G8: =SUMIF('Study Case 1_20X5 Transaction'!$M$3:$M$18,'Study Case 1_Working Paper'!$A8,'Study Case 1_20X5 Transaction'!Q$3:Q418)+'Study Case 1_Working Paper'!F8 -> 512,500 | I8: COST OF SERVICE | P8: Depreciation expense | Q8: =J14 -> 11,250 | R8: =K14 -> 11,250 | S8: =L14 -> 11,250 | T8: =M14 -> 11,250
A9: Account receivable | C9: 55000 | D9: =SUMIF('Study Case 1_20X5 Transaction'!$M$3:$M$18,'Study Case 1_Working Paper'!$A9,'Study Case 1_20X5 Transaction'!N$3:N419)+'Study Case 1_Working Paper'!C9 -> 15,000 | E9: =SUMIF('Study Case 1_20X5 Transaction'!$M$3:$M$18,'Study Case 1_Working Paper'!$A9,'Study Case 1_20X5 Transaction'!O$3:O419)+'Study Case 1_Working Paper'!D9 -> 0 | F9: =SUMIF('Study Case 1_20X5 Transaction'!$M$3:$M$18,'Study Case 1_Working Paper'!$A9,'Study Case 1_20X5 Transaction'!P$3:P419)+'Study Case 1_Working Paper'!E9 -> 35,000 | G9: =SUMIF('Study Case 1_20X5 Transaction'!$M$3:$M$18,'Study Case 1_Working Paper'!$A9,'Study Case 1_20X5 Transaction'!Q$3:Q419)+'Study Case 1_Working Paper'!F9 -> 140,000 | I9: Instructors | J9: =SUMIF('Study Case 1_20X5 Transaction'!$M$3:$M$18,'Study Case 1_Working Paper'!$I9,'Study Case 1_20X5 Transaction'!N$3:N$18) -> 40,000 | K9: =SUMIF('Study Case 1_20X5 Transaction'!$M$3:$M$18,'Study Case 1_Working Paper'!$I9,'Study Case 1_20X5 Transaction'!O$3:O$18) -> 60,000 | L9: =SUMIF('Study Case 1_20X5 Transaction'!$M$3:$M$18,'Study Case 1_Working Paper'!$I9,'Study Case 1_20X5 Transaction'!P$3:P$18) -> 55,000 | M9: =SUMIF('Study Case 1_20X5 Transaction'!$M$3:$M$18,'Study Case 1_Working Paper'!$I9,'Study Case 1_20X5 Transaction'!Q$3:Q$18) -> 70,000 | N9: =SUM(J9:M9) -> 225,000 | P9: Amortization expense | Q9: =J15 -> 3,750 | R9: =K15 -> 3,750 | S9: =L15 -> 3,750 | T9: =M15 -> 3,750 | V9: 2b | W9: Current Ratio | X9: = | Y9: Current Asset | Z9: = | AA9: =G19 -> 692,500 | AB9: = | AC9: =IF(ISERROR(AA9/AA10),0,AA9/AA10) -> 0.00
A10: Inventories | C10: 0 | D10: =SUMIF('Study Case 1_20X5 Transaction'!$M$3:$M$18,'Study Case 1_Working Paper'!$A10,'Study Case 1_20X5 Transaction'!N$3:N420)+'Study Case 1_Working Paper'!C10 -> 0 | E10: =SUMIF('Study Case 1_20X5 Transaction'!$M$3:$M$18,'Study Case 1_Working Paper'!$A10,'Study Case 1_20X5 Transaction'!O$3:O420)+'Study Case 1_Working Paper'!D10 -> 0 | F10: =SUMIF('Study Case 1_20X5 Transaction'!$M$3:$M$18,'Study Case 1_Working Paper'!$A10,'Study Case 1_20X5 Transaction'!P$3:P420)+'Study Case 1_Working Paper'!E10 -> 0 | G10: =SUMIF('Study Case 1_20X5 Transaction'!$M$3:$M$18,'Study Case 1_Working Paper'!$A10,'Study Case 1_20X5 Transaction'!Q$3:Q420)+'Study Case 1_Working Paper'!F10 -> 0 | I10: Learning Kits | J10: =SUMIF('Study Case 1_20X5 Transaction'!$M$3:$M$18,'Study Case 1_Working Paper'!$I10,'Study Case 1_20X5 Transaction'!N$3:N$18) -> 5,000 | K10: =SUMIF('Study Case 1_20X5 Transaction'!$M$3:$M$18,'Study Case 1_Working Paper'!$I10,'Study Case 1_20X5 Transaction'!O$3:O$18) -> 6,000 | L10: =SUMIF('Study Case 1_20X5 Transaction'!$M$3:$M$18,'Study Case 1_Working Paper'!$I10,'Study Case 1_20X5 Transaction'!P$3:P$18) -> 4,000 | M10: =SUMIF('Study Case 1_20X5 Transaction'!$M$3:$M$18,'Study Case 1_Working Paper'!$I10,'Study Case 1_20X5 Transaction'!Q$3:Q$18) -> 5,000 | N10: =SUM(J10:M10) -> 20,000 | Y10: Current Liabilities | AA10: 0
A11: Prepaid Tax | C11: 0 | D11: =SUMIF('Study Case 1_20X5 Transaction'!$M$3:$M$18,'Study Case 1_Working Paper'!$A11,'Study Case 1_20X5 Transaction'!N$3:N421)+'Study Case 1_Working Paper'!C11 -> 0 | E11: =SUMIF('Study Case 1_20X5 Transaction'!$M$3:$M$18,'Study Case 1_Working Paper'!$A11,'Study Case 1_20X5 Transaction'!O$3:O421)+'Study Case 1_Working Paper'!D11 -> 0 | F11: =SUMIF('Study Case 1_20X5 Transaction'!$M$3:$M$18,'Study Case 1_Working Paper'!$A11,'Study Case 1_20X5 Transaction'!P$3:P421)+'Study Case 1_Working Paper'!E11 -> 0 | G11: =SUMIF('Study Case 1_20X5 Transaction'!$M$3:$M$18,'Study Case 1_Working Paper'!$A11,'Study Case 1_20X5 Transaction'!Q$3:Q421)+'Study Case 1_Working Paper'!F11 -> 0 | I11: Gross profit | J11: =J7+SUM(J9:J10) -> (105,000) | K11: =K7+SUM(K9:K10) -> (184,000) | L11: =L7+SUM(L9:L10) -> (156,000) | M11: =M7+SUM(M9:M10) -> (110,000) | N11: =N7+SUM(N9:N10) -> (555,000) | P11: Account receivable | Q11: =C9-D9 -> 40,000 | R11: =D9-E9 -> 15,000 | S11: =E9-F9 -> (35,000) | T11: =F9-G9 -> (105,000)
A12: Prepaid Expense and advances | C12: 15000 | D12: =SUMIF('Study Case 1_20X5 Transaction'!$M$3:$M$18,'Study Case 1_Working Paper'!$A12,'Study Case 1_20X5 Transaction'!N$3:N422)+'Study Case 1_Working Paper'!C12 -> 11,250 | E12: =SUMIF('Study Case 1_20X5 Transaction'!$M$3:$M$18,'Study Case 1_Working Paper'!$A12,'Study Case 1_20X5 Transaction'!O$3:O422)+'Study Case 1_Working Paper'!D12 -> 7,500 | F12: =SUMIF('Study Case 1_20X5 Transaction'!$M$3:$M$18,'Study Case 1_Working Paper'!$A12,'Study Case 1_20X5 Transaction'!P$3:P422)+'Study Case 1_Working Paper'!E12 -> 3,750 | G12: =SUMIF('Study Case 1_20X5 Transaction'!$M$3:$M$18,'Study Case 1_Working Paper'!$A12,'Study Case 1_20X5 Transaction'!Q$3:Q422)+'Study Case 1_Working Paper'!F12 -> 0 | I12: Selling & Marketing Expenses | J12: =SUMIF('Study Case 1_20X5 Transaction'!$M$3:$M$18,'Study Case 1_Working Paper'!$I12,'Study Case 1_20X5 Transaction'!N$3:N$18) -> 10,000 | K12: =SUMIF('Study Case 1_20X5 Transaction'!$M$3:$M$18,'Study Case 1_Working Paper'!$I12,'Study Case 1_20X5 Transaction'!O$3:O$18) -> 15,000 | L12: =SUMIF('Study Case 1_20X5 Transaction'!$M$3:$M$18,'Study Case 1_Working Paper'!$I12,'Study Case 1_20X5 Transaction'!P$3:P$18) -> 12,000 | M12: =SUMIF('Study Case 1_20X5 Transaction'!$M$3:$M$18,'Study Case 1_Working Paper'!$I12,'Study Case 1_20X5 Transaction'!Q$3:Q$18) -> 20,000 | N12: =SUM(J12:M12) -> 57,000 | P12: Inventories | Q12: =B10-D10 -> - | R12: =D10-E10 -> - | S12: =E10-F10 -> - | T12: =F10-G10 -> -
A13: Total Current Assets | C13: =SUM(C8:C12) -> 315,000 | D13: =SUM(D8:D12) -> 366,250 | E13: =SUM(E8:E12) -> 458,500 | F13: =SUM(F8:F12) -> 582,750 | G13: =SUM(G8:G12) -> 652,500 | I13: General and Administrative Expenses | J13: =SUMIF('Study Case 1_20X5 Transaction'!$M$3:$M$18,'Study Case 1_Working Paper'!$I13,'Study Case 1_20X5 Transaction'!N$3:N$18) -> 5,000 | K13: =SUMIF('Study Case 1_20X5 Transaction'!$M$3:$M$18,'Study Case 1_Working Paper'!$I13,'Study Case 1_20X5 Transaction'!O$3:O$18) -> 6,000 | L13: =SUMIF('Study Case 1_20X5 Transaction'!$M$3:$M$18,'Study Case 1_Working Paper'!$I13,'Study Case 1_20X5 Transaction'!P$3:P$18) -> 6,500 | M13: =SUMIF('Study Case 1_20X5 Transaction'!$M$3:$M$18,'Study Case 1_Working Paper'!$I13,'Study Case 1_20X5 Transaction'!Q$3:Q$18) -> 7,000 | N13: =SUM(J13:M13) -> 24,500 | P13: Prepaid Tax | Q13: =B11-D11 -> - | R13: =D11-E11 -> - | S13: =E11-F11 -> - | T13: =F11-G11 -> -
A14: Non Current Assets | I14: Depreciation expense | J14: =SUMIF('Study Case 1_20X5 Transaction'!$M$3:$M$18,'Study Case 1_Working Paper'!$I14,'Study Case 1_20X5 Transaction'!N$3:N$18) -> 11,250 | K14: =SUMIF('Study Case 1_20X5 Transaction'!$M$3:$M$18,'Study Case 1_Working Paper'!$I14,'Study Case 1_20X5 Transaction'!O$3:O$18) -> 11,250 | L14: =SUMIF('Study Case 1_20X5 Transaction'!$M$3:$M$18,'Study Case 1_Working Paper'!$I14,'Study Case 1_20X5 Transaction'!P$3:P$18) -> 11,250 | M14: =SUMIF('Study Case 1_20X5 Transaction'!$M$3:$M$18,'Study Case 1_Working Paper'!$I14,'Study Case 1_20X5 Transaction'!Q$3:Q$18) -> 11,250 | N14: =SUM(J14:M14) -> 45,000 | P14: Prepaid Expense and advances | T14: =-G12 -> - | V14: 2c | W14: Total Assets Turnover | X14: = | Y14: Net Sales | Z14: = | AA14: =-N7 -> 800,000 | AB14: = | AC14: =AA14/AA15 -> 1.50
A15: Fixed assets | C15: 100000 | D15: =SUMIF('Study Case 1_20X5 Transaction'!$M$3:$M$18,'Study Case 1_Working Paper'!$A15,'Study Case 1_20X5 Transaction'!N$3:N425)+'Study Case 1_Working Paper'!C15 -> 125,000 | E15: =SUMIF('Study Case 1_20X5 Transaction'!$M$3:$M$18,'Study Case 1_Working Paper'!$A15,'Study Case 1_20X5 Transaction'!O$3:O425)+'Study Case 1_Working Paper'!D15 -> 125,000 | F15: =SUMIF('Study Case 1_20X5 Transaction'!$M$3:$M$18,'Study Case 1_Working Paper'!$A15,'Study Case 1_20X5 Transaction'!P$3:P425)+'Study Case 1_Working Paper'!E15 -> 125,000 | G15: =SUMIF('Study Case 1_20X5 Transaction'!$M$3:$M$18,'Study Case 1_Working Paper'!$A15,'Study Case 1_20X5 Transaction'!Q$3:Q425)+'Study Case 1_Working Paper'!F15 -> 125,000 | I15: Amortization expense | J15: =SUMIF('Study Case 1_20X5 Transaction'!$M$3:$M$18,'Study Case 1_Working Paper'!$I15,'Study Case 1_20X5 Transaction'!N$3:N$18) -> 3,750 | K15: =SUMIF('Study Case 1_20X5 Transaction'!$M$3:$M$18,'Study Case 1_Working Paper'!$I15,'Study Case 1_20X5 Transaction'!O$3:O$18) -> 3,750 | L15: =SUMIF('Study Case 1_20X5 Transaction'!$M$3:$M$18,'Study Case 1_Working Paper'!$I15,'Study Case 1_20X5 Transaction'!P$3:P$18) -> 3,750 | M15: =SUMIF('Study Case 1_20X5 Transaction'!$M$3:$M$18,'Study Case 1_Working Paper'!$I15,'Study Case 1_20X5 Transaction'!Q$3:Q$18) -> 3,750 | N15: =SUM(J15:M15) -> 15,000 | P15: Account payables | Q15: =D22-C22 -> (8,000) | R15: =E22-D22 -> - | S15: =F22-E22 -> - | T15: =G22-F22 -> - | Y15: Total Average Assets | AA15: =(Background!F19+G19)/2 -> 533,750
A16: Accumulated Depr. - Fixed assets | C16: -40000 | D16: =SUMIF('Study Case 1_20X5 Transaction'!$M$3:$M$18,'Study Case 1_Working Paper'!$A16,'Study Case 1_20X5 Transaction'!N$3:N426)+'Study Case 1_Working Paper'!C16 -> (51,250) | E16: =SUMIF('Study Case 1_20X5 Transaction'!$M$3:$M$18,'Study Case 1_Working Paper'!$A16,'Study Case 1_20X5 Transaction'!O$3:O426)+'Study Case 1_Working Paper'!D16 -> (62,500) | F16: =SUMIF('Study Case 1_20X5 Transaction'!$M$3:$M$18,'Study Case 1_Working Paper'!$A16,'Study Case 1_20X5 Transaction'!P$3:P426)+'Study Case 1_Working Paper'!E16 -> (73,750) | G16: =SUMIF('Study Case 1_20X5 Transaction'!$M$3:$M$18,'Study Case 1_Working Paper'!$A16,'Study Case 1_20X5 Transaction'!Q$3:Q426)+'Study Case 1_Working Paper'!F16 -> (85,000) | I16: Total operating expense | J16: =SUM(J12:J15) -> 30,000 | K16: =SUM(K12:K15) -> 36,000 | L16: =SUM(L12:L15) -> 33,500 | M16: =SUM(M12:M15) -> 42,000 | N16: =SUM(N12:N13) -> 81,500 | P16: Accrued expenses | Q16: =D23-B23 -> - | R16: =E23-D23 -> - | S16: =F23-E23 -> - | T16: =G23-F23 -> -
A17: Intangible assets | C17: 0 | D17: 0 | E17: =D17 -> 0 | F17: =E17 -> 0 | G17: =F17 -> 0 | I17: Operating Income (Loss) | J17: =J11+SUM(J12:J15) -> (75,000) | K17: =K11+SUM(K12:K15) -> (148,000) | L17: =L11+L16 -> (122,500) | M17: =M11+M16 -> (68,000) | N17: =N11+N16 -> (473,500) | P17: Taxes payables | Q17: =D24-B24 -> - | R17: =E24-D24 -> - | S17: =F24-E24 -> - | T17: =G24-F24 -> -
A18: Total Non Current Assets | C18: =SUM(C15:C17) -> 60,000 | D18: =SUM(D15:D17) -> 73,750 | E18: =SUM(E15:E17) -> 62,500 | F18: =SUM(F15:F17) -> 51,250 | G18: =SUM(G15:G17) -> 40,000 | I18: Other income & expense | P18: Unearned revenue | Q18: =D25-B25 -> - | R18: =E25-D25 -> (50,000) | S18: =F25-E25 -> - | T18: =G25-F25 -> -
A19: TOTAL ASSETS | C19: =C13+C18 -> 375,000 | D19: =D13+D18 -> 440,000 | E19: =E13+E18 -> 521,000 | F19: =F13+F18 -> 634,000 | G19: =G13+G18 -> 692,500 | I19: Interest expense | J19: =SUMIF('Study Case 1_20X5 Transaction'!$M$3:$M$18,'Study Case 1_Working Paper'!$I19,'Study Case 1_20X5 Transaction'!N$3:N$18) -> 2,000 | K19: =SUMIF('Study Case 1_20X5 Transaction'!$M$3:$M$18,'Study Case 1_Working Paper'!$I19,'Study Case 1_20X5 Transaction'!O$3:O$18) -> 2,000 | L19: =SUMIF('Study Case 1_20X5 Transaction'!$M$3:$M$18,'Study Case 1_Working Paper'!$I19,'Study Case 1_20X5 Transaction'!P$3:P$18) -> 2,000 | M19: =SUMIF('Study Case 1_20X5 Transaction'!$M$3:$M$18,'Study Case 1_Working Paper'!$I19,'Study Case 1_20X5 Transaction'!Q$3:Q$18) -> 2,000 | P19: Cash from Operating Activities | Q19: =SUM(Q7:Q18) -> 120,000 | R19: =SUM(R7:R18) -> 126,000 | S19: =SUM(S7:S18) -> 100,500 | T19: =SUM(T7:T18) -> (24,000) | V19: 2d | W19: Debt to Equity | X19: = | Y19: Total Liabilities | Z19: = | AA19: 0 | AB19: = | AC19: =AA19/AA20 -> 0.00
A20: LIABILITY AND EQUITY | I20: Total other income & expense | J20: =J17+J19 -> (73,000) | K20: =K17+K19 -> (146,000) | L20: =L17+L19 -> (120,500) | M20: =M17+M19 -> (66,000) | N20: =SUM(N19) -> - | Y20: Total Equity | AA20: =G38 -> 742,500
A21: Current Liability | I21: Net Income | J21: =J17+J19 -> (73,000) | K21: =K17+K19 -> (146,000) | L21: =L17+L19 -> (120,500) | M21: =M17+M19 -> (66,000) | N21: =SUM(J21:M21) -> (405,500) | P21: INVESTING ACTIVITIES
A22: Account payables | C22: 8000 | D22: =SUMIF('Study Case 1_20X5 Transaction'!$M$3:$M$18,'Study Case 1_Working Paper'!$A22,'Study Case 1_20X5 Transaction'!N$3:N432)+'Study Case 1_Working Paper'!C22 -> 0 | E22: =SUMIF('Study Case 1_20X5 Transaction'!$M$3:$M$18,'Study Case 1_Working Paper'!$A22,'Study Case 1_20X5 Transaction'!O$3:O432)+'Study Case 1_Working Paper'!D22 -> 0 | F22: =SUMIF('Study Case 1_20X5 Transaction'!$M$3:$M$18,'Study Case 1_Working Paper'!$A22,'Study Case 1_20X5 Transaction'!P$3:P432)+'Study Case 1_Working Paper'!E22 -> 0 | G22: =SUMIF('Study Case 1_20X5 Transaction'!$M$3:$M$18,'Study Case 1_Working Paper'!$A22,'Study Case 1_20X5 Transaction'!Q$3:Q432)+'Study Case 1_Working Paper'!F22 -> 0 | P22: Acquisition of fixed assets | Q22: 25000 | S22: =R22 | T22: =S22
A23: Accrued expenses | C23: 0 | D23: =SUMIF('Study Case 1_20X5 Transaction'!$M$3:$M$18,'Study Case 1_Working Paper'!$A23,'Study Case 1_20X5 Transaction'!N$3:N433)+'Study Case 1_Working Paper'!C23 -> 0 | E23: =SUMIF('Study Case 1_20X5 Transaction'!$M$3:$M$18,'Study Case 1_Working Paper'!$A23,'Study Case 1_20X5 Transaction'!O$3:O433)+'Study Case 1_Working Paper'!D23 -> 0 | F23: =SUMIF('Study Case 1_20X5 Transaction'!$M$3:$M$18,'Study Case 1_Working Paper'!$A23,'Study Case 1_20X5 Transaction'!P$3:P433)+'Study Case 1_Working Paper'!E23 -> 0 | G23: =SUMIF('Study Case 1_20X5 Transaction'!$M$3:$M$18,'Study Case 1_Working Paper'!$A23,'Study Case 1_20X5 Transaction'!Q$3:Q433)+'Study Case 1_Working Paper'!F23 -> 0 | P23: Cash from Investing Activities | Q23: =-Q22 -> (25,000) | R23: =-R22 -> - | S23: =-S22 -> - | T23: =-T22 -> -
A24: Taxes payables | C24: 0 | D24: =SUMIF('Study Case 1_20X5 Transaction'!$M$3:$M$18,'Study Case 1_Working Paper'!$A24,'Study Case 1_20X5 Transaction'!N$3:N434)+'Study Case 1_Working Paper'!C24 -> 0 | E24: =SUMIF('Study Case 1_20X5 Transaction'!$M$3:$M$18,'Study Case 1_Working Paper'!$A24,'Study Case 1_20X5 Transaction'!O$3:O434)+'Study Case 1_Working Paper'!D24 -> 0 | F24: =SUMIF('Study Case 1_20X5 Transaction'!$M$3:$M$18,'Study Case 1_Working Paper'!$A24,'Study Case 1_20X5 Transaction'!P$3:P434)+'Study Case 1_Working Paper'!E24 -> 0 | G24: =SUMIF('Study Case 1_20X5 Transaction'!$M$3:$M$18,'Study Case 1_Working Paper'!$A24,'Study Case 1_20X5 Transaction'!Q$3:Q434)+'Study Case 1_Working Paper'!F24 -> 0
A25: Unearned revenue | C25: 0 | D25: =SUMIF('Study Case 1_20X5 Transaction'!$M$3:$M$18,'Study Case 1_Working Paper'!$A25,'Study Case 1_20X5 Transaction'!N$3:N435)+'Study Case 1_Working Paper'!C25 -> 0 | E25: =SUMIF('Study Case 1_20X5 Transaction'!$M$3:$M$18,'Study Case 1_Working Paper'!$A25,'Study Case 1_20X5 Transaction'!O$3:O435)+'Study Case 1_Working Paper'!D25 -> (50,000) | F25: =SUMIF('Study Case 1_20X5 Transaction'!$M$3:$M$18,'Study Case 1_Working Paper'!$A25,'Study Case 1_20X5 Transaction'!P$3:P435)+'Study Case 1_Working Paper'!E25 -> (50,000) | G25: =SUMIF('Study Case 1_20X5 Transaction'!$M$3:$M$18,'Study Case 1_Working Paper'!$A25,'Study Case 1_20X5 Transaction'!Q$3:Q435)+'Study Case 1_Working Paper'!F25 -> (50,000) | P25: FINANCING ACTIVITIES
A26: Short term loan | C26: 30000 | D26: =-SUMIF('Study Case 1_20X5 Transaction'!$M$3:$M$18,'Study Case 1_Working Paper'!$A26,'Study Case 1_20X5 Transaction'!N$3:N436)+'Study Case 1_Working Paper'!C26 -> 30,000 | E26: =-SUMIF('Study Case 1_20X5 Transaction'!$M$3:$M$18,'Study Case 1_Working Paper'!$A26,'Study Case 1_20X5 Transaction'!O$3:O436)+'Study Case 1_Working Paper'!D26 -> 15,000 | F26: =-SUMIF('Study Case 1_20X5 Transaction'!$M$3:$M$18,'Study Case 1_Working Paper'!$A26,'Study Case 1_20X5 Transaction'!P$3:P436)+'Study Case 1_Working Paper'!E26 -> 7,500 | G26: =-SUMIF('Study Case 1_20X5 Transaction'!$M$3:$M$18,'Study Case 1_Working Paper'!$A26,'Study Case 1_20X5 Transaction'!Q$3:Q436)+'Study Case 1_Working Paper'!F26 -> 0 | P26: Proceeds from shares subscriptions | Q26: 0
A27: Total Current Liability | C27: =SUM(C22:C26) -> 38,000 | D27: =SUM(D22:D26) -> 30,000 | E27: =E25+E26 -> (35,000) | F27: =F25+F26 -> (42,500) | G27: =G25+G26 -> (50,000) | P27: Proceeds from loan
A28: Non Current Liability | P28: Payment loan | Q28: 0 | R28: 15000 | S28: 7500 | T28: 7500
A29: Long term loan | C29: 0 | D29: =SUMIF('Study Case 1_20X5 Transaction'!$M$3:$M$18,'Study Case 1_Working Paper'!$A29,'Study Case 1_20X5 Transaction'!N$3:N439)+'Study Case 1_Working Paper'!C29 -> 0 | E29: =SUMIF('Study Case 1_20X5 Transaction'!$M$3:$M$18,'Study Case 1_Working Paper'!$A29,'Study Case 1_20X5 Transaction'!O$3:O439)+'Study Case 1_Working Paper'!D29 -> 0 | F29: =SUMIF('Study Case 1_20X5 Transaction'!$M$3:$M$18,'Study Case 1_Working Paper'!$A29,'Study Case 1_20X5 Transaction'!P$3:P439)+'Study Case 1_Working Paper'!E29 -> 0 | G29: =SUMIF('Study Case 1_20X5 Transaction'!$M$3:$M$18,'Study Case 1_Working Paper'!$A29,'Study Case 1_20X5 Transaction'!Q$3:Q439)+'Study Case 1_Working Paper'!F29 -> 0 | P29: Dividend payment | Q29: 0 | R29: 0 | S29: 0 | T29: 0
A30: Total non current liability | C30: =SUM(C29) -> 0 | D30: =SUM(D29) -> 0 | E30: =SUM(E29) -> 0 | F30: =SUM(F29) -> 0 | G30: =SUM(G29) -> 0 | P30: Cash from Financing Activities | Q30: =SUM(Q26:Q29) -> - | R30: =R27-R28 -> (15,000) | S30: =S27-S28 -> (7,500) | T30: =T27-T28 -> (7,500)
A31: Total Liability | C31: =C27+C30 -> 38,000 | D31: =D27+D30 -> 30,000 | E31: =E27+E30 -> (35,000) | F31: =F27+F30 -> (42,500) | G31: =G27+G30 -> (50,000)
A32: Equity | P32: Net increase (decrease) | Q32: =Q19+Q23+Q30 -> 95,000 | R32: =R19+R23+R30 -> 111,000 | S32: =S19+S23+S30 -> 93,000 | T32: =T19+T23+T30 -> (31,500)
A33: Share capital | C33: 97000 | D33: =SUMIF('Study Case 1_20X5 Transaction'!$M$3:$M$18,'Study Case 1_Working Paper'!$A33,'Study Case 1_20X5 Transaction'!N$3:N443)+'Study Case 1_Working Paper'!C33 -> 97,000 | E33: =SUMIF('Study Case 1_20X5 Transaction'!$M$3:$M$18,'Study Case 1_Working Paper'!$A33,'Study Case 1_20X5 Transaction'!O$3:O443)+'Study Case 1_Working Paper'!D33 -> 97,000 | F33: =SUMIF('Study Case 1_20X5 Transaction'!$M$3:$M$18,'Study Case 1_Working Paper'!$A33,'Study Case 1_20X5 Transaction'!P$3:P443)+'Study Case 1_Working Paper'!E33 -> 97,000 | G33: =SUMIF('Study Case 1_20X5 Transaction'!$M$3:$M$18,'Study Case 1_Working Paper'!$A33,'Study Case 1_20X5 Transaction'!Q$3:Q443)+'Study Case 1_Working Paper'!F33 -> 97,000
A34: Beginning Retained Earnings | C34: 108000 | D34: =C37 -> 240,000 | E34: =D37 -> 313,000 | F34: =E37 -> 459,000 | G34: =F37 -> 579,500 | P34: Beginning Cash | Q34: =C8 -> 245,000 | R34: =Q36 -> 340,000 | S34: =R36 -> 451,000 | T34: =S36 -> 544,000
A35: Profit & Loss Current | C35: =Background!F45 -> 152,000 | D35: =-J20 -> 73,000 | E35: =-K20 -> 146,000 | F35: =-L20 -> 120,500 | G35: =-M20 -> 66,000
A36: Dividend | C36: =Background!F30 -> (20,000) | P36: Ending Cash | Q36: =Q32+Q34 -> 340,000 | R36: =R32+R34 -> 451,000 | S36: =S32+S34 -> 544,000 | T36: =T32+T34 -> 512,500
A37: Ending Retained Earnings | C37: 240000 | D37: =D34+D35 -> 313,000 | E37: =SUM(E34:E35) -> 459,000 | F37: =SUM(F34:F35) -> 579,500 | G37: =SUM(G34:G35) -> 645,500
A38: Total equity | C38: =C33+C37 -> 337,000 | D38: =D33+D37 -> 410,000 | E38: =E33+E37 -> 556,000 | F38: =F33+F37 -> 676,500 | G38: =G33+G37 -> 742,500 | P38: Control | Q38: =Q36-D8 -> - | R38: =R36-E8 -> - | S38: =S36-F8 -> - | T38: =T36-G8 -> -
A39: Total Liability and Equity | C39: =C31+C38 -> 375,000 | D39: =D31+D38 -> 440,000 | E39: =E31+E38 -> 521,000 | F39: =F31+F38 -> 634,000 | G39: =G31+G38 -> 692,500
A40: Control | C40: =C19-C39 -> - | D40: =D19-D39 -> - | E40: =E19-E39 -> - | F40: =F19-F39 -> - | G40: =G19-G39 -> -
A66: Cash and cash equivalents
...

Sheet Case Study 2
A2: PT EduSupplies Nusantara, vendor stationary terkemuka di Jakarta, yang melayani keperluan Bootcamp dan Learning Center daerah Jabodetabek. PT EduSupplies Nusantara juga melakukan penjualan dengan termin sebagai berikut:
B4: Swasta | C4: 30
B5: Kementerian/Lembaga | C5: 60
A7: No | B7: Nama Pelanggan | C7: Jenis Pelanggan | D7: Tanggal Invoice | E7: No. Invoice | F7: Jatuh Tempo | G7: Nilai Invoice (Rp) | H7: Tanggal Pembayaran | I7: Aging Skedul | J7: Status / Keterangan
A8: 1 | B8: PT Andalan Sejahtera | C8: Swasta | D8: 45902 | E8: INV-001 | F8: =IF(C8=$B$4,$C$4,$C$5) -> 30 Hari | G8: 12000000 | H8: =D8+F8 -> 2-Oct-25 | I8: =DATE(2025,10,31) -> 31-Oct-25 | J8: =I8-H8 -> 29 Hari
A9: 2 | B9: CV Maju Terus | C9: Swasta | D9: 45879 | E9: INV-002 | F9: =IF(C9=$B$4,$C$4,$C$5) -> 30 Hari | G9: 8500000 | H9: =D9+F9 -> 9-Sep-25 | I9: =DATE(2025,10,31) -> 31-Oct-25 | J9: =I9-H9 -> 52 Hari
A10: 3 | B10: PT Sinar Abadi | C10: Swasta | D10: 45860 | E10: INV-003 | F10: =IF(C10=$B$4,$C$4,$C$5) -> 30 Hari | G10: 15750000 | H10: =D10+F10 -> 21-Aug-25 | I10: =DATE(2025,10,31) -> 31-Oct-25 | J10: =I10-H10 -> 71 Hari
A11: 4 | B11: PT Mandiri Karya | C11: Swasta | D11: 45935 | E11: INV-004 | F11: =IF(C11=$B$4,$C$4,$C$5) -> 30 Hari | G11: 9250000 | H11: =D11+F11 -> 4-Nov-25 | I11: =DATE(2025,10,31) -> 31-Oct-25 | J11: =I11-H11 -> -4 Hari
A12: 5 | B12: CV Tunas Harapan | C12: Swasta | D12: 45820 | E12: INV-005 | F12: =IF(C12=$B$4,$C$4,$C$5) -> 30 Hari | G12: 6000000 | H12: =D12+F12 -> 12-Jul-25 | I12: =DATE(2025,10,31) -> 31-Oct-25 | J12: =I12-H12 -> 111 Hari
A13: 6 | B13: PT Nusantara Jaya | C13: Swasta | D13: 45920 | E13: INV-006 | F13: =IF(C13=$B$4,$C$4,$C$5) -> 30 Hari | G13: 10000000 | H13: =D13+F13 -> 20-Oct-25 | I13: =DATE(2025,10,31) -> 31-Oct-25 | J13: =I13-H13 -> 11 Hari
A14: 7 | B14: PT Bumi Sentosa | C14: Swasta | D14: 45802 | E14: INV-007 | F14: =IF(C14=$B$4,$C$4,$C$5) -> 30 Hari | G14: 7500000 | H14: =D14+F14 -> 24-Jun-25 | I14: =DATE(2025,10,31) -> 31-Oct-25 | J14: =I14-H14 -> 129 Hari
A15: 8 | B15: CV Berkah Makmur | C15: Swasta | D15: 45868 | E15: INV-008 | F15: =IF(C15=$B$4,$C$4,$C$5) -> 30 Hari | G15: 5800000 | H15: =D15+F15 -> 29-Aug-25 | I15: =DATE(2025,10,31) -> 31-Oct-25 | J15: =I15-H15 -> 63 Hari
A16: 9 | B16: PT Globalindo | C16: Swasta | D16: 45901 | E16: INV-009 | F16: =IF(C16=$B$4,$C$4,$C$5) -> 30 Hari | G16: 18250000 | H16: =D16+F16 -> 1-Oct-25 | I16: =DATE(2025,10,31) -> 31-Oct-25 | J16: =I16-H16 -> 30 Hari
A17: 10 | B17: PT Sejahtera Mandiri | C17: Swasta | D17: 45826 | E17: INV-010 | F17: =IF(C17=$B$4,$C$4,$C$5) -> 30 Hari | G17: 13600000 | H17: =D17+F17 -> 18-Jul-25 | I17: =DATE(2025,10,31) -> 31-Oct-25 | J17: =I17-H17 -> 105 Hari
A18: 11 | B18: Kementerian Kesehatan RI | C18: Kementerian | D18: 45874 | E18: INV-011 | F18: =IF(C18=$B$4,$C$4,$C$5) -> 60 Hari | G18: 25000000 | H18: =D18+F18 -> 4-Oct-25 | I18: =DATE(2025,10,31) -> 31-Oct-25 | J18: =I18-H18 -> 27 Hari
A19: 12 | B19: Lembaga Administrasi Negara (LAN) | C19: Lembaga Pemerintah | D19: 45910 | E19: INV-012 | F19: =IF(C19=$B$4,$C$4,$C$5) -> 60 Hari | G19: 30000000 | H19: =D19+F19 -> 9-Nov-25 | I19: =DATE(2025,10,31) -> 31-Oct-25 | J19: =I19-H19 -> -9 Hari
... A22: 15 | B22: Kementerian Keuangan RI | C22: Kementerian | D22: 45912 | E22: INV-015 | F22: =IF(C22=$B$4,$C$4,$C$5) -> 60 Hari | G22: 27500000 | H22: =D22+F22 -> 11-Nov-25 | I22: =DATE(2025,10,31) -> 31-Oct-25 | J22: =I22-H22 -> -11 Hari
B24: Informasi Tambahan:
B25: Pada bulan Oktober 2025, Perussahaan melakukan rekonsiliasi piutang dengan Perusahaan Swasta didapati sebagai berikut:
A26: - | B26: PT Bumi Sentosa sudah melakukan pembayaran penuh pada tanggal 15 Agustus 2025, namun tidak melakukan konfirmasi pembayaran ke Finance
A27: - | B27: PT Sinar Abadi berencana membayar 50% dari piutangnya pada tanggal 22 Oktober 2025
A28: - | B28: CV Tunas Harapan meminta keringanan pembayaran berupa pembayaran dicicil 3 kali pada akhir bulan (Oktober, November, Desember)
B31: Pertanyaan:
A32: 1 | B32: Buatkan tanggal jatuh tempo per masing-masing customer, sesuai informasi tambahan diatas
A33: 2 | B33: Buatkan aging schedule per 31 Oktober 2025 dengan kriteria sebagai berikut:
B34: Belum jatuh tempo
B35: 0 - 30 hari
B36: 30 - 45 hari
B37: 45 - 60 hari
B38: 60 - 75 hari
B39: 75 - 90 hari
A40: 3 | B40: Mana saja piutang yang berisiko tinggi? Dan mengapa?
B41: Piutang yang beresiko tinggi ada di PT Sejahtera Mandiri dan PT Tunas Harapan karena lebih dari 90 hari. Sedangkan PT Bumi Sentosa memang lebih dari 90 hari dart tanggal jatuh tempo akan tetapi sudah melakukan pembayaraan. Hal ini juga tetep berisiko jika tidak ditangani akan mengganggu pencatatan rekonsiliasi data, karena tim tidak tahu mana yang sudah dibayar mana yang belum.
A42: 4 | B42: Buatkan langkah-langkah efektif dalam penagihan piutang perusahaan baik secara administratif, komunikatif, dan preventif
B44: A. Administratif
B45: 1. Catat semua data pelanggan, tanggal invoice, dan jatuh tempo
B46: 2. Kirim invoice dan buat aging schedule (0-30, 30-45,45-60,60-75,75-90,>90)
B47: 3. Kirim reminder sebelum dan sesudah jatuh tempo
B48: 4. Catat hasil penagihan dan pembayaraan yang masuk
B49: 5. >90 hari belum bayar segeara kirim surat peringatan resmi, lapor ke manajemen dan pertimbangan pembatasan kredit
...

Sheet Case Study 3
B2: Scenario:
B3: Talented Bootcamp telah berjalan online selama 3 tahun. Di 20X6, manajemen sedang mempertimbangkan untuk membuka bootcamp offline yang berlokasi di ruko di Jakarta Selatan. Perluasan usaha akan membutuhkan investasi awal untuk renovasi, peralatan, dan perlengkapan pembelajaran.
B5: Investment Data:
A6: 1 | B6: Investasi awal (renovasi, peralatan, furnitur): Rp150.000.000 (awal 20X6).
A7: 2 | B7: Economic life of project: 4 years (20X6–20X9).
A8: 3 | B8: Tingkat diskonto (biaya modal): 12% per tahun.
B10: Projected Cash Inflows
B11: Period | C11: Projected Cash Inflows
B12: 20X6 | C12: -150000000 | D12: {=ISNUMBER(C12:C16)} -> TRUE
B13: 20X6 | C13: 60000000 | D13: TRUE
B14: 20X7 | C14: 70000000 | D14: TRUE
B15: 20X8 | C15: 80000000 | D15: TRUE
B16: 20X9 | C16: 90000000 | D16: TRUE
B17: Diskonto | C17: 0.12
B18: Question:
A19: 1 | B19: Hitung FV, NPV, IRR, PI
A20: 2 | B20: Berdasarkan perhitungan Anda, apakah proyek tersebut layak atau tidak layak?
B22: Criteria | C22: Feasible | D22: Not Feasible
B23: FV | C23: FV > Investment | D23: FV ≤ Investment
B24: NPV | C24: NPV > 0 | D24: NPV ≤ 0
B25: IRR | C25: IRR > r | D25: IRR ≤ r
B26: PI | C26: PI > 1 | D26: PI ≤ 1
B28: Criteria | C28: Formula | D28: Result | E28: Feasible?
B29: FV | C29: =FV('rate';'period';'payment each period';'investment';0) | D29: =FV(C17,4,0,-D30,0) -> 351,703,680 | E29: =IF(D29>ABS(C12),C22,D22) -> Feasible
B30: NPV | C30: =NPV('rate';'cf1';'cf2';'cf3';…) | D30: {=NPV(C17,C13:C16)} -> 223,514,046.88 | E30: =IF(D30>ABS(C12),C22,D22) -> Feasible
B31: IRR | C31: =IRR('-investment + projected cf') | D31: =IRR(C12:C16) -> 32% | E31: =IF(D31>C18,C22,D22) -> Feasible
B32: PI | C32: =NPV / Investment | D32: =ABS(D30/C12) -> 1.49 | E32: =IF(D32>1,C22,D22) -> Feasible
A35: Analysis:
A36: I | B36: Executive Summary
B37: Berdasarkan evaluasi finansial komprehensif terhadap proposal investasi Proyek Offline Talented Bootcamp, tim telah melakukan penghitungan atas empat parameter kelayakan investasi utama. Hasil analisis menunjukkan Fesiable, dimana setiap indikator secara jelas menunjukan projek ini layak dijalankan Oleh karena itu, dengan ini kami merekomendasikan projek ini agar segera diesekusi.
A39: II | B39: Analisa Metrik dan Interpretasi
B40: Kriteria | C40: Hasil | D40: Interpretasi dan Implikasi Strategis
B41: Net Present Value (NPV) | C41: {=IF(E29:E32=C22,C23:C26,D23:D26)} -> FV > Investment | D41: Proyek layak dijalankan karena menambah kekayaan pemilik modal
B42: Internal Rate of Return (IRR) | C42: NPV > 0 | D42: Proyek meningkatkan investasi seiring waktu
B43: Profitability Index (PI) | C43: IRR > r | D43: Karena lebih besar dari diskonto 12%, proyek memberikan return jauh di atas ekspetasi minimum
B44: Future Value (FV) | C44: PI > 1 | D44: Proyek sangat efisien karena nilai pi>1 menandakan investasi memberikan keuntungan yang tinggi
A46: III | B46: Kesimpulan dan Rekomendasi
A47: 1 | B47: Proyek dinyatakan LAYAK/TIDAK LAYAK secara finansial berdasarkan konsensus empat kriteria investasi (NPV, IRR, PI, FV). Proyeksi finansial menunjukkan bahwa proyek ini layak dijalankan
A48: 2 | B48: Kami merekomendasikan agar Direksi MENYETUJUI/TIDAK MENYETUJUI dan MENGALOKASIKAN/TIDAK MENGALOKASIKAN anggaran untuk diimplementasikan ke proyek offline Talented Bootcamp
A49: 3 | B49: Meskipun indikator finansial sangat kuat/tIdak kuat, keberhasilan proyek juga bergantung pada faktor-faktor non-kuantitatif. Kami menyarankan untuk:
...
