Workbook

Sheet KASUS 1
A1: MEMBUAT JURNAL UMUM
A2: Tanggal | B2: Data transaksi | E2: Jurnal Umum
A3: 45292 | B3: Tn.Adi menyetor uang sebagai modal awal Rp.40.000.000 | E3: Tanggal | F3: Keterangan | G3: Reff | H3: Debit | I3: Kredit
A4: 45296 | B4: Tn.Adi membeli peralatan sebesar Rp.10.000.000 | E4: =A3 -> 45292 | F4: Kas | H4: 40000000
A5: 45301 | B5: Tn.Adi membeli persediaan obat sebesar Rp.5.000.000 secara kredit | F5: Modal | I5: =H4 -> 40000000
A6: 45306 | B6: Tn.Adi menjual obat senilai Rp.2.000.000 tunai | E6: =A4 -> 45296 | F6: Peralatan | H6: 10000000
A7: 45307 | B7: Membayar biaya listrik sebesar Rp.300.000 | F7: Kas | I7: =H6 -> 10000000
A8: 45314 | B8: Membayar pembelian obat yang dibeli tanggal 10/1/2024 | E8: =A5 -> 45301 | F8: Persediaan | H8: 5000000
A9: 45317 | B9: Membayar biaya sewa Rp.700.000 | F9: Hutang Usaha | I9: =H8 -> 5000000
A10: 45322 | B10: Membayar beban gaji karyawan sebesar Rp.1.000.000 | E10: =A6 -> 45306 | F10: Penjualan | H10: 2000000
A11: 45322 | B11: Penarikan modal untuk keperluan pribadi sebesar Rp.500.000 | F11: Kas | I11: 2000000
E12: =A7 -> 45307 | F12: Beban Ulisitas | H12: 300000
F13: Kas | I13: =H12 -> 300000
E14: =A8 -> 45314 | F14: Hutang Usaha | H14: =H8 -> 5000000
F15: Kas | I15: =I9 -> 5000000
E16: =A9 -> 45317 | F16: Beban Sewa | H16: 700000
F17: Kas | I17: =H16 -> 700000
E18: =A10 -> 45322 | F18: Beban Gaji | H18: 1000000
F19: Kas | I19: 1000000
E20: =A11 -> 45322 | F20: Prive | H20: 500000
F21: Kas | I21: 500000
F22: Jumlah | H22: =SUM(H4:H21) -> 64500000 | I22: =SUM(I4:I21) -> 64500000

Sheet KASUS 2
A1: MEMBUAT BUKU BESAR
A2: Apotek Brawijaya Malang
A3: Neraca
A4: Per 1 Januari 2024
A5: Kas | B5: 40000000 | C5: Utang Usaha | D5: 5000000
A6: Piutang Usaha | B6: 15000000 | C6: Modal Adi | D6: 55000000
A7: Peralatan | B7: 2000000
A8: Persediaan | B8: 3000000
A10: Jumlah Aktiva | B10: 60000000 | C10: Jumlah Pasiva | D10: 60000000

Sheet KASUS 2.2
A2: Jurnal Umum | D2: Halaman :
A3: Tanggal | B3: Keterangan | C3: Ref | D3: Debit | E3: Kredit
A4: 45660 | B4: Persediaan | C4: 121 | D4: 2000000
B5: Kas | C5: 101 | E5: 2000000
A6: 45662 | B6: Peralatan | C6: 103 | D6: 3000000
B7: Kas | C7: 101 | E7: 3000000
A8: 45667 | B8: Persediaan | C8: 121 | D8: 5000000
B9: Utang | C9: 201 | E9: 5000000
A10: 45672 | B10: Kas | C10: 101 | D10: 2000000
B11: Pendapatan | C11: 401 | E11: 2000000
B12: Beban Persediaan/ HPP | C12: 503 | D12: 2000000
B13: Persediaan | C13: 121 | E13: 2000000
A14: 45673 | B14: Beban Listrik | C14: 502 | D14: 300000
B15: Kas | C15: 101 | E15: 300000
A16: 45680 | B16: Utang | C16: 201 | D16: 5000000
B17: Kas | C17: 101 | E17: 5000000
A18: 45683 | B18: Beban Sewa | C18: 504 | D18: 700000
B19: Kas | C19: 101 | E19: 700000
A20: 45688 | B20: Beban Gaji | C20: 501 | D20: 1000000
B21: Kas | C21: 101 | E21: 1000000
A22: 45688 | B22: Prive | C22: 302 | D22: 500000
B23: Kas | C23: 101 | E23: 500000

Sheet KASUS 2.3
A1: Nama : Kas | H1: No : 101
A2: Tanggal | C2: Keterangan | D2: Reff | E2: Debit | F2: Kredit | G2: Saldo
G3: Debit | H3: Kredit
A4: 2024
A5: Jan | B5: 1 | C5: Saldo | D5: NS | E5: 40000000 | G5: =E5-F5 -> 40000000
B6: 3 | C6: Posting | D6: JU | F6: 2000000 | G6: =G5+E6-F6 -> 38000000
B7: 5 | D7: JU | F7: 3000000 | G7: =G6+E7-F7 -> 35000000
B8: 15 | D8: JU | E8: 2000000 | G8: =G7+E8-F8 -> 37000000
B9: 16 | D9: JU | F9: 300000 | G9: =G8+E9-F9 -> 36700000
B10: 23 | D10: JU | F10: 5000000 | G10: =G9+E10-F10 -> 31700000
B11: 26 | D11: JU | F11: 700000 | G11: =G10+E11-F11 -> 31000000
B12: 31 | D12: JU | F12: 1000000 | G12: =G11+E12-F12 -> 30000000
B13: 31 | D13: JU | F13: 500000 | G13: =G12+E13-F13 -> 29500000
A15: Nama : Piutang Usaha | H15: No : 102
A16: Tanggal | C16: Keterangan | D16: Ref | E16: Debit | F16: Kredit | G16: Saldo
G17: Debit | H17: Kredit
A18: 2024
A19: Jan | B19: 1 | C19: Saldo | D19: NS | E19: 15000000 | G19: 15000000
A21: Nama : Peralatan | H21: No : 103
A22: Tanggal | C22: Keterangan | D22: Ref | E22: Debit | F22: Kredit | G22: Saldo
G23: Debit | H23: Kredit
A24: 2024
A25: Jan | B25: 1 | C25: Saldo | D25: NS | E25: 2000000 | G25: =E25+F25 -> 2000000
B26: 5 | C26: =C6 -> Posting | D26: JU | E26: 3000000 | G26: =G25+E26-F26 -> 5000000
A28: Nama : Utang Usaha | H28: No : 201
A29: Tanggal | C29: Keterangan | D29: Ref | E29: Debit | F29: Kredit | G29: Saldo
G30: Debit | H30: Kredit
A31: 2024
A32: Jan | B32: 1 | C32: Saldo | D32: NS | F32: 5000000 | H32: =F32-E32 -> 5000000
B33: 10 | C33: =C26 -> Posting | D33: JU | F33: 5000000 | H33: =H32-E33+F33 -> 10000000
B34: 23 | D34: JU | E34: 5000000 | H34: =H33-E34+F34 -> 5000000
A36: Nama : Modal | H36: No : 301
A37: Tanggal | C37: Keterangan | D37: Ref | E37: Debit | F37: Kredit | G37: Saldo
G38: Debit | H38: Kredit
A39: 2024
A40: Jan | B40: 1 | C40: Saldo | D40: - | F40: 55000000 | H40: =F40+E40 -> 55000000
A42: Nama : Pendapatan | H42: No : 401
A43: Tanggal | C43: Keterangan | D43: Ref | E43: Debit | F43: Kredit | G43: Saldo
G44: Debit | H44: Kredit
A45: 2024
...

Sheet KASUS 3.1
A1: MEMBUAT NERACA LAJUR
A2: Apotek Brawijaya Malang
A3: Neraca
A4: Per 1 Januari 2024
A5: Kas | B5: 40000000 | C5: Utang Usaha | D5: 5000000
A6: Piutang Usaha | B6: 15000000 | C6: Modal Adi | D6: 55000000
A7: Peralatan | B7: 2000000
A8: Persediaan | B8: 3000000
A10: Jumlah Aktiva | B10: 60000000 | C10: Jumlah Pasiva | D10: 60000000

Sheet KAUSUS 3.2
A1: Jurnal Penyesuaian | D1: Halaman :
A2: Tanggal | B2: Keterangan | C2: Ref | D2: Debit | E2: Kredit
A3: 31 Des | B3: Kas | D3: 40000
B4: Pendapatan diterima dimuka | E4: 40000
A5: 31 Des | B5: Pendapatan diterima dimuka | D5: 45000
B6: Pendapatan | E6: 45000
A7: 31 Des | B7: Beban Gaji | D7: 5000
B8: Utang Gaji | E8: 5000
A9: 31 Des | B9: Beban Asuransi | D9: 2000
B10: Asuransi dibayar dimuka | E10: 2000
A11: 31 Des | B11: Beban Penyusutan Peralatan | D11: 1000
B12: Akum.Penyusutan Peralatan | E12: 1000

Sheet KAUSUS 3.3
A1: Apotek Brawijaya Malang
A2: NERACA LAJUR
A3: Per 31 Desember 2024 (dalam jutaan rupiah)
A4: Nama Perkiraan | B4: D | C4: Neraca Saldo | E4: Penyesuaian | G4: N.S.S disesuaikan
B5: K | C5: Debit | D5: Kredit | E5: Debit | F5: Kredit | G5: Debit | H5: Kredit
A6: Kas | B6: {=_xlfn.IFS(C6>0,"D",D6>0,"K",E6>0,"D",F6>0,"K")} -> D | C6: 95000 | E6: =IF(SUMIF('KAUSUS 3.2'!$B$3:$B$12,$A6,'KAUSUS 3.2'!D$3:D$12)=0,"-",SUMIF('KAUSUS 3.2'!$B$3:$B$12,$A6,'KAUSUS 3.2'!D$3:D$12)) -> 40000 | F6: =SUMIF('KAUSUS 3.2'!$B$3:$B$12,$A6,'KAUSUS 3.2'!E$3:E$12) -> 0 | G6: =IF(B6="D",ABS((C6+E6)-F6),0) -> 135000 | H6: =IF(B6="K",ABS((D6-E6)+F6),0) -> 0
A7: Asuransi dibayar dimuka | B7: {=_xlfn.IFS(C7>0,"D",D7>0,"K",E7>0,"D",F7>0,"K")} -> D | C7: 15000 | E7: =SUMIF('KAUSUS 3.2'!$B$3:$B$12,$A7,'KAUSUS 3.2'!D$3:D$12) -> 0 | F7: =SUMIF('KAUSUS 3.2'!$B$3:$B$12,$A7,'KAUSUS 3.2'!E$3:E$12) -> 2000 | G7: =IF(B7="D",ABS((C7+E7)-F7),0) -> 13000 | H7: =IF(B7="K",ABS((D7-E7)+F7),0) -> 0
A8: Peralatan | B8: {=_xlfn.IFS(C8>0,"D",D8>0,"K",E8>0,"D",F8>0,"K")} -> D | C8: 2000 | E8: =SUMIF('KAUSUS 3.2'!$B$3:$B$12,$A8,'KAUSUS 3.2'!D$3:D$12) -> 0 | F8: =SUMIF('KAUSUS 3.2'!$B$3:$B$12,$A8,'KAUSUS 3.2'!E$3:E$12) -> 0 | G8: =IF(B8="D",ABS((C8+E8)-F8),0) -> 2000 | H8: =IF(B8="K",ABS((D8-E8)+F8),0) -> 0
A9: Persediaan | B9: {=_xlfn.IFS(C9>0,"D",D9>0,"K",E9>0,"D",F9>0,"K")} -> D | C9: 3000 | E9: =SUMIF('KAUSUS 3.2'!$B$3:$B$12,$A9,'KAUSUS 3.2'!D$3:D$12) -> 0 | F9: =SUMIF('KAUSUS 3.2'!$B$3:$B$12,$A9,'KAUSUS 3.2'!E$3:E$12) -> 0 | G9: =IF(B9="D",ABS((C9+E9)-F9),0) -> 3000 | H9: =IF(B9="K",ABS((D9-E9)+F9),0) -> 0
A10: Utang Usaha | B10: {=_xlfn.IFS(C10>0,"D",D10>0,"K",E10>0,"D",F10>0,"K")} -> K | C10: 0 | D10: 5000 | E10: =SUMIF('KAUSUS 3.2'!$B$3:$B$12,$A10,'KAUSUS 3.2'!D$3:D$12) -> 0 | F10: =SUMIF('KAUSUS 3.2'!$B$3:$B$12,$A10,'KAUSUS 3.2'!E$3:E$12) -> 0 | G10: =IF(B10="D",ABS((C10+E10)-F10),0) -> 0 | H10: =IF(B10="K",ABS((D10-E10)+F10),0) -> 5000
A11: Pendapatan diterima dimuka | B11: {=_xlfn.IFS(C11>0,"D",D11>0,"K",E11>0,"D",F11>0,"K")} -> K | C11: 0 | D11: 10000 | E11: =SUMIF('KAUSUS 3.2'!$B$3:$B$12,$A11,'KAUSUS 3.2'!D$3:D$12) -> 45000 | F11: =SUMIF('KAUSUS 3.2'!$B$3:$B$12,$A11,'KAUSUS 3.2'!E$3:E$12) -> 40000 | G11: =IF(B11="D",ABS((C11+E11)-F11),0) -> 0 | H11: =IF(B11="K",ABS((D11-E11)+F11),0) -> 5000
A12: Modal Adi | B12: {=_xlfn.IFS(C12>0,"D",D12>0,"K",E12>0,"D",F12>0,"K")} -> K | C12: 0 | D12: 55000 | E12: =SUMIF('KAUSUS 3.2'!$B$3:$B$12,$A12,'KAUSUS 3.2'!D$3:D$12) -> 0 | F12: =SUMIF('KAUSUS 3.2'!$B$3:$B$12,$A12,'KAUSUS 3.2'!E$3:E$12) -> 0 | G12: =IF(B12="D",ABS((C12+E12)-F12),0) -> 0 | H12: =IF(B12="K",ABS((D12-E12)+F12),0) -> 55000
A13: Pendapatan | B13: {=_xlfn.IFS(C13>0,"D",D13>0,"K",E13>0,"D",F13>0,"K")} -> K | C13: 0 | D13: 50000 | E13: =SUMIF('KAUSUS 3.2'!$B$3:$B$12,$A13,'KAUSUS 3.2'!D$3:D$12) -> 0 | F13: =SUMIF('KAUSUS 3.2'!$B$3:$B$12,$A13,'KAUSUS 3.2'!E$3:E$12) -> 45000 | G13: =IF(B13="D",ABS((C13+E13)-F13),0) -> 0 | H13: =IF(B13="K",ABS((D13-E13)+F13),0) -> 95000
A14: Beban Gaji | B14: {=_xlfn.IFS(C14>0,"D",D14>0,"K",E14>0,"D",F14>0,"K")} -> D | C14: 5000 | D14: 0 | E14: =SUMIF('KAUSUS 3.2'!$B$3:$B$12,$A14,'KAUSUS 3.2'!D$3:D$12) -> 5000 | F14: =SUMIF('KAUSUS 3.2'!$B$3:$B$12,$A14,'KAUSUS 3.2'!E$3:E$12) -> 0 | G14: =IF(B14="D",ABS((C14+E14)-F14),0) -> 10000 | H14: =IF(B14="K",ABS((D14-E14)+F14),0) -> 0
A15: Utang Gaji | B15: {=_xlfn.IFS(C15>0,"D",D15>0,"K",E15>0,"D",F15>0,"K")} -> K | C15: 0 | D15: 0 | E15: =SUMIF('KAUSUS 3.2'!$B$3:$B$12,$A15,'KAUSUS 3.2'!D$3:D$12) -> 0 | F15: =SUMIF('KAUSUS 3.2'!$B$3:$B$12,$A15,'KAUSUS 3.2'!E$3:E$12) -> 5000 | G15: =IF(B15="D",ABS((C15+E15)-F15),0) -> 0 | H15: =IF(B15="K",ABS((D15-E15)+F15),0) -> 5000
A16: Beban asuransi | B16: {=_xlfn.IFS(C16>0,"D",D16>0,"K",E16>0,"D",F16>0,"K")} -> D | C16: 0 | D16: 0 | E16: =SUMIF('KAUSUS 3.2'!$B$3:$B$12,$A16,'KAUSUS 3.2'!D$3:D$12) -> 2000 | F16: =SUMIF('KAUSUS 3.2'!$B$3:$B$12,$A16,'KAUSUS 3.2'!E$3:E$12) -> 0 | G16: =IF(B16="D",ABS((C16+E16)-F16),0) -> 2000 | H16: =IF(B16="K",ABS((D16-E16)+F16),0) -> 0
A17: Beban Penyusutan Peralatan | B17: {=_xlfn.IFS(C17>0,"D",D17>0,"K",E17>0,"D",F17>0,"K")} -> D | C17: 0 | D17: 0 | E17: =SUMIF('KAUSUS 3.2'!$B$3:$B$12,$A17,'KAUSUS 3.2'!D$3:D$12) -> 1000 | F17: =SUMIF('KAUSUS 3.2'!$B$3:$B$12,$A17,'KAUSUS 3.2'!E$3:E$12) -> 0 | G17: =IF(B17="D",ABS((C17+E17)-F17),0) -> 1000 | H17: =IF(B17="K",ABS((D17-E17)+F17),0) -> 0
A18: ='KAUSUS 3.2'!B12 -> Akum.Penyusutan Peralatan | B18: {=_xlfn.IFS(C18>0,"D",D18>0,"K",E18>0,"D",F18>0,"K")} -> K | C18: 0 | D18: 0 | E18: =SUMIF('KAUSUS 3.2'!$B$3:$B$12,$A18,'KAUSUS 3.2'!D$3:D$12) -> 0 | F18: =SUMIF('KAUSUS 3.2'!$B$3:$B$12,$A18,'KAUSUS 3.2'!E$3:E$12) -> 1000 | G18: =IF(B18="D",ABS((C18+E18)-F18),0) -> 0 | H18: =IF(B18="K",ABS((D18-E18)+F18),0) -> 1000
A19: Jumlah | C19: 120000 | D19: 120000 | E19: =SUM(E6:E18) -> 93000 | F19: =SUM(F6:F18) -> 93000 | G19: =SUM(G6:G18) -> 166000 | H19: =SUM(H6:H18) -> 166000

Sheet KASUSS 4.1
A1: MENUTUP MODAL DAN MEMBUAT NERACA SALDO SETELAH PENUTUP
A3: Apotek Brawijaya Malang
A4: NERACA LAJUR
A5: Per 31 Desember 2024 (dalam jutaan rupiah)
A6: Nama Perkiraan | B6: N.S.S disesuaikan | D6: Laba Rugi | F6: Neraca
B7: Debit | C7: Kredit | D7: Debit | E7: Kredit | F7: Debit | G7: Kredit
A8: Kas | B8: 135000 | C8: - | D8: - | E8: - | F8: 135000 | G8: -
A9: Beban Asuransi dibayar dimuka | B9: 13000 | C9: - | D9: - | E9: - | F9: 13000 | G9: -
A10: Peralatan | B10: 2000 | C10: - | D10: - | E10: - | F10: 2000 | G10: -
A11: Persediaan | B11: 3000 | C11: - | D11: - | E11: - | F11: 3000 | G11: -
A12: Utang Usaha | B12: - | C12: 5000 | D12: - | E12: - | F12: - | G12: 5000
A13: Pendapatan diterima dimuka | B13: - | C13: 45500 | D13: - | E13: - | F13: - | G13: 45500
A14: Modal Adi | B14: - | C14: 55000 | D14: - | E14: - | F14: - | G14: 55000
A15: Pendapatan | B15: - | C15: 54500 | D15: - | E15: 54500 | F15: - | G15: -
A16: Beban Gaji | B16: 10000 | D16: 10000 | E16: - | F16: - | G16: -
A17: Utang Gaji | B17: - | C17: 5000 | D17: - | E17: - | F17: - | G17: 5000
A18: Beban asuransi | B18: 2000 | C18: - | D18: 2000 | E18: - | F18: - | G18: -
A19: Beban Penyusutan Peralatan | B19: 1000 | C19: - | D19: 1000 | E19: - | F19: - | G19: -
A20: Akum Penyusutan Peralatan | B20: - | C20: 1000 | D20: - | E20: - | F20: - | G20: 1000
A21: Jumlah | B21: 166.000 | C21: 166000 | D21: 13000 | E21: 54500 | F21: 153000 | G21: 111500
D22: =E21-D21 -> 41500 | G22: =F21-G21 -> 41500
D23: =SUM(D21:D22) -> 54500 | E23: =SUM(E21:E22) -> 54500 | F23: =SUM(F21:F22) -> 153000 | G23: =SUM(G21:G22) -> 153000

Sheet KASUS 4.2
A1: Apotek Brawijaya Malang
A2: Neraca Saldo setelah penutupan
A3: Per 31 Des 2024
A4: Kas | B4: ='KASUSS 4.1'!F8 -> 135000 | F4: Nama Akun | G4: Debit | H4: Kredit
A5: Beban Asuransi dibayar dimuka | B5: ='KASUSS 4.1'!F9 -> 13000 | E5: 31 Des | F5: Ikhtisar laba rugi | G5: 41500000
A6: Peralatan | B6: ='KASUSS 4.1'!F10 -> 2000 | F6: Modal | H6: 41500000
A7: Akum.Penyusutan Peralatan | C7: ='KASUSS 4.1'!G20 -> 1000
A8: Persediaan | B8: 3000
A9: Utang Usaha | C9: ='KASUSS 4.1'!G12 -> 5000
A10: Pendapatan diterima dimuka | C10: ='KASUSS 4.1'!G13 -> 45500
A11: Utang Gaji | C11: ='KASUSS 4.1'!G17 -> 5000
A12: Modal Adi | C12: ='KASUSS 4.1'!G14+'KASUSS 4.1'!G22 -> 96500
A13: Total | B13: =SUM(B4:B12) -> 153000 | C13: =SUM(C4:C12) -> 153000

Sheet KASUS 5.1
A1: ANALISIS UMUR PUTANG
A9: Nama Debitur | B9: Saldo Piutang 31 Des 2023 | C9: Tanggal Jatuh Tempo | D9: =B22 -> Persentase Kerugian | F9: Perbaikan | G9: CEK | H9: Tempo | I9: Selisih
A10: PT Harum Sari | B10: 10000000 | C10: =G10 -> Minggu, 19 November 2023 | D10: {=_xlfn.IFS(I10<1,$B$23,I10<31,$B$24,I10<61,$B$25,I10<91,$B$26,I10>=91,$B$27)} -> 0.12 | F10: =DATE(2023,11,19) -> 45249 | G10: =TEXT(F10,"[$-21]DDDD")&", "&TEXT(F10,"[$-21]DD MMMM YYYY") -> Minggu, 19 November 2023 | H10: =DATE(2023,12,31) -> 45291 | I10: =H10-F10 -> 42
A11: PT Mekar Pagi | B11: 5000000 | C11: =G11 -> Selasa, 05 Desember 2023 | D11: {=_xlfn.IFS(I11<1,$B$23,I11<31,$B$24,I11<61,$B$25,I11<91,$B$26,I11>=91,$B$27)} -> 0.05 | F11: =DATE(2023,12,5) -> 45265 | G11: =TEXT(F11,"[$-21]DDDD")&", "&TEXT(F11,"[$-21]DD MMMM YYYY") -> Selasa, 05 Desember 2023 | H11: =DATE(2023,12,31) -> 45291 | I11: =H11-F11 -> 26
A12: PT Segar Abadi | B12: 2000000 | C12: =G12 -> Senin, 03 Juli 2023 | D12: {=_xlfn.IFS(I12<1,$B$23,I12<31,$B$24,I12<61,$B$25,I12<91,$B$26,I12>=91,$B$27)} -> 0.25 | F12: =DATE(2023,7,3) -> 45110 | G12: =TEXT(F12,"[$-21]DDDD")&", "&TEXT(F12,"[$-21]DD MMMM YYYY") -> Senin, 03 Juli 2023 | H12: =DATE(2023,12,31) -> 45291 | I12: =H12-F12 -> 181
A13: CV Putik Mawar | B13: 3000000 | C13: =G13 -> Sabtu, 23 Desember 2023 | D13: {=_xlfn.IFS(I13<1,$B$23,I13<31,$B$24,I13<61,$B$25,I13<91,$B$26,I13>=91,$B$27)} -> 0.05 | F13: =DATE(2023,12,23) -> 45283 | G13: =TEXT(F13,"[$-21]DDDD")&", "&TEXT(F13,"[$-21]DD MMMM YYYY") -> Sabtu, 23 Desember 2023 | H13: =DATE(2023,12,31) -> 45291 | I13: =H13-F13 -> 8
A14: PT Bougenville | B14: 8000000 | C14: =G14 -> Senin, 20 November 2023 | D14: {=_xlfn.IFS(I14<1,$B$23,I14<31,$B$24,I14<61,$B$25,I14<91,$B$26,I14>=91,$B$27)} -> 0.12 | F14: =DATE(2023,11,20) -> 45250 | G14: =TEXT(F14,"[$-21]DDDD")&", "&TEXT(F14,"[$-21]DD MMMM YYYY") -> Senin, 20 November 2023 | H14: =DATE(2023,12,31) -> 45291 | I14: =H14-F14 -> 41
A15: PT Melati Puti | B15: 2000000 | C15: =G15 -> Selasa, 23 Januari 2024 | D15: {=_xlfn.IFS(I15<1,$B$23,I15<31,$B$24,I15<61,$B$25,I15<91,$B$26,I15>=91,$B$27)} -> 0.02 | F15: =DATE(2024,1,23) -> 45314 | G15: =TEXT(F15,"[$-21]DDDD")&", "&TEXT(F15,"[$-21]DD MMMM YYYY") -> Selasa, 23 Januari 2024 | H15: =DATE(2023,12,31) -> 45291 | I15: =H15-F15 -> -23
A16: Toko Hanum | B16: 40000000 | C16: =G16 -> Senin, 05 Februari 2024 | D16: {=_xlfn.IFS(I16<1,$B$23,I16<31,$B$24,I16<61,$B$25,I16<91,$B$26,I16>=91,$B$27)} -> 0.02 | F16: =DATE(2024,2,5) -> 45327 | G16: =TEXT(F16,"[$-21]DDDD")&", "&TEXT(F16,"[$-21]DD MMMM YYYY") -> Senin, 05 Februari 2024 | H16: =DATE(2023,12,31) -> 45291 | I16: =H16-F16 -> -36
A17: CV Lili Kuning | B17: 15000000 | C17: =G17 -> Jumat, 15 Desember 2023 | D17: {=_xlfn.IFS(I17<1,$B$23,I17<31,$B$24,I17<61,$B$25,I17<91,$B$26,I17>=91,$B$27)} -> 0.05 | F17: =DATE(2023,12,15) -> 45275 | G17: =TEXT(F17,"[$-21]DDDD")&", "&TEXT(F17,"[$-21]DD MMMM YYYY") -> Jumat, 15 Desember 2023 | H17: =DATE(2023,12,31) -> 45291 | I17: =H17-F17 -> 16
A18: Toko Anggrek | B18: 9000000 | C18: =G18 -> Sabtu, 05 Agustus 2023 | D18: {=_xlfn.IFS(I18<1,$B$23,I18<31,$B$24,I18<61,$B$25,I18<91,$B$26,I18>=91,$B$27)} -> 0.25 | F18: =DATE(2023,8,5) -> 45143 | G18: =TEXT(F18,"[$-21]DDDD")&", "&TEXT(F18,"[$-21]DD MMMM YYYY") -> Sabtu, 05 Agustus 2023 | H18: =DATE(2023,12,31) -> 45291 | I18: =H18-F18 -> 148
A19: CV Seruni | B19: 6000000 | C19: =G19 -> Rabu, 18 Oktober 2023 | D19: {=_xlfn.IFS(I19<1,$B$23,I19<31,$B$24,I19<61,$B$25,I19<91,$B$26,I19>=91,$B$27)} -> 0.15 | F19: =DATE(2023,10,18) -> 45217 | G19: =TEXT(F19,"[$-21]DDDD")&", "&TEXT(F19,"[$-21]DD MMMM YYYY") -> Rabu, 18 Oktober 2023 | H19: =DATE(2023,12,31) -> 45291 | I19: =H19-F19 -> 74
A20: Jumlah | B20: 100000000
A22: Golongan umur piutang | B22: Persentase Kerugian
A23: Belum jatuh tempo | B23: 0.02
A24: Lewat dari 1-30 hari | B24: 0.05
A25: Lewat dari 31-60 hari | B25: 0.12
A26: Lewat dari 61-90 hari | B26: 0.15
A27: Lewat > 90 hari | B27: 0.25

Sheet KASUS 5.2
D1: Umur
A2: Daftar Akun | B2: Belum Jatuh Tempo | C2: ="1"&"-"&"30" -> 1-30 | D2: 31-60 | E2: 61-90 | F2: >90 hari | H2: Nama Akun | I2: No | J2: Debet | K2: Kredit
A3: PT Harum Sari | D3: ='KASUS 5.1'!B10 -> 10000000 | H3: Beban Kerugian Piutang Tak Tertagih | J3: =SUM(B15:F15) -> 6740000
A4: PT Mekar Pagi | C4: ='KASUS 5.1'!B11 -> 5000000 | H4: Cadangan Piutang Tak tertagih | K4: =J3 -> 6740000
A5: PT Segar Abadi | F5: ='KASUS 5.1'!B12 -> 2000000
A6: CV Putik Mawar | C6: ='KASUS 5.1'!B13 -> 3000000
A7: PT Bougonville | D7: ='KASUS 5.1'!B14 -> 8000000
A8: PT Melati Putri | B8: ='KASUS 5.1'!B15 -> 2000000
A9: Toko Hanum | B9: ='KASUS 5.1'!B16 -> 40000000
A10: Cv Lili Kuning | C10: ='KASUS 5.1'!B17 -> 15000000
A11: Toko Anggrek | F11: ='KASUS 5.1'!B18 -> 9000000
A12: Cv Seruni | E12: 6000000
A13: Jumlah Piutang | B13: =SUM(B3:B11) -> 42000000 | C13: =SUM(C3:C11) -> 23000000 | D13: =SUM(D3:D11) -> 18000000 | E13: =E12 -> 6000000 | F13: =SUM(F3:F11) -> 11000000
A14: Jumlah Diskonto | B14: 0.02 | C14: 0.05 | D14: 0.12 | E14: 0.15 | F14: 0.25
A15: Total | B15: 760000 | C15: 2250000 | D15: 480000 | E15: 750000 | F15: 2500000

Sheet KASUS 6.1
A1: REKONSILIASI BANK
A18: NO. CEK | B18: TANGGAL | C18: JUMLAH
A19: 337 | B19: 27 Oktober | C19: Rp. 2.860.000
A20: 338 | B20: 28 Oktober | C20: Rp. 3.194.700
A21: 339 | B21: 28 Oktober | C21: Rp. 830.000
A22: 340 | B22: 29 Oktober | C22: Rp. 2.031.400
A23: 341 | B23: 30 Oktober | C23: Rp. 4.585.300

Sheet KASUS 6.2
A2: Saldo Awal
A3: Rekening Internal | B3: 53884800
A4: Rekening Bank | B4: 32942100
A6: Rekonsiliasi Bank
A8: Saldo Menurut kas | D8: 32942100
A9: Di Tambah
A10: Piutang Wasel | B10: 19000000
A11: Pendapatan Bunga Wasel | B11: 2140000
A12: Pendapatan Bunga Bank | B12: 280100
A13: koreksi salah catat | B13: 3600000
A17: Di Kurang
A18: Beban administrasi Bank | B18: 142500
A19: Cek kosong | B19: 520000
A21: Saldo Akhir | D21: =SUM(D8,B10:B13)-SUM(B18:B19) -> 57299700
A25: Saldo Menurut Bank | D25: 53884800
A26: Di Tambah :
A27: Setoran Dalam Perjalanan | B27: 15916300
A28: Koreksi Bank | B28: 1000000
A30: Di Kurang :
A31: Cek Beredar :
A32: 337 | B32: 2860000
A33: 338 | B33: 3194700
A34: 339 | B34: 830000
A35: 340 | B35: 2031400
A36: 341 | B36: 4585300
A39: Saldo Akhir | D39: =SUM(D25,B27:B28)-SUM(B32:B36) -> 57299700

Sheet KASUS 6.3
A1: Penyesuain
A2: Akun | B2: Reff | C2: Debit | D2: Kredit
A3: Kas | C3: 21140000
A4: Piutang Wasel | D4: 19000000
A5: Pendapatan Bunga Wasel | D5: 2140000
A6: Kas | C6: 280100
A7: Pendapatan Bunga Bank | D7: =C6 -> 280100
A8: Kas | C8: 3600000
A9: Pembelian | D9: 3600000
A10: Beban Administrasi Bank | C10: 142500
A11: Kas | D11: 142500
A12: Piutang Usaha | C12: 520000
A13: Kas | D13: =C12 -> 520000
C14: =SUM(C3:C13) -> 25682600 | D14: =SUM(D3:D13) -> 25682600
B15: Test | C15: =SUM(C3:C13)-SUM('KASUS 6.2'!B10:B19) -> 0 | D15: =D14-SUM('KASUS 6.2'!B10:B19) -> 0

Sheet KASUS 7.1
A1: KAS KECIL

Sheet KASUS 7.2
A1: Metode Dana Tetap
A2: Tanggal | B2: Akun | C2: Reff | D2: Debet | E2: Kredit
A3: 3 Des 2023 | B3: Kas Kecil | D3: 2000000
B4: Kas | E4: 2000000
B5: Tidak Ada Pencatatan
B6: Tidak ada Pencatatan
B7: Tidak Ada Pencatatan
B8: Tidak Ada pencatatan
B9: Tidak Ada pencatatan
B10: a. Perlengkapan Kantor | D10: 96000
B11: b. Beban Angkut Pembelian | D11: 275000
B12: c. Beban Konsumsi Lembur | D12: 150000
B13: d. Peralatan Kantor | D13: 70000
B14: Kas kecil | E14: =SUM(D10:D13) -> 591000
B15: Kas Kecil | D15: Rp 1 500.000
B16: Kas | E16: Rp 1 500.000

Sheet KASUS 7.3
A1: Metode Fluktuatif
A2: Tanggal | B2: Akun | C2: Reff | D2: Debet | E2: Kredit
A3: 3 Des 2023 | B3: Kas Kecil | D3: 2000000
B4: Kas | E4: 2000000
B5: Peralatan Kantor | D5: 96000
B6: Kas Kecil | E6: 96000
B7: Beban Angkut Pembelian | D7: 275000
B8: Kas Kecil | E8: 275000
B9: Beban Konsumsi Lembur | D9: 150000
B10: Kas Kecil | E10: 150000
B11: Perlengkapan Kantor | D11: 70000
B12: Kas Kecil | E12: 70000
B13: Kas Kecil | D13: 591000
B14: Kas | E14: 591000
B15: Kas Kecil | D15: 1 500.000
B16: Kas | E16: =D15 -> 1 500.000

Sheet KASUS 8.1
A1: ANALISA LAPORAN KEUANGAN
A7: Laporan Neraca dan Laba rugi PT Indosat TBK 2024
A8: Kas Ditambah Kas Yang Dibatasi Penggunaanya | B8: =4454098+17882 -> 4471980 | C8: EBIT | D8: 10837896
A9: Hutang Lancar | B9: 31009045 | C9: Biaya Bunga | D9: 4477795
A10: Asset lancar | B10: 14887675 | C10: Pendapatan bersih | D10: 55886870
A11: Piutang | B11: 3281932 | C11: Aktiva Tetap | D11: 99509023
A12: Persediaan | B12: 71815 | C12: Laba bersih (EAIT) | D12: 5272412
A13: Total Hutang | B13: 77734901 | C13: Total Hutang Jangka Panjang | D13: 46725856
A14: Total Asset | B14: 114386698
A15: Ekuisitas | B15: 36651797

Sheet KASUS 8.2
A1: Rasio Liquiditas
A2: Jenis Rasio | B2: Angka Rasio | C2: Interpretasi
A3: Current Ratio | B3: ='KASUS 8.1'!$B$10/'KASUS 8.1'!$B$9 -> 0.4801075 | C3: Artinya setiap Rp 1 hutang lancar dijamin dengan Rp 0,480 Aktiva lancar Atau 0,480:1 antara aktiva lancar dengan hutang lancar. Hasil pengukuran yang rendah menunjukan bahwa Perusahaan kurang modal dalam membayar hutang.
A4: Quick Ratio | B4: =('KASUS 8.1'!$B$10-'KASUS 8.1'!$B$12)/'KASUS 8.1'!$B$9 -> 0.47779156 | C4: Perusahaan masih bergantung dengan persediaan dalam membayar hutangnya artinya perushaan belum bisa mengandalkan asset yang cepat dicairkan seperti kas, setara kas dan piutang usaha karena harus bergantung dengan persediaannya itu.
A5: Cash Ratio | B5: ='KASUS 8.1'!$B$8/'KASUS 8.1'!$B$9 -> 0.14421534 | C5: Perusahaan belum cukup liquid artinya masih bergantung terhadap piutang dan persediaan dalam membayar hutangnya
A7: Rasio Solvabilitas
A8: Jenis Rasio | B8: Angka Rasio | C8: Interpretasi
A9: Debt to Asset Ratio | B9: ='KASUS 8.1'!B13/'KASUS 8.1'!B14 -> 0.6795799 | C9: Rasio ini menunjukan bahwa 68% pendannaan dibiayai oleh hutang. Artinya dari
C10: Rp 100 pendanaan Rp 68 dibiayai oleh hutang dan Rp 32 di sediakan pemegang saham.
A11: Debt to Equity Ratio | B11: ='KASUS 8.1'!B13/'KASUS 8.1'!B15 -> 2.1209029 | C11: Rasio ini menunjukan bahwa kreditor memberikan Rp 212,09 pada tahun 2024 untuk setiap Rp 100 yang disediakan oleh pemegang saham artinya utang perusaan 2,12 kali lipat dari pada modal sendiri.
A12: Time Interest Earned Ratio | B12: ='KASUS 8.1'!D13/'KASUS 8.1'!B15 -> 1.2748585 | C12: Time Interest Earned Ratio adalah 1,27 kali atau dengan kata lain biaya bunga dapat ditutup oleh 1,27 kali dari laba sebelum bunga dan pajak.
A13: Total Asset to Equity Ratio | B13: ='KASUS 8.1'!B14/'KASUS 8.1'!B15 -> 3.1209029 | C13: Hal ini menunjukan bahwa Perusahaan memiliki 3,12 kali asset lebih banyak dibandingkan modal.
A15: Rasio Aktivitas
A16: Jenis Rasio | B16: Angka Rasio | C16: Interpretasi
A17: Sales to Liquid Asset Ratio | B17: ='KASUS 8.1'!D10/'KASUS 8.1'!B8 -> 12.49712 | C17: Rasio ini menandakan bahwa Perusahaan Menghasilkan penjualan 12,50 kali dari total asset liquid yang dimilikinya.
A18: Sales to Receivable Ratio | B18: ='KASUS 8.1'!D10/'KASUS 8.1'!B11 -> 17.02865 | C18: Hal ini berarti perusahaan dapat menghasilkan penjualan sebesar 17,03 kali lipat dari total piutang dagang yang dimilikinya
A19: Sales to Inventory Ratio | B19: ='KASUS 8.1'!D10/'KASUS 8.1'!B12 -> 778.20609 | C19: Perputaran persediaan perusahaan sangat tinggi yaitu 778 kali artinya 778,21 kali persediaan diganti dalam setahun dan dalam sehari sekitar 2 kali mengganti persediaan.
A20: Sales to Current Asset Ratio | B20: ='KASUS 8.1'!D10/'KASUS 8.1'!B10 -> 3.7539018 | C20: Hasil dari rasio Sales to current asset sebesar 3,75 Kali. Hal ini menunjukan bahwa perusahaan menghasilkan Rp 3,75 penjualan untuk setiap rupiah asset lancar yang dimiliki.
A21: Sales to Fixed Asset Ratio | B21: ='KASUS 8.1'!D10/'KASUS 8.1'!D11 -> 0.56162616 | C21: Hasil dari Sales to fixed asset sebesar 0,56 kali menunjukan bahwa perusahaan menghasilkan Rp. 0,56 penjualan untuk setiap rupiah asset tetap yang dimiliki.
A23: Rasio Portabilitas
A24: Jenis Rasio | B24: Angka Rasio | C24: Interpretasi
A25: Net Profit Margin (NPM) | B25: =('KASUS 8.1'!D12/'KASUS 8.1'!D10)*100% -> 0.0943408 | C25: NPM sebesar 9,43% menunjukan bahwa perusahaan berhasil mempertahankan 9,43% keuntungan bersih.
A26: Return on Investment (ROI) | B26: ='KASUS 8.1'!D12/'KASUS 8.1'!B14 -> 0.046092877 | C26: ROI sebesar 4,61% menunjukan bahwa investor berhasil meraih keuntungan sebesar 4,61% dari total investasinya selama satu tahun
A27: Return on Equity (ROE) | B27: ='KASUS 8.1'!D12/'KASUS 8.1'!B15 -> 0.14385139 | C27: ROE sebesar 14,39% menunjukan bahwa perusahaan berhasil menhasilkan 14,39% keuntungan bersih pemegang saham

Sheet KASUS 9
A1: ANALISIS KOMPARATIF
B10: PT DEAL | C10: PT DUEL
A11: Pendapatan | B11: 1850000000 | C11: 1580000000
A12: Laba Bersih | B12: 462500000 | C12: 553000000
A13: Total Aset | B13: 1820000000 | C13: 2059000000
A14: Ekuitas Pemegang Saham | B14: 1000000000 | C14: 1000000000
B31: PT DEAL | C31: PT DUEL
A32: Return on Asset (ROA) | B32: 0.08 | C32: 0.1
A33: Return on Equity (ROE) | B33: 0.1 | C33: 0.12
A34: Net Profit Margin | B34: 0.25 | C34: 0.35

Sheet KASUS 10
A1: ANALISA ARUS KAS

Sheet Kasus 11.1
A44: Produksi | B44: 15
A45: Pengiriman | B45: 3
A46: Penagihan | B46: 10
A47: Pembayaran | B47: 30
A48: Perputaran Pesediaan | B48: 10
A49: Tahun (Hari) | B49: 365
A50: Siklus Pendapatan | B50: =SUM(B44:B47) -> 58
A51: Siklus Pembelian | B51: 7
A52: Siklus Pesediaan | B52: =B49/B48 -> 36.5

Sheet Kasus 11.2
A39: Investasi Awal | B39: 2500000000
A40: Pendapatan yang diharapkan | B40: 1500000000 | C40: 2000000000 | D40: 2500000000
A41: Discoun Rate | B41: 0.13
A42: Nvp | B42: =NPV(B41,B40:D40)-B39 -> 2.1263524e+09
A52: Investasi | B52: Arus Kas Setiap Tahun | C52: Payback Periode
A53: 880000000 | B53: 120000000 | C53: =(A53/B53)*1 -> 7.3333333

Sheet Kasus 11.3
A37: Sewa Perbulan | B37: Tahun (Bulan) | C37: Durasi Sewa (Tahun)
A38: 7800000 | B38: 12 | C38: 8
A39: =A38*B38*C38 -> 748800000
A47: Utang | B47: Bunga | C47: Tempo
A48: 8000000 | B48: 0.065 | C48: 5
A50: Bunga Pertahun | B50: =A48*B48 -> 520000
A51: Bunga jatuh tempo | B51: =A48*B48*C48 -> 2600000
A52: Utang dan bunga jatuh tempo | B52: =SUM(B50:B51) -> 3120000

Sheet Kasus 11.4
A1: ANALISA SUMBER PENGGUNAAN DANA
A3: Arus Kas Operasi | B3: 2012 | C3: 2011 | D3: Varian (Rp) | E3: Varian (%) | F3: kinerja
A4: Penerimaan Dana :
A5: Penerimaan dari pelanggan | B5: 21020109 | C5: 17641866 | D5: =IF(AND(ISBLANK(B5),ISBLANK(C5)),"",B5-C5) -> 3378243 | E5: =IF(AND(ISBLANK(B5),ISBLANK(C5)),"",D5/C5) -> 0.19149012 | F5: =IF((E5)="","",IF(E5<0,"Turun",IF(E5>0,"Naik","Tidak Ada Kenaikan"))) -> Naik
A6: Pendapatan Keuangan | B6: 37935 | C6: 28376 | D6: =IF(AND(ISBLANK(B6),ISBLANK(C6)),"",B6-C6) -> 9559 | E6: =IF(AND(ISBLANK(B6),ISBLANK(C6)),"",D6/C6) -> 0.33686919 | F6: =IF((E6)="","",IF(E6<0,"Turun",IF(E6>0,"Naik","Tidak Ada Kenaikan"))) -> Naik
A7: Pendapatan operasional lain | B7: 30935 | C7: 17374 | D7: =IF(AND(ISBLANK(B7),ISBLANK(C7)),"",B7-C7) -> 13561 | E7: =IF(AND(ISBLANK(B7),ISBLANK(C7)),"",D7/C7) -> 0.78053413 | F7: =IF((E7)="","",IF(E7<0,"Turun",IF(E7>0,"Naik","Tidak Ada Kenaikan"))) -> Naik
E8: =IF(AND(ISBLANK(B8),ISBLANK(C8)),"",D8/C8) | F8: =IF((E8)="","",IF(E8<0,"Turun",IF(E8>0,"Naik","Tidak Ada Kenaikan")))
A9: Pengeluaran Dana : | E9: =IF(AND(ISBLANK(B9),ISBLANK(C9)),"",D9/C9) | F9: =IF((E9)="","",IF(E9<0,"Turun",IF(E9>0,"Naik","Tidak Ada Kenaikan")))
A10: Pembayaran kepada Pemasok dan karyawan | B10: 18567131 | C10: 15745069 | D10: =IF(AND(ISBLANK(B10),ISBLANK(C10)),"",B10-C10) -> 2822062 | E10: =IF(AND(ISBLANK(B10),ISBLANK(C10)),"",D10/C10) -> 0.17923465 | F10: =IF((E10)="","",IF(E10<0,"Turun",IF(E10>0,"Naik","Tidak Ada Kenaikan"))) -> Naik
A11: Pajak Penghasilan | B11: 759000 | C11: 827749 | D11: =IF(AND(ISBLANK(B11),ISBLANK(C11)),"",B11-C11) -> -68749 | E11: =IF(AND(ISBLANK(B11),ISBLANK(C11)),"",D11/C11) -> -0.083055371 | F11: =IF((E11)="","",IF(E11<0,"Turun",IF(E11>0,"Naik","Tidak Ada Kenaikan"))) -> Turun
A12: Tagihan Pajak | C12: 3812 | D12: =IF(AND(ISBLANK(B12),ISBLANK(C12)),"",B12-C12) -> -3812 | E12: =IF(AND(ISBLANK(B12),ISBLANK(C12)),"",D12/C12) -> -1 | F12: =IF((E12)="","",IF(E12<0,"Turun",IF(E12>0,"Naik","Tidak Ada Kenaikan"))) -> Turun | J12: =IF((I12)="","",IF(I12<0,"Turun",IF(I12>0,"Naik","Tidak Ada Kenaikan")))
A13: Biaya Keuangan | B13: 72922 | C13: 58816 | D13: =IF(AND(ISBLANK(B13),ISBLANK(C13)),"",B13-C13) -> 14106 | E13: =IF(AND(ISBLANK(B13),ISBLANK(C13)),"",D13/C13) -> 0.2398327 | F13: =IF((E13)="","",IF(E13<0,"Turun",IF(E13>0,"Naik","Tidak Ada Kenaikan"))) -> Naik
D14: =IF(AND(ISBLANK(B14),ISBLANK(C14)),"",B14-C14) | E14: =IF(AND(ISBLANK(B14),ISBLANK(C14)),"",D14/C14) | F14: =IF((E14)="","",IF(E14<0,"Turun",IF(E14>0,"Naik","Tidak Ada Kenaikan")))
A15: Total Penerimaan Dana | B15: =SUM(B5:B7) -> 21088979 | C15: =SUM(C5:C7) -> 17687616 | D15: =IF(AND(ISBLANK(B15),ISBLANK(C15)),"",B15-C15) -> 3401363 | E15: =IF(AND(ISBLANK(B15),ISBLANK(C15)),"",D15/C15) -> 0.19230195 | F15: =IF((E15)="","",IF(E15<0,"Turun",IF(E15>0,"Naik","Tidak Ada Kenaikan"))) -> Naik
A16: Total Pengeluaran Dana | B16: =SUM(B10:B12) -> 19326131 | C16: =SUM(C10:C13) -> 16635446 | D16: =IF(AND(ISBLANK(B16),ISBLANK(C16)),"",B16-C16) -> 2690685 | E16: =IF(AND(ISBLANK(B16),ISBLANK(C16)),"",D16/C16) -> 0.16174409 | F16: =IF((E16)="","",IF(E16<0,"Turun",IF(E16>0,"Naik","Tidak Ada Kenaikan"))) -> Naik
A35: Arus Kas Investasi | B35: =B3 -> 2012 | C35: =C3 -> 2011 | D35: =D3 -> Varian (Rp) | E35: =E3 -> Varian (%) | F35: =F3 -> kinerja
A36: Penerimaan Dana
A37: Penerimaan dari hasil penjualan asset tetap | B37: 53957 | C37: 11725 | D37: =IF(AND(ISBLANK(B37),ISBLANK(C37)),"",B37-C37) -> 42232 | E37: =IF(AND(ISBLANK(B37),ISBLANK(C37)),"",D37/C37) -> 3.6018763 | F37: =IF((E37)="","",IF(E37<0,"Turun",IF(E37>0,"Naik","Tidak Ada Kenaikan"))) -> Naik
D38: =IF(AND(ISBLANK(B38),ISBLANK(C38)),"",B38-C38) | E38: =IF(AND(ISBLANK(B38),ISBLANK(C38)),"",D38/C38) | F38: =IF((E38)="","",IF(E38<0,"Turun",IF(E38>0,"Naik","Tidak Ada Kenaikan")))
A39: Penggunaan Dana : | D39: =IF(AND(ISBLANK(B39),ISBLANK(C39)),"",B39-C39) | E39: =IF(AND(ISBLANK(B39),ISBLANK(C39)),"",D39/C39) | F39: =IF((E39)="","",IF(E39<0,"Turun",IF(E39>0,"Naik","Tidak Ada Kenaikan")))
A40: Perolehan asset tetap | B40: 1712469 | C40: 1432350 | D40: =IF(AND(ISBLANK(B40),ISBLANK(C40)),"",B40-C40) -> 280119 | E40: =IF(AND(ISBLANK(B40),ISBLANK(C40)),"",D40/C40) -> 0.19556603 | F40: =IF((E40)="","",IF(E40<0,"Turun",IF(E40>0,"Naik","Tidak Ada Kenaikan"))) -> Naik
A41: Uang muka Pembelian Asset tatap | B41: 132842 | C41: 18082 | D41: =IF(AND(ISBLANK(B41),ISBLANK(C41)),"",B41-C41) -> 114760 | E41: =IF(AND(ISBLANK(B41),ISBLANK(C41)),"",D41/C41) -> 6.3466431 | F41: =IF((E41)="","",IF(E41<0,"Turun",IF(E41>0,"Naik","Tidak Ada Kenaikan"))) -> Naik
A42: Akuisisi Entitas anak di kuraingi kas yang diperoleh | C42: 14933 | D42: =IF(AND(ISBLANK(B42),ISBLANK(C42)),"",B42-C42) -> -14933 | E42: =IF(AND(ISBLANK(B42),ISBLANK(C42)),"",D42/C42) -> -1 | F42: =IF((E42)="","",IF(E42<0,"Turun",IF(E42>0,"Naik","Tidak Ada Kenaikan"))) -> Turun
A43: Total Penerimaan Dana | B43: =SUM(B37) -> 53957 | C43: =SUM(C37) -> 11725 | D43: =IF(AND(ISBLANK(B43),ISBLANK(C43)),"",B43-C43) -> 42232 | E43: =IF(AND(ISBLANK(B43),ISBLANK(C43)),"",D43/C43) -> 3.6018763 | F43: =IF((E43)="","",IF(E43<0,"Turun",IF(E43>0,"Naik","Tidak Ada Kenaikan"))) -> Naik
A44: Total Pengeluaran Dana | B44: =SUM(B40:B41) -> 1845311 | C44: =SUM(C35:C40) -> 1446086 | D44: =IF(AND(ISBLANK(B44),ISBLANK(B44)),"",B44-C44) -> 399225 | E44: =IFERROR(IF(D44="","",IF(D44="Tidak ada varian",D44,IF((B44-C44)/C44=0,"Tidak ada varian",IF((B44-C44)/C44>0,(B44-C44)/C44,IF(C44<0,(B44-C44)/ABS(C44),(B44-C44)/C44))))),100%) -> 0.27607279 | F44: =IF(E44="","",IF(E44="Tidak Ada Varian","Tidak ada varian",IF(E44>0%,"Naik","Turun"))) -> Naik
A58: Arus Kas Pendannaan | B58: =B35 -> 2012 | C58: =C35 -> 2011 | D58: =D35 -> Varian (Rp) | E58: =E35 -> Varian (%) | F58: =F35 -> kinerja
A59: Sumber Dana
A60: Penerimaan dari : | D60: =IF(AND(ISNUMBER(FIND(":",A60)),B60="",C60=""),"",IF(AND(A60<>"",B60="",C60="",""),"Tidak ada varian",IF(AND(A60="",B60="",C60=""),"",IF((C60-B60)=0,"Tidak ada varian",B60-C60)))) | E60: =IFERROR(IF(D60="","",IF(D60="Tidak ada varian",D60,IF((B60-C60)/C60=0,"Tidak ada varian",IF((B60-C60)/C60>0,(B60-C60)/C60,IF(C60<0,(B60-C60)/ABS(C60),(B60-C60)/C60))))),100%) | F60: =IF(E60="","",IF(E60="Tidak Ada Varian","Tidak ada varian",IF(E60>0%,"Naik","Turun")))
A61: Utang Jangka pendek | B61: 318438 | C61: 660818 | D61: =IF(AND(ISBLANK(B61),ISBLANK(C61)),"",B61-C61) -> -342380 | E61: =IF(AND(ISBLANK(B61),ISBLANK(C61)),"",D61/C61) -> -0.51811543 | F61: =IF((E61)="","",IF(E61<0,"Turun",IF(E61>0,"Naik","Tidak Ada Kenaikan"))) -> Turun
A62: Utang Jangka panjang | B62: 646800 | C62: 884384 | D62: =IF(AND(ISBLANK(B62),ISBLANK(C62)),"",B62-C62) -> -237584 | E62: =IF(AND(ISBLANK(B62),ISBLANK(C62)),"",D62/C62) -> -0.26864349 | F62: =IF((E62)="","",IF(E62<0,"Turun",IF(E62>0,"Naik","Tidak Ada Kenaikan"))) -> Turun
D63: =IF(AND(ISBLANK(B63),ISBLANK(C63)),"",B63-C63) | E63: =IF(AND(ISBLANK(B63),ISBLANK(C63)),"",D63/C63) | F63: =IF((E63)="","",IF(E63<0,"Turun",IF(E63>0,"Naik","Tidak Ada Kenaikan")))
A64: Penggunaan Dana : | D64: =IF(AND(ISBLANK(B64),ISBLANK(C64)),"",B64-C64) | E64: =IF(AND(ISBLANK(B64),ISBLANK(C64)),"",D64/C64) | F64: =IF((E64)="","",IF(E64<0,"Turun",IF(E64>0,"Naik","Tidak Ada Kenaikan")))
A65: Pembayaran Untuk : | D65: =IF(AND(ISBLANK(B65),ISBLANK(C65)),"",B65-C65) | E65: =IF(AND(ISBLANK(B65),ISBLANK(C65)),"",D65/C65) | F65: =IF((E65)="","",IF(E65<0,"Turun",IF(E65>0,"Naik","Tidak Ada Kenaikan")))
A66: Deviden Tunai | B66: 688716 | C66: 652640 | D66: =IF(AND(ISBLANK(B66),ISBLANK(C66)),"",B66-C66) -> 36076 | E66: =IF(AND(ISBLANK(B66),ISBLANK(C66)),"",D66/C66) -> 0.055277029 | F66: =IF((E66)="","",IF(E66<0,"Turun",IF(E66>0,"Naik","Tidak Ada Kenaikan"))) -> Naik
A67: Utang bank jangka pendek | B67: 90850 | C67: 426640 | D67: =IF(AND(ISBLANK(B67),ISBLANK(C67)),"",B67-C67) -> -335790 | E67: =IF(AND(ISBLANK(B67),ISBLANK(C67)),"",D67/C67) -> -0.787057 | F67: =IF((E67)="","",IF(E67<0,"Turun",IF(E67>0,"Naik","Tidak Ada Kenaikan"))) -> Turun
A68: Utang bank jangka panjang | B68: 37697 | C68: 542574 | D68: =IF(AND(ISBLANK(B68),ISBLANK(C68)),"",B68-C68) -> -504877 | E68: =IF(AND(ISBLANK(B68),ISBLANK(C68)),"",D68/C68) -> -0.93052192 | F68: =IF((E68)="","",IF(E68<0,"Turun",IF(E68>0,"Naik","Tidak Ada Kenaikan"))) -> Turun
A69: Deviden Tunai kepada pemegang saham : | D69: =IF(AND(ISBLANK(B69),ISBLANK(C69)),"",B69-C69) | E69: =IF(AND(ISBLANK(B69),ISBLANK(C69)),"",D69/C69) | F69: =IF((E69)="","",IF(E69<0,"Turun",IF(E69>0,"Naik","Tidak Ada Kenaikan")))
A70: Non Pengendali entitas anak | B70: 5162 | C70: 2423 | D70: =IF(AND(ISBLANK(B70),ISBLANK(C70)),"",B70-C70) -> 2739 | E70: =IF(AND(ISBLANK(B70),ISBLANK(C70)),"",D70/C70) -> 1.1304168 | F70: =IF((E70)="","",IF(E70<0,"Turun",IF(E70>0,"Naik","Tidak Ada Kenaikan"))) -> Naik
A71: Utang sewa pembiyaaan | B71: 183 | C71: 842 | D71: =IF(AND(ISBLANK(B71),ISBLANK(C71)),"",B71-C71) -> -659 | E71: =IF(AND(ISBLANK(B71),ISBLANK(C71)),"",D71/C71) -> -0.78266033 | F71: =IF((E71)="","",IF(E71<0,"Turun",IF(E71>0,"Naik","Tidak Ada Kenaikan"))) -> Turun
D72: =IF(AND(ISBLANK(B72),ISBLANK(C72)),"",B72-C72) | E72: =IF(AND(ISBLANK(B72),ISBLANK(C72)),"",D72/C72) | F72: =IF((E72)="","",IF(E72<0,"Turun",IF(E72>0,"Naik","Tidak Ada Kenaikan")))
...

Sheet Kasus12.1
K4: Nilai Nolinal | L4: 15000000
K5: Kupon (%) | L5: 0.07
K6: Bunga Pasar | L6: 0.1
K7: Jamgka Waktu (Tahun) | L7: 5
K8: Kupon Per Tahun | L8: =L4*L5 -> 1050000
K9: Nilai Obligasi Kini | L9: =ABS(PV(L6,L7,L8,L4,0)) -> 13294146

Sheet Kasus 12.2
A15: Tanggal | B15: Akun | C15: Reff | D15: Debet | E15: Kredit
A16: =DATE(2006,1,1) -> 38718 | B16: Kas | D16: 200000000
B17: Hutang Obnigasi | E17: =D16 -> 200000000
B18: (Saat Penerbitan)
A19: =DATE(2006,7,1) -> 38899 | B19: Biaya Bunga Obligasi | D19: =200000000/2*10% -> 10000000
B20: Kas | E20: =D19 -> 10000000
A22: =DATE(2009,12,31) -> 40178 | B22: Biaya Bunga Obligasi | D22: 1000000
B23: Hutang Obligasi | E23: 10000000

Sheet Kasus 12.3
A13: Tanggal | B13: Jenis Obligasi | C13: Akun | D13: Reff | E13: Debit | F13: Kredit
A14: =DATE(2006,1,1) -> 38718 | B14: Diskonto Obligasi | C14: (Saat Penerbitan)
C15: Kas | E15: =98%*F17 -> 196000000
C16: Disknto Obligasi | E16: =F17-E15 -> 4000000
C17: Hutang bligasi | F17: 200000000
A18: =DATE(2006,7,1) -> 38899 | C18: (Pembayaran Bunga Pertama)
C19: Beban Bunga Obligasi | E19: =SUM(F20:F21) -> 10200000
C20: Diskonto Obligasi | F20: =E16/10/2 -> 200000
C21: Kas | F21: =F17*6/12*10% -> 10000000
A22: =DATE(2006,12,31) -> 39082 | C22: (Penyesuaian Obligasi)
C23: Beban Bunga Obligasi | E23: =E19 -> 10200000
C24: Diskonto Obligasi | F24: =F20 -> 200000
C25: Hutang Obligasi | F25: =F21 -> 10000000
A27: =A14 -> 38718 | B27: Premium Obligasi | C27: =C14 -> (Saat Penerbitan)
C28: =C15 -> Kas | E28: =F30*103% -> 206000000
C29: Premium Obligasi | F29: =E28-F30 -> 6000000
C30: =C17 -> Hutang bligasi | F30: 200000000
A31: =A18 -> 38899 | C31: =C18 -> (Pembayaran Bunga Pertama)
C32: =C19 -> Beban Bunga Obligasi | E32: =F34-E33 -> 9700000
C33: Premium Atas Obligasi | E33: =F29/10/2 -> 300000
C34: =C21 -> Kas | F34: =F30*6/12*10% -> 10000000
A35: =A22 -> 39082 | C35: =C22 -> (Penyesuaian Obligasi)
C36: =C23 -> Beban Bunga Obligasi | E36: =E32 -> 9700000
C37: =C33 -> Premium Atas Obligasi | E37: =E33 -> 300000
C38: =C25 -> Hutang Obligasi | F38: =F34 -> 10000000

Sheet Kasus 13.1
A19: Menghitung Besarnya Perolehan Tanah :
A20: Harga Pasar Aktiva Yang Diberikan | B20: 50000000
A21: Kas Yang di Berikan | B21: 25000000
A22: Harga Perolehan tanah | B22: =SUM(B20:B21) -> 75000000
A24: Keuntungan Atau Kerugan :
A25: Nilai Pasar Mobil | C25: =B20 -> 50000000
A26: Nilai Buku Mobil | B26: 100000000
A27: Ak,u;;asi Penyusutan | B27: -36000000
A28: Nilai Buku Mobil | C28: -64000000
A29: Kerugian Pertukaran Mobil Bekas | C29: =C25+C28 -> -14000000
A31: Tanggal | B31: Nama Akun | C31: Reff | D31: Debit (Rp) | E31: Kredit (Rp)
B32: Tanah | D32: =B22 -> 75000000
B33: Akumulasi Penyusutan Mobil | D33: =ABS(B27) -> 36000000
B34: Kerugian Pertukaran | D34: =ABS(C29) -> 14000000
B35: Mobil | E35: =B26 -> 100000000
B36: Kas | E36: =B21 -> 25000000

Sheet Kasus 3.2
A21: Nilai Buku Laptop Bekas Dan Perolehan Laptop Baru : | D21: Tanggal | E21: Akun | F21: Reff | G21: Debit | H21: Kredit
A22: Harga Perolehan Laptop Bekas | B22: 30000000 | E22: Laptop Baru | G22: =B30 -> 32000000
A23: Akmulasi Penyusutan Komputer Bekas | B23: -12000000 | E23: Akumulasi Penyusutan Laptop Bekas | G23: =ABS(B23) -> 12000000
A24: Nilai Komputer Bekas | B24: =-SUM(B22:B23) -> -18000000 | E24: Kerugian Pertukaran | G24: =ABS(B39) -> 4000000
E25: Laptop Bekas | H25: =B22 -> 30000000
A26: Harga Laptop Baru | B26: 35000000 | E26: Kas | H26: =ABS(B38) -> 18000000
A27: Harga Kasepakatan Dan Tawar Menawar Oleh Pihak Toko | B27: -17000000
A28: Jumlah Bayar | B28: =SUM(B26:B27) -> 18000000
A29: Harga Laptop Bekas | B29: 14000000
A30: Total Perolehan Laptop Baru | B30: =SUM(B28:B29) -> 32000000
A33: Kerugian Pertukaran Sejenis :
A34: Harga Perolehan Pasar Laptop Bekas | B34: =B29 -> 14000000
A35: Nilai Buku Laptop Bekas :
A36: Harga Perolehan Pasar Laptop Bekas | B36: =B22 -> 30000000
A37: Akumulasi Penyusutan Laptop Bekas | B37: =B23 -> -12000000
A38: Nilai Buku Laptop Bekas : | B38: =-SUM(B36:B37) -> -18000000
A39: Kerugian Pertukaran Laptop Bekas | B39: =B34+B38 -> -4000000

Sheet Kasus 13.3
A20: Penyusutan per tahun :
A21: Harga Perolehan | B21: 100000000
A22: Nulai Residu | B22: 10000000
A23: Umur Ekonomis | B23: 10
A24: Penyusutan per tahun | B24: =(B21-B22)/B23 -> 9000000
A26: Jurnal Penyesuian Awal
A27: Tanggal | B27: Akun | C27: Reff | D27: Debit | E27: Kredit
B28: Biaya penyusutan mesin | D28: =B24 -> 9000000
B29: Akumulasi Penyusutan Bekas | E29: =D28 -> 9000000
A31: Nilai Buku Mesin Sebelum Disusutkan :
A32: Harga Perolehan | B32: =B21 -> 100000000
A33: Pembelian | B33: =DATE(2015,1,1) -> 42005
A34: Perbaikan | B34: =DATE(2022,7,1) -> 44743
A35: Umur Mesin (Udah Dipakai) | B35: =ROUND(((B34-B33)/365),1) -> 7.5
A36: Penyusutan Pertahun | B36: =B24 -> 9000000
A37: Total Penyusutan | B37: =B35*B36 -> 67500000
A38: Nilai Buku Mesin | B38: =B32-B37 -> 32500000
A40: Jurnal Perbaikan Mesin
A41: Tanggal | B41: Akun | C41: Reff | D41: Debit | E41: Kredit
B42: Akumulasi Penyusutan | D42: =B47 -> 27000000
B43: Kas | E43: =D42 -> 27000000
A45: Perhitungan Penyusutan Pertahun dilakukan Perbaikan Pada akhir Tahun 2022 :
A46: Nilai Buku | B46: =B38 -> 32500000
A47: Nilai Aktiva Yang Diganti | B47: 27000000
A48: Nilai Residu | B48: =-B22 -> -10000000
A49: Umur beli | B49: =B23 -> 10
A50: Sisa Umur Ekonomis | B50: =ABS(B35-B49) -> 2.5
A51: Tambahan | B51: 1.5
A52: Total Umur | B52: =SUM(B50:B51) -> 4
A53: Biaya Penyutan Pertahuan | B53: =((B46+B47)+B48)/B52 -> 12375000
A54: Penyusutan Diakhir 2022 makaSetengah Tahun, Maka :
A55: Harga Perolehan
A56: Akhir 2022 | B56: =DATE(2022,12,31) -> 44926
A57: Umur akhir 2022 | B57: =INT((ABS(B34-B56)/30)) -> 6
A58: Dalam Pecahan | B58: {=_xlfn.IFS($B$57=1,$I$59,$B$57=2,$I$60,$B$57=3,$I$61,$B$57=4,$I$62,$B$57=5,$I$63,$B$57=6,$I$64,$B$57=7,$I$65,$B$57=8,$I$66,$B$57=9,$I$67,$B$57=10,#REF!,$B$57=11,$I$68,$B$57=12,$I$69)} -> 0.5
A59: Penyustan akhit Tahun | B59: =B58*B53 -> 6187500 | H59: {=_xlfn.SEQUENCE(12,)} -> 1 | I59: =H59/12 -> 0.083333333
A60: Jurnal Penyesuaian Setelah Perbaikan | H60: 2 | I60: =H60/12 -> 0.16666667
A61: Tanggal | B61: Akun | C61: Reff | D61: Debit | E61: Kredit | H61: 3 | I61: =H61/12 -> 0.25
B62: Biaya Penyusutan Penyusutan | D62: =B59 -> 6187500 | H62: 4 | I62: =H62/12 -> 0.33333333
B63: Akumulasi penyusutan | E63: =B59 -> 6187500 | H63: 5 | I63: =H63/12 -> 0.41666667
...

Sheet Kasus 13.4
A13: Penyusutan Pertahun
A14: Harga Perolehan | B14: 250000000
A15: Nilai Residu | B15: 0
A16: Umur Ekonomis | B16: 5
A17: Penyusutan Pertahun | B17: =(B14-B15)/B16 -> 50000000
A19: Jurnal Penyesuaian
A20: Tanggal | B20: Akun | C20: Ref | D20: Debit | E20: Kredit
B21: Biaya Penyusutan Mesin | D21: =B17 -> 50000000
B22: Akumulasi Penyusutan Bekas | E22: =B17 -> 50000000
A24: Mulai | B24: =DATE(2020,1,1) -> 43831
A25: Penghentian | B25: =DATE(2023,1,1) -> 44927
A26: Umur Pakai | B26: =ROUND(((B25-B24)/365),1) -> 3
A27: ="Akimulasi Penyusutan Selama "&INT(B26)&" Tahun" -> Akimulasi Penyusutan Selama 3 Tahun | B27: =B17*B26 -> 150000000
A28: Rugi Untung | B28: =B27-B14 -> -100000000
A30: Jurnal Penghentian Mesin
A31: Tanggal | B31: Akun | C31: Ref | D31: Debit | E31: Kredit
B32: Akumulasi penyusutan mesin | D32: =B27 -> 150000000
B33: Rugi penghentian Mesin | D33: =ABS(B28) -> 100000000
B34: Mesin | E34: =SUM(D32:D33) -> 250000000

Sheet Kasus 13.5
A14: Penyusutan Pertahun
A15: Harga Perolehan | B15: 120000000
A16: Nilai Residu | B16: 10000000
A17: Umur Ekonomis | B17: 10
A18: Penyusutan Pertahun | B18: =(B15-B16)/B17 -> 11000000
A20: Total Akumulasi Penyusutan Sebelum Dijual
A21: Mulai | B21: =DATE(2017,1,1) -> 42736
A22: Dijual | B22: =DATE(2019,7,1) -> 43647
A23: Umur Pakai | B23: =ROUND(((B22-B21)/365),1) -> 2.5
A24: Akumulai Penyusutan (Pakai) | B24: =B18*B23 -> 27500000
A25: Nilai Buku Mesin | B25: =B15-B24 -> 92500000
A26: ="Jika Harga Jual Tanggal"&TEXT($B$22,"[$-21] DD MMMM YYYY")&" Sebesar :" -> Jika Harga Jual Tanggal 01 Juli 2019 Sebesar : | B26: 87000000
A27: ="Jika Harga jual Tanggal"&TEXT($B$22,"[$-21] DD MMMM YYYY")&" Sebesar :" -> Jika Harga jual Tanggal 01 Juli 2019 Sebesar : | B27: 70000000
A28: ="Rugi Untung jika Dijual Sebesar"&TEXT(B26," 0#.##0") -> Rugi Untung jika Dijual Sebesar 87.000.000 | B28: =B26-B25 -> -5500000
A29: ="Rugi Untung jika Dijual Sebesar"&TEXT(B27," 0#.##0") -> Rugi Untung jika Dijual Sebesar 70.000.000 | B29: =B27-B25 -> -22500000
A31: Jurnal Rugi
A32: Tanggal | B32: Akun | C32: Reff | D32: Debit | E32: Kredit
B33: Kas | D33: =B26 -> 87000000
B34: Akumulasi Penyusutan | D34: =B24 -> 27500000
B35: Kerugian Penjualan | D35: =ABS(B28) -> 5500000
B36: Mesin | E36: =SUM(D33:D35) -> 120000000
A37: Jurnal Rugi
A38: Tanggal | B38: Akun | C38: Reff | D38: Debit | E38: Kredit
B39: Kas | D39: =B27 -> 70000000
B40: Akumulasi Penyusutan | D40: =B24 -> 27500000
B41: Kerugian Penjualan | D41: =ABS(B29) -> 22500000
B42: Mesin | E42: =SUM(D39:D41) -> 120000000

Sheet Kasus 14.1
A83: Pendapatan Keluarga Ibu Sarah | B83: 3500000
A84: Suami Ibu Sarah | B84: 1700000
A85: Total Pendapatan | B85: =SUM(B83:B84) -> 5200000
A87: Pengeluaran Bulanan
A88: Biaya Rumah Tangga | B88: -1200000
A89: Air,Telepon, Listrik | B89: -350000
A90: Pendidikan | B90: -1000000
A91: Lain-lain | B91: -200000
A92: Angsuran Kredis Sebelumnya | B92: -500000
A93: Total Pengeluaran | B93: =SUM(B88:B92) -> -3250000
A94: Penadaptan Bersih | B94: =B85 -> 5200000
A95: Kas Sisa | B95: =B94+B93 -> 1950000
A97: Angsuran Pokok | B97: -12000000
A98: Durasi Angsuran | B98: 24
A99: Angsuran Pinjaman Baru | B99: =B97/B98 -> -500000
A100: Bunga (flat) | B100: 0.015
A101: Total Angsuran Perbulan | B101: =(B97*B100)+B99 -> -680000
A102: Sisa Pendapatan Setelah Cicilan | B102: =B95+B101 -> 1270000

Sheet Kasus 15.1
B35: Mie Soto | C35: Mie Ayam Bawang | D35: Total
A36: Unit yang diproduksi/tahun | B36: 10000 | C36: 20000
A37: Biaya utama | B37: 80000000 | C37: 120000000 | D37: 200000000
A39: Jam tenaga kerja langsung | B39: 10000 | C39: 20000 | D39: 30000
A40: Jam kerja mesin | B40: 5000 | C40: 10000 | D40: 15000
A41: Pergerakan produksi | B41: 10 | C41: 20 | D41: 30
A42: Number of moves | B42: 60 | C42: 30 | D42: 90
B43: Data per Departemen
B44: Dept. pemrosesan | C44: Dept. pengemasan | D44: Total
A45: Jam tenaga kerja langsung
A46: Mie Soto | B46: 3000 | C46: 7000 | D46: 10000
A47: Mie Ayam Bawang | B47: 5000 | C47: 15000 | D47: 20000
A48: Total | B48: 8000 | C48: 22000 | D48: 30000
A50: Jam kerja mesin
A51: Mie Soto | B51: 1000 | C51: 4000 | D51: 5000
A52: Mie Ayam Bawang | B52: 2000 | C52: 8000 | D52: 10000
A53: Total | B53: 3000 | C53: 12000 | D53: 15000
B54: Dept. pemrosesan | C54: Dept. pengemasan | D54: Total
A55: Biaya overhead pabrik
A56: Biaya penyetelan | B56: 10000000 | C56: 90000000 | D56: 100000000
A57: Biaya penanganan material | B57: 8000000 | C57: 72000000 | D57: 80000000
A58: Biaya listrik dan energi | B58: 60000000 | C58: 60000000 | D58: 120000000
A59: Biaya inspeksi | B59: 30000000 | C59: 30000000 | D59: 60000000
A60: Total | B60: 108000000 | C60: 252000000 | D60: 360000000

Sheet Kasus.15.2
A1: 1. Mengelompokan Biaya Overhead Dari Setiap Aktivitas
A2: Jenis Biaya | B2: Jumlah (Rp) | C2: Jenis Aktivitas
A3: Biaya Penyetelan | B3: ='Kasus 15.1'!D56 -> 100000000 | C3: Batch - Level Activity
A4: Biaya Penanganan Material | B4: ='Kasus 15.1'!B57 -> 8000000 | C4: Batch - Level Activity
A5: Total Biaya | B5: 180000000
A6: Biaya Listrik Dan Energi | B6: ='Kasus 15.1'!B58 -> 60000000 | C6: Unit Level Ackivity
A7: Biaya Infeksi | B7: ='Kasus 15.1'!B59 -> 30000000 | C7: Unit Level Activity
A8: Total Biaya | B8: 180000000
A10: 2. Menghitung Biaya Overhead Pabrik Perkelompok (Pool Rate)
A11: Jenis Aktivitas | B11: Total Biaya | C11: Dasar Tarif | D11: Tarif BOP
A12: Batch-Level Activity | B12: =B5 -> 180000000 | C12: ='Kasus 15.1'!D41 -> 30 | D12: 6000000
A13: Unit Level Acivity | B13: =B8 -> 180000000 | C13: ='Kasus 15.1'!D40 -> 15000 | D13: =B13/C13 -> 12000
A15: 3. Membebankan Biaya Overhead Pabrik
A16: Jenis Aktivitas | B16: Tarif BOP | C16: Aktivitas yang Digunakan | D16: Pembebanan BOP
A17: Batch-Level Activity
A18: Mie Soto | B18: =D12 -> 6000000 | C18: ='Kasus 15.1'!B41 -> 10 | D18: =B18*C18 -> 60000000
A19: Mie Bawang | B19: =D12 -> 6000000 | C19: ='Kasus 15.1'!C41 -> 20 | D19: =B19*C19 -> 120000000
A20: Unit Level Acivity
A21: Mie Soto | B21: =D13 -> 12000 | C21: ='Kasus 15.1'!B40 -> 5000 | D21: =B21*C21 -> 60000000
A22: Mie Bawang | B22: =D13 -> 12000 | C22: ='Kasus 15.1'!C40 -> 10000 | D22: =B22*C22 -> 120000000
A24: 4. Perhitungan Harga Pokok Produksi
A25: Keterangan | B25: Mie Soto | C25: Mie Ayam Bawang
A26: Biaya Utama | B26: ='Kasus 15.1'!B37 -> 80000000 | C26: ='Kasus 15.1'!C37 -> 120000000
A27: Biaya Overhead :
A28: Batch Level Activity | B28: =D18 -> 60000000 | C28: =D19 -> 120000000
A29: Unit Level Activity | B29: =D21 -> 60000000 | C29: =D22 -> 120000000
A30: Total Biaya Produksi | B30: =SUM(B26:B29) -> 200000000 | C30: =SUM(C26:C29) -> 360000000
A31: Unit yang diproduksi | B31: ='Kasus 15.1'!B36 -> 10000 | C31: ='Kasus 15.1'!C36 -> 20000
A32: Harga Pokok PerUnit | B32: =B30/B31 -> 20000 | C32: =C30/C31 -> 18000

Sheet Kasus 16
A47: Keterangan | B47: Varians | C47: Kesimpulan
C48: (U/F)
A49: Pembelian Bahan Baku | B49: =(850000-900000)*280 -> -14000000 | C49: =IF(B49<0,"F (Menguntungkan)",IF(B49>0,"U (Rugi)","Varian Tidak Muncul")) -> F (Menguntungkan)
A50: Pemakaian Bahan Baku | B50: =((0.3*800)-240)*900000 -> 0 | C50: =IF(B50<0,"F (Menguntungkan)",IF(B50>0,"U (Rugi)","Varian Tidak Muncul")) -> Varian Tidak Muncul
A51: Pembayaran Upah Tenaga Kerja Langsung | B51: =(60000-55000)*2000 -> 10000000 | C51: =IF(B51<0,"F (Menguntungkan)",IF(B51>0,"U (Rugi)","Varian Tidak Muncul")) -> U (Rugi)
A52: Pembebanan Biaya Tenaga Kerja Langsung | B52: =((2.5*800)-2000)*5500 -> 0 | C52: =IF(B52<0,"F (Menguntungkan)",IF(B52>0,"U (Rugi)","Varian Tidak Muncul")) -> Varian Tidak Muncul
A53: Varian Overhead Pabrik | B53: =(180000000+90000000+120000000+35000000)-(18*800*18000) -> 165800000 | C53: =IF(B53<0,"F (Menguntungkan)",IF(B53>0,"U (Rugi)","Varian Tidak Muncul")) -> U (Rugi)
A55: Keterangan | B55: Kredit | C55: Kredit
A56: Mencatat Pembelian Bahan Baku :
A57: Persediaan Bahan baku | B57: =900000*280 -> 252000000
A58: Varian Bahan Baku | C58: =B57-C59 -> 14000000
A59: Utang dagang | C59: =850000*280 -> 238000000
A60: Mencatat Pemakaian Bahan Baku :
A61: BDP Bahan Baku | B61: =(0.3*800*900000) -> 216000000
A62: Persediaaan Bahan baku | C62: =240*900000 -> 216000000
A63: Mencatat Biaya Tenaga Kerja Langsung :
A64: Gaji dan upah | B64: =2000*55000 -> 110000000
A65: Varian Gaji | B65: =ABS(B64-C66) -> 10000000
A66: Kas | C66: =2000*60000 -> 120000000
A67: Mencatat Biaya Overhead Pabrik (BOP) :
A68: Persediaan BDP – BOP | B68: =18*800*18000 -> 259200000
A69: BOP dibebankan | C69: =B68 -> 259200000
A71: BOP Sesungguhnya | B71: =+SUM(C72:C75) -> 425000000
A72: Biaya Tenaga Kerja Tidak Langsung (Kas) | C72: 120000000
A73: Biaya Penyusutan Mesin | C73: 180000000
A74: Biaya Listrik (Masih terutang) | C74: 90000000
A75: Biaya Bahan Baku Tidak Langsusng (Perlengkapan Pabrik ) | C75: 35000000
A77: BOP dibebankan | B77: =18*800*18000 -> 259200000
A78: Varian Overhead Pabrik | B78: =ABS(B77-C79) -> 165800000
A79: BOP Sesungguhnya | C79: =180000000+90000000+120000000+35000000 -> 425000000
A80: Mencatat Pembebanan Gaji Dan Upah Langsung :
A81: BDP-BTKL | B81: =B64 -> 110000000
A82: Gaji Dan Upah | C82: =B64 -> 110000000
A83: Mencatat Varian :
A84: Varaian bahan baku | B84: =C58 -> 14000000
A85: Harga Pokok Penjualan (selisih antara debit dan total varian) | B85: =ABS(B84-SUM(C86:C87)) -> 161800000
A86: Varian gaji dan upah | C86: =B65 -> 10000000
A87: Varian overhead Pabrik | C87: =B78 -> 165800000
A88: Mencatat Persediaan Produk Jadi :
A89: Persedian Produk Jadi | B89: =B61+B64+B77 -> 585200000
...

Sheet Kasus 17
A9: Tahun | B9: Jumlah
A10: Tahun 1 | B10: 70000
A11: Tahun 2 | B11: 120000
A12: Tahun 3 | B12: 140000
A13: Tahun 4 | B13: 140000
A14: Tahun 5 | B14: 40000
A24: Tahun | B24: Ars Kas | C24: Tingkat Bunga | D24: Nilai Sekarang | E24: Tingkat Bunga | F24: Nilai Sekarang (PV)
B25: -400000 | C25: 0.09 | E25: 0.08
A26: {=_xlfn.SEQUENCE(ROWS(B26:B30))} -> 1 | B26: =B10 -> 70000 | C26: =(1/(1+9%)^A26) -> 0.91743119 | D26: =(B26*C26) -> 64220.183 | E26: =(1/(1+E25))^A26 -> 0.92592593 | F26: =(B26*E26) -> 64814.815
A27: 2 | B27: =B11 -> 120000 | C27: =(1/(1+9%)^A27) -> 0.84167999 | D27: =(B27*C27) -> 101001.6 | E27: =(1/(1+8%))^A27 -> 0.85733882 | F27: =(B27*E27) -> 102880.66
A28: 3 | B28: =B12 -> 140000 | C28: =(1/(1+9%)^A28) -> 0.77218348 | D28: =(B28*C28) -> 108105.69 | E28: =(1/(1+8%))^A28 -> 0.79383224 | F28: =(B28*E28) -> 111136.51
A29: 4 | B29: =B13 -> 140000 | C29: =(1/(1+9%)^A29) -> 0.70842521 | D29: =(B29*C29) -> 99179.53 | E29: =(1/(1+8%))^A29 -> 0.73502985 | F29: =(B29*E29) -> 102904.18
A30: 5 | B30: =B14 -> 40000 | C30: =(1/(1+9%)^A30) -> 0.64993139 | D30: =(B30*C30) -> 25997.255 | E30: =(1/(1+8%))^A30 -> 0.6805832 | F30: =(B30*E30) -> 27223.328
A31: Total Nilai Sekarang NVP | D31: =SUM(D26:D30) -> 398504.25 | F31: =SUM(F26:F30) -> 408959.49
A32: Total Nilai Investasi Awal (Io) | D32: =ABS($B$25) -> 400000 | F32: =ABS($B$25) -> 400000
A33: Nilai Sekarang Bersih | D33: =D31-D32 -> -1495.7451 | F33: =F31-F32 -> 8959.4943
A35: Selisih Pv | B35: =ABS(D31-F31) -> 10455.239
A36: Nilai IRR 8% | B36: =8%+(F33/B35)*1% -> 0.088569382
A37: Nilai IRR 9% | B37: =9%+(D33/B35)*1% -> 0.088569382

Sheet Kasus 18.1
A25: Tahun | B25: Arus Kas | C25: Tingkat Bunga | D25: Nilai Sekarang (PV)
B26: -150000 | C26: 0.1
A27: {=_xlfn.SEQUENCE(ROWS(B27:B31))} -> 1 | B27: {=_xlfn.SEQUENCE(4,,40000,10000)} -> 40000 | C27: =(1/(1+10%)^A27) -> 0.90909091 | D27: =(B27*C27) -> 36363.636
A28: 2 | B28: 50000 | C28: =(1/(1+10%)^A28) -> 0.82644628 | D28: =(B28*C28) -> 41322.314
A29: 3 | B29: 60000 | C29: =(1/(1+10%)^A29) -> 0.7513148 | D29: =(B29*C29) -> 45078.888
A30: 4 | B30: 70000 | C30: =(1/(1+10%)^A30) -> 0.68301346 | D30: =(B30*C30) -> 47810.942
A31: 5 | C31: =(1/(1+10%)^A31) -> 0.62092132 | D31: =(B31*C31) -> 0
A32: Total Nilai Sekarang NVP | D32: =SUM(D27:D31) -> 170575.78
A33: Total Nilai Investasi Awal (Io) | D33: =ABS(B26) -> 150000
A34: Nilai Sekarang Bersih | D34: =D32-D33 -> 20575.78

Sheet Kasus 19.2
A23: Tahun | B23: Ars Kas | C23: Tingkat Bunga | D23: Nilai Sekarang | E23: Tingkat Bunga | F23: Nilai Sekarang (PV)
B24: -150000 | C24: 0.16 | E24: 0.15
A25: {=_xlfn.SEQUENCE(ROWS(B25:B29))} -> 1 | B25: 40000 | C25: =(1/(1+$C$24)^A25) -> 0.86206897 | D25: =(B25*C25) -> 34482.759 | E25: =(1/(1+$E$24))^A25 -> 0.86956522 | F25: =(B25*E25) -> 34782.609
A26: 2 | B26: 50000 | C26: =(1/(1+$C$24)^A26) -> 0.7431629 | D26: =(B26*C26) -> 37158.145 | E26: =(1/(1+$E$24))^A26 -> 0.75614367 | F26: =(B26*E26) -> 37807.183
A27: 3 | B27: 60000 | C27: =(1/(1+$C$24)^A27) -> 0.64065767 | D27: =(B27*C27) -> 38439.46 | E27: =(1/(1+$E$24))^A27 -> 0.65751623 | F27: =(B27*E27) -> 39450.974
A28: 4 | B28: 70000 | C28: =(1/(1+$C$24)^A28) -> 0.5522911 | D28: =(B28*C28) -> 38660.377 | E28: =(1/(1+$E$24))^A28 -> 0.57175325 | F28: =(B28*E28) -> 40022.727
A29: 5
A30: Total Nilai Sekarang NVP | D30: =SUM(D25:D29) -> 148740.74 | F30: =SUM(F25:F29) -> 152063.49
A31: Total Nilai Investasi Awal (Io) | D31: =ABS($B$24) -> 150000 | F31: =ABS($B$24) -> 150000
A32: Nilai Sekarang Bersih | D32: =D30-D31 -> -1259.259 | F32: =F30-F31 -> 2063.4932
A34: Selisih Pv | B34: =ABS(D30-F30) -> 3322.7522
A35: ="Nilai IRR "&E24*100&"%" -> Nilai IRR 15% | B35: =(15%+(F32/B34)*1%) -> 0.15621019
A36: ="Nilai IRR "&C24*100&"%" -> Nilai IRR 16% | B36: =(16%+(D32/B34)*1%) -> 0.15621019

Sheet Kasus 19.3
B16: =-'Kasus 18.1'!B26 -> 150000 | C16: =-B16 -> -150000
A17: Tahun 1 | B17: ='Kasus 18.1'!B27 -> 40000 | C17: =C16+B17 -> -110000
A18: Tahun 2 | B18: ='Kasus 18.1'!B28 -> 50000 | C18: =C17+B18 -> -60000
A19: Tahun 3 | B19: ='Kasus 18.1'!B29 -> 60000 | C19: =C18+B19 -> 0
A20: Tahun 4 | B20: ='Kasus 18.1'!B30 -> 70000 | C20: =C19+B20 -> 70000

Sheet Kasus 20
A24: Dreamy Lnas
A25: Anggaran Penjualan
A26: Untuk periode yang berakhir pada 31 Desember 2023
B27: Triwulan | F27: Tahunan
B28: 1 | C28: 2 | D28: 3 | E28: 4
A29: Unit | B29: 5000 | C29: 7000 | D29: 6500 | E29: 8000 | F29: =SUM(B29:E29) -> 26500
A30: Harga Jual/Unit ($) | B30: 20 | C30: 20 | D30: 20 | E30: 20 | F30: 20
A31: Anggaran Penjualan ($) | B31: =B29*B30 -> 100000 | C31: =C29*C30 -> 140000 | D31: =D29*D30 -> 130000 | E31: =E29*E30 -> 160000 | F31: =F29*F30 -> 530000
A39: Dreamy Land
A40: Anggaran Produksi
A41: Untuk periode yang berakhir pada 31 Desember 2023
B42: Triwulan | F42: Tahunan
B43: 1 | C43: 2 | D43: 3 | E43: 4 | F43: Tahunan
A44: Penjualan | B44: 5000 | C44: 7000 | D44: 6500 | E44: 8000 | F44: 26500
A45: Persediaan Akhir yang diinginkan | B45: =C44*20% -> 1400 | C45: =D44*20% -> 1300 | D45: =E44*20% -> 1600 | E45: 1000 | F45: =SUM(B45:E45) -> 5300
A46: Total Kebutuhan | B46: 6400 | C46: 8300 | D46: 8100 | E46: 9000 | F46: =F44+F45 -> 31800
A47: Dikurangi : Persediaan Awal | B47: =E45 -> 1000 | C47: =B45 -> 1400 | D47: =C45 -> 1300 | E47: =D45 -> 1600 | F47: =SUM(B47:E47) -> 5300
A48: Unit yang harus diproduksi | B48: 5400 | C48: 6900 | D48: 6800 | E48: 7400 | F48: =F46-F47 -> 26500
A61: Dreamy Land
A62: Anggaran Pembelian Bahan Baku (Bahan Kima) untuk periode yang berakhir pada 31 Desember 2023
A63: Sabun Mandi | B63: Triwulan | F63: Tahunan
B64: 1 | C64: 2 | D64: 3 | E64: 4
A65: Unit yang harus diproduksi (Tabel 2) | B65: =B48 -> 5400 | C65: =C48 -> 6900 | D65: =D48 -> 6800 | E65: =E48 -> 7400 | F65: =SUM(B65:E65) -> 26500
A66: Bahan Baku Langsung per Unit | B66: 120 | C66: 120 | D66: 120 | E66: 120 | F66: 120
A67: Kebutuhan Produksi | B67: =B65*B66 -> 648000 | C67: =C65*C66 -> 828000 | D67: =D65*D66 -> 816000 | E67: =E65*E66 -> 888000 | F67: =F65*F66 -> 3180000 | G67: =SUM(B67:E67)-F67 -> 0
A68: Persedian Akhir yang diinginkan | B68: =(C65*C66)*10% -> 82800 | C68: =D65*D66*10% -> 81600 | D68: =E65*E66*10% -> 88800 | E68: =$B$65*125*10% -> 67500 | F68: =E68 -> 67500
A69: Total Kebutuhan | B69: =B67+B68 -> 730800 | C69: =C67+C68 -> 909600 | D69: =D67+D68 -> 904800 | E69: =E67+E68 -> 955500 | F69: =F67+F68 -> 3247500
A70: Dikurangi : Persediaan Awal | B70: 100000 | C70: =B68 -> 82800 | D70: =C68 -> 81600 | E70: =D68 -> 88800 | F70: =B70 -> 100000
A71: Bahan Baku Langsung yang harus dibeli | B71: =B69-B70 -> 630800 | C71: =C69-C70 -> 826800 | D71: =D69-D70 -> 823200 | E71: =E69-E70 -> 866700 | F71: =F69-F70 -> 3147500 | G71: =SUM(B71:E71)-F71 -> 0
A72: Biaya per Sabun Mandi ($) | B72: 5 | C72: 5 | D72: 5 | E72: 5 | F72: 5
A73: Total Biaya Pembelian Sabun Mandi | B73: =(B71/B66)*B72 -> 26283.333 | C73: =(C71/C66)*C72 -> 34450 | D73: =(D71/D66)*D72 -> 34300 | E73: =(E71/E66)*E72 -> 36112.5 | F73: =SUM(B73:E73) -> 131145.83 | G73: =SUM(B73:E73)-F73 -> 0
A75: Dreamy Land
A76: Anggaran Pembelian Bahan Baku (Botol) untuk periode yang berakhir pada 31 Desember 2023
A77: Sabun Mandi | B77: Triwulan | F77: Tahunan
B78: 1 | C78: 2 | D78: 3 | E78: 4
A79: Unit yang harus diproduksi (Tabel 2) | B79: =B65 -> 5400 | C79: =C65 -> 6900 | D79: =D65 -> 6800 | E79: =E65 -> 7400 | F79: =SUM(B79:E79) -> 26500
A80: Bahan Baku Langsung per Unit | B80: 1 | C80: 1 | D80: 1 | E80: 1 | F80: 1
A81: Kebutuhan Produksi | B81: =B79*B80 -> 5400 | C81: =C79*C80 -> 6900 | D81: =D79*D80 -> 6800 | E81: =E79*E80 -> 7400 | F81: =SUM(B81:E81) -> 26500 | G81: =SUM(B81:E81)-F81 -> 0
