Workbook

Sheet Day 1.1 Informasi
A1: Informasi Umum :
A2: Bapak Andika mendirikan perusahaan penyedia layanan internet dengan nama “Juara Net” pada awal tahun 2023. Berikut adalah transaksi Juara Net pada tanggal 1 Januari - 31 Januari 2023. | E2: Kode Akun :
A4: Tanggal | C4: Keterangan | E4: Kode Akun | F4: Nama Akun
A5: Jan | B5: 1 | C5: Bapak Andika menyetorkan uang tunai sebesar Rp 25.000.000 sebagai modal usaha Juara Net | E5: 101 | F5: Kas
B6: 1 | C6: Juara Net membayar sewa gedung untuk operasional kantor selama 1 tahun ( Jan - Des) sebesar Rp 12.000.000 secara tunai | E6: 102 | F6: Piutang Usaha
B7: 3 | C7: Juara Net membeli peralatan jaringan sebesar Rp 7.000.000 secara kredit, nomor faktur F01/23 | E7: 103 | F7: Perlengkapan
B8: 5 | C8: Juara Net membeli perlengkapan kantor seharga Rp 1.000.000 secara tunai | E8: 104 | F8: Sewa Dibayar Dimuka
B9: 8 | C9: Juara Net menerima uang tunai dari PT Makmur Jaya atas jasa layanan internet yang telah selesai diberikan sebesar Rp 7.500.000 | E9: 121 | F9: Peralatan Jaringan
B10: 10 | C10: Bapak Andika mengambil Rp 2.000.000 sebagai penarikan pribadi | E10: 201 | F10: Utang Usaha
B11: 14 | C11: Juara Net telah menyelesaikan jasa layanan internet kepada CV Barokah sebesar Rp 5.000.000 tetapi belum diterima uangnya | E11: 301 | F11: Modal Usaha
B12: 17 | C12: Mengangsur hutang atas pembelian peralatan jaringan yang dibeli pada tanggal 3 Januari dengan nomor faktur F01/23 sebesar Rp 3.000.000 | E12: 302 | F12: Prive Bapak Andika
B13: 25 | C13: Membayar gaji kepada karyawan sebesar Rp 4.500.000 secara tunai | E13: 401 | F13: Pendapatan Usaha
B14: 27 | C14: Menerima pelunasan dari CV Barokah atas layanan internet yang sudah diberikan pada tanggal 14 Januari sebesar Rp 5.000.000 | E14: 501 | F14: Beban Gaji
E15: 502 | F15: Beban Sewa

Sheet Day 1.2 Jurnal Umum
A2: JUARA NET
A3: JURNAL UMUM
A4: JANUARI 2023
A6: Tanggal | B6: Keterangan | C6: Ref | D6: Debit | E6: Kredit
A7: =DATE(2023,1,1) -> 44927 | B7: Kas | C7: 101 | D7: 25000000
B8: Modal Awal | C8: 301 | E8: 25000000
B9: Sewa Gedung Dibayar Dimuka | C9: 104 | D9: 12000000
B10: Kas | C10: 101 | E10: 12000000
A12: =DATE(2023,1,3) -> 44929 | B12: Peralatan Jaringan | C12: 121 | D12: 7000000
B13: Utang Usaha | C13: 201 | E13: 7000000
A15: =DATE(2023,1,5) -> 44931 | B15: Perlengkapan Kantor | C15: 103 | D15: 1000000
B16: Kas | C16: 101 | E16: 1000000
A18: =DATE(2023,1,8) -> 44934 | B18: Kas | C18: 101 | D18: 7500000
B19: Pendapatan Usaha | C19: 401 | E19: 7500000
A21: =DATE(2023,1,10) -> 44936 | B21: Prive Bapak Andika | C21: 302 | D21: 2000000
B22: Kas | C22: 101 | E22: 2000000
A24: =DATE(2023,1,14) -> 44940 | B24: Piutang Usaha | C24: 102 | D24: 5000000
B25: Pendapatan Usaha | C25: 401 | E25: 5000000
A27: =DATE(2023,1,17) -> 44943 | B27: Utang Usaha | C27: 201 | D27: 3000000
B28: Kas | C28: 101 | E28: 3000000
A30: =DATE(2023,1,25) -> 44951 | B30: Beban Gaji | C30: 501 | D30: 4500000
B31: Kas | C31: 101 | E31: 4500000
A33: =DATE(2023,1,27) -> 44953 | B33: Kas | C33: 101 | D33: 5000000
B34: Piutang Usaha | C34: 102 | E34: 5000000
A37: TOTAL | D37: =SUM(D7:D36) -> 72000000 | E37: =SUM(E7:E36) -> 72000000

Sheet Day 1.3 Buku Besar
A2: BUKU BESAR
A4: Nama Akun : | B4: ='Day 1.1 Informasi'!F5 -> Kas | E4: Kode Akun : | F4: ='Day 1.1 Informasi'!E5 -> 101
A5: Tanggal | B5: Keterangan | C5: Ref | D5: Debit | E5: Kredit | F5: Saldo
F6: Debet | G6: Kredit
A7: =DATE(2023,1,1) -> 44927 | B7: Posting | C7: JU -1 | D7: {=_xlws.FILTER('Day 1.2 Jurnal Umum'!$D$7:$E$34,'Day 1.2 Jurnal Umum'!$B$7:$B$34="Kas")} -> #NAME? | F7: =D7-E7 -> #NAME?
C8: =$C$7 -> JU -1 | F8: =IF(AND(D8="",E8=""),"",(F7+D8)-E8)
A9: =DATE(2023,1,5) -> 44931 | C9: =$C$7 -> JU -1 | F9: =IF(AND(D9="",E9=""),"",(F8+D9)-E9)
A10: =DATE(2023,1,8) -> 44934 | C10: =$C$7 -> JU -1 | F10: =IF(AND(D10="",E10=""),"",(F9+D10)-E10)
A11: =DATE(2023,1,10) -> 44936 | C11: =$C$7 -> JU -1 | F11: =IF(AND(D11="",E11=""),"",(F10+D11)-E11)
A12: =DATE(2023,1,17) -> 44943 | C12: =$C$7 -> JU -1 | F12: =IF(AND(D12="",E12=""),"",(F11+D12)-E12)
A13: =DATE(2023,1,25) -> 44951 | C13: =$C$7 -> JU -1 | F13: =IF(AND(D13="",E13=""),"",(F12+D13)-E13)
A14: =DATE(2023,1,27) -> 44953 | C14: =$C$7 -> JU -1 | F14: =IF(AND(D14="",E14=""),"",(F13+D14)-E14)
F15: =IF(AND(D15="",E15=""),"",(F14+D15)-E15)
F16: =IF(AND(D16="",E16=""),"",(F15+D16)-E16)
F17: =IF(AND(D17="",E17=""),"",(F16+D17)-E17)
F18: =IF(AND(D18="",E18=""),"",(F17+D18)-E18)
A21: Nama Akun : | B21: ='Day 1.1 Informasi'!F6 -> Piutang Usaha | E21: Kode Akun : | F21: ='Day 1.1 Informasi'!E6 -> 102
A22: Tanggal | B22: Keterangan | C22: Ref | D22: Debit | E22: Kredit | F22: Saldo
F23: Debet | G23: Kredit
A24: =DATE(2023,1,14) -> 44940 | B24: Postinng | C24: =$C$7 -> JU -1 | D24: {=_xlws.FILTER('Day 1.2 Jurnal Umum'!$D$7:$E$34,'Day 1.2 Jurnal Umum'!$B$7:$B$34="Piutang Usaha")} -> #NAME? | F24: =D24-E24 -> #NAME?
A25: =DATE(2023,1,27) -> 44953 | C25: =$C$7 -> JU -1 | F25: =IF(AND(D25="",E25=""),"",(F24+D25)-E25)
F26: =IF(AND(D26="",E26=""),"",(F25+D26)-E26)
F27: =IF(AND(D27="",E27=""),"",(F26+D27)-E27)
F28: =IF(AND(D28="",E28=""),"",(F27+D28)-E28)
A32: Nama Akun : | B32: ='Day 1.1 Informasi'!F7 -> Perlengkapan | E32: Kode Akun : | F32: ='Day 1.1 Informasi'!E7 -> 103
A33: Tanggal | B33: Keterangan | C33: Ref | D33: Debit | E33: Kredit | F33: Saldo
F34: Debet | G34: Kredit
A35: =DATE(2023,1,5) -> 44931 | B35: =B24 -> Postinng | C35: =$C$7 -> JU -1 | D35: ='Day 1.2 Jurnal Umum'!D15 -> 1000000 | F35: =D35-E35 -> 1000000
F36: =IF(AND(D36="",E36=""),"",(F35+D36)-E36)
F37: =IF(AND(D37="",E37=""),"",(F36+D37)-E37)
F38: =IF(AND(D38="",E38=""),"",(F37+D38)-E38)
F39: =IF(AND(D39="",E39=""),"",(F38+D39)-E39)
A43: Nama Akun : | B43: ='Day 1.1 Informasi'!F8 -> Sewa Dibayar Dimuka | E43: Kode Akun : | F43: ='Day 1.1 Informasi'!E8 -> 104
A44: Tanggal | B44: Keterangan | C44: Ref | D44: Debit | E44: Kredit | F44: Saldo
F45: Debet | G45: Kredit
A46: =DATE(2023,1,1) -> 44927 | B46: =B35 -> Postinng | C46: =C35 -> JU -1 | D46: ='Day 1.2 Jurnal Umum'!D9 -> 12000000 | F46: =D46-E46 -> 12000000
F47: =IF(AND(D47="",E47=""),"",(F46+D47)-E47)
F48: =IF(AND(D48="",E48=""),"",(F47+D48)-E48)
F49: =IF(AND(D49="",E49=""),"",(F48+D49)-E49)
F50: =IF(AND(D50="",E50=""),"",(F49+D50)-E50)
...

Sheet Day 2.1 Informasi
A1: Berikut adalah Neraca Saldo Sebelum Penyesuaian milik UD Sanjaya per 31 Desember 2023 : | G1: Data Jurnal Penyesuaian Desember 2023 :
A3: Kode Akun | B3: Nama Akun | C3: Debit | D3: Kredit | G3: Tanggal | I3: Keterangan
A4: 101 | B4: Kas | C4: 290000 | G4: Des | H4: 31 | I4: Penyusutan peralatan pada bulan Desember 2023 sebesar Rp 5.000
A5: 102 | B5: Piutang Dagang | C5: 126000 | H5: 31 | I5: Terdapat gaji yang belum dibayarkan pada bulan Desember 2023 sebesar Rp 25.000. Gaji akan dibayarkan pada tanggal 05 Januari 2024
A6: 103 | B6: Persediaan | C6: 200000 | H6: 31 | I6: Perlengkapan yang tersisa berdasarkan perhitungan fisik senilai Rp 2.000
A7: 104 | B7: Iklan Dibayar Dimuka | C7: 24000 | H7: 31 | I7: Pada tanggal 15 November 2023, UD Sanjaya membayar iklan kepada Digital Advertising untuk 4 kali penayangan iklan dengan harga per penayangan iklan sebesar Rp 6.000. Pada tanggal 31 Desember, Digital Advertising sudah menayangkan seluruh iklan milik UD Sanjaya.
A8: 105 | B8: Perlengkapan | C8: 11000
A9: 106 | B9: Peralatan | C9: 180000
A10: 107 | B10: Akumulasi Penyusutan Peralatan | D10: 10000
A11: 201 | B11: Hutang Dagang | D11: 90000
A12: 202 | B12: Hutang Gaji | D12: 20000
A13: 301 | B13: Modal UD Sanjaya | D13: 560000
A14: 302 | B14: Laba Ditahan | D14: 40000
A15: 401 | B15: Penjualan | D15: 200000
A16: 501 | B16: Beban Pokok Penjualan | C16: 70000
A17: 601 | B17: Beban Gaji | C17: 15000
A18: 602 | B18: Beban Iklan | C18: 4000
A19: TOTAL | C19: =SUM(C4:C18) -> 920000 | D19: =SUM(D4:D18) -> 920000

Sheet Day 2.2 Jurnal Penyesuian
A2: UD SANJAYA
A3: JURNAL PENYESUIAN
A6: Tanggal | B6: Keterangan | C6: Ref | D6: Debit | E6: Kredit
A7: 45291 | B7: Beban penyusutan peralatan | C7: 604 | D7: 5000
B8: Akumulasi peyusutan peralatan | C8: 106 | E8: 5000
A9: =A7 -> 45291 | B9: Beban gaji | C9: 601 | D9: 25000
B10: Hutang gaji | C10: 202 | E10: 25000
A11: =A9 -> 45291 | B11: Beban perlengkapan | C11: ='Day 2.3 Neraca Lajur'!A21 -> 603 | D11: 9000
B12: Perlengkapan | C12: ='Day 2.3 Neraca Lajur'!A11 -> 105 | E12: 9000
A13: =A11 -> 45291 | B13: Beban Iklan | C13: ='Day 2.3 Neraca Lajur'!A20 -> 602 | D13: 24000
B14: Iklan dibayar muka | C14: ='Day 2.3 Neraca Lajur'!A9 -> 104 | E14: 24000
A16: TOTAL | D16: =SUM(D7:D15) -> 63000 | E16: =SUM(E7:E15) -> 63000

Sheet Day 2.3 Neraca Lajur
A1: UD SANJAYA
A2: NERACA LAJUR
A4: Kode Akun | B4: Nama Akun | D4: Sebelum Penyesuaian | F4: Penyesuaian | H4: Setelah Penyesuaian | J4: Laba Rugi | L4: Neraca
D5: Debit | E5: Kredit | F5: Debit | G5: Kredit | H5: Debit | I5: Kredit | J5: Debit | K5: Kredit | L5: Debit | M5: Kredit
A6: 101 | B6: Kas | C6: D | D6: ='Day 2.1 Informasi'!C4 -> 290000 | H6: =IF(C6="D",D6+F6-G6,0) -> 290000 | I6: =IF(C6="K",E6-F6+G6,0) -> 0 | L6: =IF(C6="D",H6,0) -> 290000 | M6: =IF(C6="K",I6,0) -> 0
A7: 102 | B7: Piutang Dagang | C7: D | D7: ='Day 2.1 Informasi'!C5 -> 126000 | H7: =IF(C7="D",D7+F7-G7,0) -> 126000 | I7: =IF(C7="K",E7-F7+G7,0) -> 0 | L7: =IF(C7="D",H7,0) -> 126000 | M7: =IF(C7="K",I7,0) -> 0
A8: 103 | B8: Persediaan | C8: D | D8: ='Day 2.1 Informasi'!C6 -> 200000 | H8: =IF(C8="D",D8+F8-G8,0) -> 200000 | I8: =IF(C8="K",E8-F8+G8,0) -> 0 | L8: =IF(C8="D",H8,0) -> 200000 | M8: =IF(C8="K",I8,0) -> 0
A9: 104 | B9: Iklan Dibayar Dimuka | C9: D | D9: ='Day 2.1 Informasi'!C7 -> 24000 | G9: ='Day 2.2 Jurnal Penyesuian'!E14 -> 24000 | H9: =IF(C9="D",D9+F9-G9,0) -> 0 | I9: =IF(C9="K",E9-F9+G9,0) -> 0 | L9: =IF(C9="D",H9,0) -> 0 | M9: =IF(C9="K",I9,0) -> 0
A10: 105 | B10: Perlengkapan | C10: D | D10: ='Day 2.1 Informasi'!C8 -> 11000 | G10: ='Day 2.2 Jurnal Penyesuian'!E12 -> 9000 | H10: =IF(C10="D",D10+F10-G10,0) -> 2000 | I10: =IF(C10="K",E10-F10+G10,0) -> 0 | L10: =IF(C10="D",H10,0) -> 2000 | M10: =IF(C10="K",I10,0) -> 0
A11: 105 | B11: Peralatan | C11: D | D11: ='Day 2.1 Informasi'!C9 -> 180000 | H11: =IF(C11="D",D11+F11-G11,0) -> 180000 | I11: =IF(C11="K",E11-F11+G11,0) -> 0 | L11: =IF(C11="D",H11,0) -> 180000 | M11: =IF(C11="K",I11,0) -> 0
A12: 106 | B12: Akumulasi Penyusutan Peralatan | C12: K | E12: ='Day 2.1 Informasi'!D10 -> 10000 | G12: ='Day 2.2 Jurnal Penyesuian'!E8 -> 5000 | H12: =IF(C12="D",D12+F12-G12,0) -> 0 | I12: =IF(C12="K",E12-F12+G12,0) -> 15000 | L12: =IF(C12="D",H12,0) -> 0 | M12: =IF(C12="K",I12,0) -> 15000
A13: 201 | B13: Hutang Dagang | C13: K | E13: ='Day 2.1 Informasi'!D11 -> 90000 | H13: =IF(C13="D",D13+F13-G13,0) -> 0 | I13: =IF(C13="K",E13-F13+G13,0) -> 90000 | L13: =IF(C13="D",H13,0) -> 0 | M13: =IF(C13="K",I13,0) -> 90000
A14: 202 | B14: Hutang Gaji | C14: K | E14: ='Day 2.1 Informasi'!D12 -> 20000 | G14: ='Day 2.2 Jurnal Penyesuian'!E10 -> 25000 | H14: =IF(C14="D",D14+F14-G14,0) -> 0 | I14: =IF(C14="K",E14-F14+G14,0) -> 45000 | L14: =IF(C14="D",H14,0) -> 0 | M14: =IF(C14="K",I14,0) -> 45000
A15: 301 | B15: Modal UD Sanjaya | C15: K | E15: ='Day 2.1 Informasi'!D13 -> 560000 | H15: =IF(C15="D",D15+F15-G15,0) -> 0 | I15: =IF(C15="K",E15-F15+G15,0) -> 560000 | L15: =IF(C15="D",H15,0) -> 0 | M15: =IF(C15="K",I15,0) -> 560000
A16: 302 | B16: Laba Ditahan | C16: K | E16: ='Day 2.1 Informasi'!D14 -> 40000 | H16: =IF(C16="D",D16+F16-G16,0) -> 0 | I16: =IF(C16="K",E16-F16+G16,0) -> 40000 | L16: =IF(C16="D",H16,0) -> 0 | M16: =IF(C16="K",I16,0) -> 40000
A17: 401 | B17: Penjualan | C17: K | E17: ='Day 2.1 Informasi'!D15 -> 200000 | H17: =IF(C17="D",D17+F17-G17,0) -> 0 | I17: =IF(C17="K",E17-F17+G17,0) -> 200000 | J17: =IF(C17="D",H17,0) -> 0 | K17: =IF(C17="K",I17,0) -> 200000
A18: 501 | B18: Beban Pokok Penjualan | C18: D | D18: ='Day 2.1 Informasi'!C16 -> 70000 | H18: =IF(C18="D",D18+F18-G18,0) -> 70000 | I18: =IF(C18="K",E18-F18+G18,0) -> 0 | J18: =IF(C18="D",H18,0) -> 70000 | K18: =IF(C18="K",I18,0) -> 0
A19: 601 | B19: Beban Gaji | C19: D | D19: ='Day 2.1 Informasi'!C17 -> 15000 | F19: ='Day 2.2 Jurnal Penyesuian'!D9 -> 25000 | H19: =IF(C19="D",D19+F19-G19,0) -> 40000 | I19: =IF(C19="K",E19-F19+G19,0) -> 0 | J19: =IF(C19="D",H19,0) -> 40000 | K19: =IF(C19="K",I19,0) -> 0
A20: 602 | B20: Beban Iklan | C20: D | D20: ='Day 2.1 Informasi'!C18 -> 4000 | F20: ='Day 2.2 Jurnal Penyesuian'!D13 -> 24000 | H20: =IF(C20="D",D20+F20-G20,0) -> 28000 | I20: =IF(C20="K",E20-F20+G20,0) -> 0 | J20: =IF(C20="D",H20,0) -> 28000 | K20: =IF(C20="K",I20,0) -> 0
A21: 603 | B21: Beban Perlengkapan | C21: D | F21: ='Day 2.2 Jurnal Penyesuian'!D11 -> 9000 | H21: =IF(C21="D",D21+F21-G21,0) -> 9000 | I21: =IF(C21="K",E21-F21+G21,0) -> 0 | J21: =IF(C21="D",H21,0) -> 9000 | K21: =IF(C21="K",I21,0) -> 0
A22: 604 | B22: Beban Penyusutan Peralatan | C22: D | F22: ='Day 2.2 Jurnal Penyesuian'!D7 -> 5000 | H22: =IF(C22="D",D22+F22-G22,0) -> 5000 | I22: =IF(C22="K",E22-F22+G22,0) -> 0 | J22: =IF(C22="D",H22,0) -> 5000 | K22: =IF(C22="K",I22,0) -> 0
A23: TOTAL | D23: =SUM(D6:D22) -> 920000 | E23: =SUM(E6:E22) -> 920000 | F23: =SUM(F6:F22) -> 63000 | G23: =SUM(G6:G22) -> 63000 | H23: =SUM(H6:H22) -> 950000 | I23: =SUM(I6:I22) -> 950000 | J23: =SUM(J6:J22) -> 152000 | K23: =SUM(K6:K22) -> 200000 | ... M23: =SUM(M6:M22) -> 750000
A24: LABA BERSIH | J24: =K23-J23 -> 48000 | M24: =L23-M23 -> 48000
A25: TOTAL AKHIR | D25: =D23+D24 -> 920000 | E25: =E23+E24 -> 920000 | F25: =F23+F24 -> 63000 | G25: =G23+G24 -> 63000 | H25: =H23+H24 -> 950000 | I25: =I23+I24 -> 950000 | J25: =J23+J24 -> 200000 | K25: =K23+K24 -> 200000 | ... M25: =M23+M24 -> 798000

Sheet Day 2.4 Laporan
E1: VERSI 1
A2: LAPORAN LABA RUGI UD SANJAYA Untuk Periode yang Berakhir pada 31 Desember 2023 | E2: LAPORAN PERUBAHAN EKUITAS UD SANJAYA Untuk Periode yang Berakhir pada 31 Desember 2023
A3: Penjualan | C3: ='Day 2.3 Neraca Lajur'!K17 -> 200000 | E3: Modal Awal UD Sanjaya, 1 Des 2023 | G3: ='Day 2.3 Neraca Lajur'!M15 -> 560000
A4: Beban Pokok Penjualan | C4: ='Day 2.3 Neraca Lajur'!J18 -> 70000 | E4: Penambahan/Pengurangan Modal :
A5: Laba Kotor | C5: =C3-C4 -> 130000 | E5: Setoran Modal
E6: Laba Ditahan | F6: ='Day 2.3 Neraca Lajur'!M16 -> 40000
E7: Laba Tahun Berjalan | F7: =C15 -> 48000
A8: Beban : | E8: Prive
A9: ='Day 2.3 Neraca Lajur'!B19 -> Beban Gaji | B9: ='Day 2.3 Neraca Lajur'!J19 -> 40000 | E9: Total Penambahan/Pengurangan | G9: =F5+F6+F7-F8 -> 88000
A10: ='Day 2.3 Neraca Lajur'!B20 -> Beban Iklan | B10: ='Day 2.3 Neraca Lajur'!J20 -> 28000 | E10: Modal UD Sanjaya, 31 Des 2023 | G10: =G3+G9 -> 648000
A11: ='Day 2.3 Neraca Lajur'!B21 -> Beban Perlengkapan | B11: ='Day 2.3 Neraca Lajur'!J21 -> 9000
A12: ='Day 2.3 Neraca Lajur'!B22 -> Beban Penyusutan Peralatan | B12: ='Day 2.3 Neraca Lajur'!J22 -> 5000
A13: Total Beban | C13: =SUM(B9:B12) -> 82000
A15: Laba Bersih | C15: =C5-C13 -> 48000 | E15: VERSI 1
E16: LAPORAN POSISI KEUANGAN UD SANJAYA Per 31 Desember 2023
E17: ASET | G17: LIABILITAS
E18: ='Day 2.3 Neraca Lajur'!B6 -> Kas | F18: ='Day 2.3 Neraca Lajur'!L6 -> 290000 | G18: ='Day 2.3 Neraca Lajur'!B13 -> Hutang Dagang | H18: ='Day 2.3 Neraca Lajur'!M13 -> 90000
E19: ='Day 2.3 Neraca Lajur'!B7 -> Piutang Dagang | F19: ='Day 2.3 Neraca Lajur'!L7 -> 126000 | G19: ='Day 2.3 Neraca Lajur'!B14 -> Hutang Gaji | H19: ='Day 2.3 Neraca Lajur'!M14 -> 45000
E20: ='Day 2.3 Neraca Lajur'!B8 -> Persediaan | F20: ='Day 2.3 Neraca Lajur'!L8 -> 200000
E21: ='Day 2.3 Neraca Lajur'!B9 -> Iklan Dibayar Dimuka | F21: 0 | G21: TOTAL LIABILITAS | H21: =SUM(H18:H19) -> 135000
E22: ='Day 2.3 Neraca Lajur'!B10 -> Perlengkapan | F22: ='Day 2.3 Neraca Lajur'!L10 -> 2000
E23: ='Day 2.3 Neraca Lajur'!B11 -> Peralatan | F23: ='Day 2.3 Neraca Lajur'!L11 -> 180000 | G23: EKUITAS
E24: ='Day 2.3 Neraca Lajur'!B12 -> Akumulasi Penyusutan Peralatan | F24: =-'Day 2.3 Neraca Lajur'!M12 -> -15000 | G24: ='Day 2.3 Neraca Lajur'!B15 -> Modal UD Sanjaya | H24: ='Day 2.3 Neraca Lajur'!M15+F7+F6 -> 648000
G27: TOTAL EKUITAS | H27: =H24+H25 -> 648000
E28: TOTAL ASET | F28: =SUM(F18:F24) -> 783000 | G28: TOTAL LIABILITAS DAN EKUITAS | H28: =H21+H27 -> 783000

Sheet Day 3.1 Analis Laporan Keuangan
A1: Studi Kasus : Analisis Laporan Keuangan
A3: Studi Kasus: PT IKN
A4: PT IKN adalah sebuah perusahaan manufaktur yang beroperasi di sektor otomotif. Berikut adalah ringkasan laporan keuangan PT IKN untuk periode 2021 - 2023 :
A6: Keterangan | B6: 2023 | C6: 2022 | D6: 2021
A7: Laba Bersih | B7: 5000000000 | C7: 4800000000 | D7: 4200000000
A8: Total Beban Operasional | B8: 25000000000 | C8: 27200000000 | D8: 23800000000
A9: Total Pendapatan | B9: 30000000000 | C9: 32000000000 | D9: 28000000000
A10: Total Aset (Lancar) | B10: 50000000000 | C10: 48000000000 | D10: 45000000000
A11: Ekuitas Pemegang Saham | B11: 20000000000 | C11: 19000000000 | D11: 18000000000
A12: Total Utang (Lancar) | B12: 30000000000 | C12: 29000000000 | D12: 27000000000
A13: Arus Kas Bersih dari Aktivitas Operasi | B13: 8000000000 | C13: 7500000000 | D13: 7000000000
A14: Arus Kas Bersih dari Aktivitas Investasi | B14: -3000000000 | C14: -2800000000 | D14: -2500000000
A15: Arus Kas Bersih dari Aktivitas Pendanaan | B15: -4000000000 | C15: -3700000000 | D15: -3500000000
A18: Instruksi :
A19: Ilustrasikan bahwa Anda merupakan akuntan di PT IKN. Anda diminta oleh manajer untuk menyajikan data analisis keuangan PT IKN selama 3 tahun terakhir (2021 - 2023). Adapun kebutuhan data tersebut diantaranya adalah sebagai berikut :
A20: 1.Rasio Keuangan:
A21: a. Rasio Lancar (Current Ratio) Tahun 2021 - 2023
A22: b. Rasio Utang Terhadap Aset (Debt to Asset Ratio) Tahun 2021 - 2023
A23: c. Rasio Profitabilitas Tahun 2021 - 2023
A24: 2. Analisis Horizontal (Komparatif) :
A25: Analisis Laporan Laba Rugi : Tren tahunan laporan laba rugi PT IKN dalam dua tahun terakhir.

Sheet Day 3.2 Analis Laporan Keuangan
A1: Hasil Analisa Laporan Keuangan bisa disajikan dalam tabel berikut :
A4: Rasio | B4: 2023 | C4: 2022 | D4: 2021 | E4: Analisis
A5: Rasio Lancar (Current Ratio) | B5: ='Day 3.1 Analis Laporan Keuangan'!B10/'Day 3.1 Analis Laporan Keuangan'!B12 -> 1.6666667 | C5: ='Day 3.1 Analis Laporan Keuangan'!C10/'Day 3.1 Analis Laporan Keuangan'!C12 -> 1.6551724 | D5: ='Day 3.1 Analis Laporan Keuangan'!D10/'Day 3.1 Analis Laporan Keuangan'!D12 -> 1.6666667 | E5: =IF(B5>=C5,"Naik",IF(B5=C5,"Tidak Ada Kenaikan","Turun")) -> Naik
A6: Rasio Total Hutang terhadap Aset (Debt to Asset Ratio) | B6: ='Day 3.1 Analis Laporan Keuangan'!B12/'Day 3.1 Analis Laporan Keuangan'!B10 -> 0.6 | C6: ='Day 3.1 Analis Laporan Keuangan'!C12/'Day 3.1 Analis Laporan Keuangan'!C10 -> 0.60416667 | D6: ='Day 3.1 Analis Laporan Keuangan'!D12/'Day 3.1 Analis Laporan Keuangan'!D10 -> 0.6 | E6: =IF(B6>=C6,"Naik",IF(B6=C6,"Tidak Ada Kenaikan","Turun")) -> Turun
A7: Rasio Profitabilitas (profit margin) | B7: ='Day 3.1 Analis Laporan Keuangan'!B7/'Day 3.1 Analis Laporan Keuangan'!B9 -> 0.16666667 | C7: ='Day 3.1 Analis Laporan Keuangan'!C7/'Day 3.1 Analis Laporan Keuangan'!C9 -> 0.15 | D7: ='Day 3.1 Analis Laporan Keuangan'!D7/'Day 3.1 Analis Laporan Keuangan'!D9 -> 0.15 | E7: =IF(B7>=C7,"Naik",IF(B7=C7,"Tidak Ada Kenaikan","Turun")) -> Naik
A10: 1. Analisa Ratio Keuangan
A12: 1. Pada tahun 2023 Rasio lancar perusahaan sebesar1,67. Rasio ini naik dari tahun sebelumnya
A13: Hal ini meandakan kemampuan perusahaan dalam membayar hutang jangka pendeknya semakin meningkat. Rasio ini dapatdikatakan baik karena
A14: di atas standar industri
A16: 2. Pada tahun 2023 Debt To Asset Ratio 60,00%. Rasio ini turun dari tahun sebelumnya yang artinya ketergantungan hutang perusahaan semakin
A17: berkurang dalam membiayai asetnya sehingga resiko keuangan menurun. Rasio ini dapat dikatakan baik karena diatas standart industri
A19: 3. Pada tahun 2023 Profit Margin Ratio perusahaan PT IKN mengalami keenaikan. Ha ini menandakan bahwa kinerja perusahaan dalam
A20: memperoleh laba semakin baik dari tahun sebelumnya. Rasio ini dapat dikatakan baik karena berada diatas standar industri
A25: Laporan Laba Rugi | B25: 2023 | C25: 2022 | D25: Varaian (%) | E25: Kenaikan Penurunan
A27: Pendapatan | B27: ='Day 3.1 Analis Laporan Keuangan'!B9 -> 30000000000 | C27: ='Day 3.1 Analis Laporan Keuangan'!C9 -> 32000000000 | D27: =IF(OR((B27-C27)/C27>0,(B27-C27)/C27<0),(B27-C27)/C27,"Tidak ada varaian") -> -0.0625 | E27: =IF(B27>C27,"Naik",IF(B27<C27,"Turun","Tidak Ada Kenaikan")) -> Turun | H27: =(B27-C27)/C27 -> -0.0625
A28: Beban Operasional | B28: ='Day 3.1 Analis Laporan Keuangan'!B8 -> 25000000000 | C28: ='Day 3.1 Analis Laporan Keuangan'!C8 -> 27200000000 | D28: =IF(OR((B28-C28)/C28>0,(B28-C28)/C28<0),(B28-C28)/C28,"Tidak ada varaian") -> -0.080882353 | E28: =IF(B28>C28,"Naik",IF(B28<C28,"Turun","Tidak Ada Kenaikan")) -> Turun
A29: Laba Bersih | B29: ='Day 3.1 Analis Laporan Keuangan'!B7 -> 5000000000 | C29: ='Day 3.1 Analis Laporan Keuangan'!C7 -> 4800000000 | D29: =IF(OR((B29-C29)/C29>0,(B29-C29)/C29<0),(B29-C29)/C29,"Tidak ada varaian") -> 0.041666667 | E29: =IF(B29>C29,"Naik",IF(B29<C29,"Turun","Tidak Ada Kenaikan")) -> Naik
A32: 2. Analisa Rasio Horizontal

Sheet Day 4.1 Akuntansi Biaya
A1: Pada bulan Januari 2019 PT. Mitra (sebuah perusahaan percetakan) menerima pesanan 10.000 brosur dari Sumber Utama dengan harga Rp 3.000,- per brosur dan pesanan diberi nomor 01-0113, dimana pembayarannya akan dilakukan secara kredit.
A3: Untuk memproduksi pesanan tersebut perusahaan membeli bahan baku dan bahan penolong secara kredit 01 Januari 2019 sebagai berikut:
A5: Bahan Baku & Penolong | B5: Qty | C5: Harga Satuan | D5: Total
A6: Kertas jenis A | B6: 100 | C6: 35000 | D6: =B6*C6 -> 3500000
A7: Tinta jenis 1 | B7: 30 | C7: 150000 | D7: =B7*C7 -> 4500000
A8: Bahan penolong X | B8: 100 | C8: 10000 | D8: =B8*C8 -> 1000000
A9: Bahan penolong Y | B9: 100 | C9: 90000 | D9: =B9*C9 -> 9000000
A10: Jumlah Pembelian | D10: =SUM(D6:D9) -> 18000000
A12: Setelah pesanan selesai diproduksi didapat data sebagai berikut:
A14: Penggunaan Bahan Baku | B14: =B5 -> Qty | C14: =C5 -> Harga Satuan | D14: =D5 -> Total
A15: Kertas jenis A | B15: 80 | C15: 35000 | D15: =B15*C15 -> 2800000
A16: Tinta jenis 1 | B16: 26 | C16: 150000 | D16: =B16*C16 -> 3900000
A17: Jumlah Penggunaan Bahan Baku | D17: =SUM(D15:D16) -> 6700000
A19: Penggunaan Bahan Penolong: | B19: =B14 -> Qty | C19: =C14 -> Harga Satuan | D19: =D14 -> Total
A20: Bahan penolong X | B20: 80 | C20: 10000 | D20: =B20*C20 -> 800000
A21: Bahan penolong Y | B21: 80 | C21: 90000 | D21: =B21*C21 -> 7200000
A22: Jumlah Penggunaan Bahan Penolong | D22: =SUM(D20:D21) -> 8000000
A24: Biaya Tenaga Kerja: | B24: Jam Kerja | C24: Upah Perjam | D24: Total
A25: Upah Langsung | B25: 300 | C25: 12000 | D25: =B25*C25 -> 3600000
A26: Upah Tidak Langsung | D26: 1500000
A27: Jumlah Upah | D27: =SUM(D25:D26) -> 5100000
A28: Gaji Bagian Administrasi & Umum | D28: 3000000
A29: Gaji Bagian Pemasaran | D29: 4000000
A30: Jumlah Gaji | D30: =SUM(D28:D29) -> 7000000
A31: Jumlah Upah dan Gaji | D31: =D27+D30 -> 12100000
A33: Tarif Biaya Overhead Pabrik:
A34: BOP Pesanan dibebankan atas dasar tarif 150% dari Biaya Bahan Baku
A36: Biaya Overhead Pabrik Sesungguhnya:
A37: BOP yang sesungguhnya terjadi selain BTKTL dan Bahan Penolong adalah:
A39: Depresiasi Mesin | B39: 1300000
A40: Depresiasi Gedung Pabrik | B40: 1200000
A41: Biaya Asuransi Gedung Pabrik & Mesin | B41: 900000
A42: Biaya Pemeliharaan Mesin | B42: 1100000
A43: Biaya Pemeliharaan Gedung | B43: 1000000
A44: Total BOP sesungguhnya | B44: =SUM(B39:B43) -> 5500000
A46: Diminta:
A47: Buatlah jurnal-jurnal yang diperlukan.

Sheet Day 4 .2 Akuntansi Biaya
A2: PT MITRA
A3: JURNAL UMUM
A4: 43466
A6: Tanggal | B6: Keterangan | C6: Reff | D6: Debit | E6: Kredit
A7: Jurnal Mencatat Pembelian Bahan Baku dan Bahan Penolong
B8: Persediaan Bahan Baku | D8: =SUM('Day 4.1 Akuntansi Biaya'!D6:D7) -> 8000000
B9: Hutang Dagang | E9: =D8 -> 8000000
B10: (pembelian bahan baku)
B11: Persediaan Bahan Penolong | D11: ='Day 4.1 Akuntansi Biaya'!D8+'Day 4.1 Akuntansi Biaya'!D9 -> 10000000
B12: Hutang Dagang | E12: =D11 -> 10000000
A14: Jurnal Mencatat Pemakaian Bahan Baku dan Bahan Penolong
B15: Bahan Dalam Proses Bahan Baku | D15: ='Day 4.1 Akuntansi Biaya'!D17 -> 6700000
B16: Persediaaan Bahan baku | E16: =D15 -> 6700000
B18: Biaya Overhead Pabrik Sesungguhnya | D18: ='Day 4.1 Akuntansi Biaya'!D22 -> 8000000
B19: Persediaan Bahan Penolong | E19: =D18 -> 8000000
A21: Jurnal Mencatat Pembayaran Tenaga Kerja
B22: Barang Dalam Proses Tenaga Kerja Langsung | D22: ='Day 4.1 Akuntansi Biaya'!D25 -> 3600000
B23: Biaya Overhead Pabrik Sesungguhnya | D23: ='Day 4.1 Akuntansi Biaya'!D26 -> 1500000
B24: Biaya Administration Umum | D24: ='Day 4.1 Akuntansi Biaya'!D28 -> 3000000
B25: Biaya Pemasaran | D25: ='Day 4.1 Akuntansi Biaya'!D29 -> 4000000
B26: Utang Gaji Dan Upah | E26: =SUM(D22:D25) -> 12100000
B28: =B26 -> Utang Gaji Dan Upah | D28: =SUM(D22:D25) -> 12100000
B29: Kas | E29: =E26 -> 12100000
A31: Jurnal Mencatat Alokasi BOP
B32: Barang Dalam Proses - Biaya Overhead Pabrik | D32: =H35 -> 10050000 | G32: Mencari BOP DIBebankan
B33: Biaya Overhead Pabrik Di Bebankan | E33: =H35 -> 10050000 | G33: BBB | H33: 6700000
G34: BOP-Pesanan | H34: 1.5
B35: =B23 -> Biaya Overhead Pabrik Sesungguhnya | D35: ='Day 4.1 Akuntansi Biaya'!B44 -> 5500000 | G35: BDP-OP | H35: =H33*H34 -> 10050000
B36: Akumulasi Depresiasi Mesin Mesin | E36: 1300000
B37: Akumulasi Depresiasi Gedung Pabrik | E37: 1200000 | G37: Mencari Total Kas
B38: Kas | E38: =I42 -> 3000000 | G38: ='Day 4.1 Akuntansi Biaya'!A41 -> Biaya Asuransi Gedung Pabrik & Mesin | I38: {='Day 4.1 Akuntansi Biaya'!B41:B43} -> 900000
B39: (Biaya Asuransi Gedung Pabrik & Mesin,Pemeliharan Mesin Dan Pemeliharan Gedung) | G39: ='Day 4.1 Akuntansi Biaya'!A42 -> Biaya Pemeliharaan Mesin | I39: 1100000
G40: ='Day 4.1 Akuntansi Biaya'!A43 -> Biaya Pemeliharaan Gedung | I40: 1000000
B41: Biaya Overhead Pabrik Dibebankan | D41: =D32 -> 10050000
B42: =B23 -> Biaya Overhead Pabrik Sesungguhnya | E42: =D41 -> 10050000 | G42: Total Kas | I42: =SUM(I38:I41) -> 3000000
B44: Selisih Biaya Overhead Pabrik | D44: =K50 -> 4950000
B45: Biaya Overhead Pabrik Dibebankan | E45: =K50 -> 4950000 | G45: Mencari Selisih | K45: Jumlah Selisih | L45: Rugi / Untung
G46: BBP | H46: =E19 -> 8000000
A47: Jurnal Transfer Persediaan Barang Dalam Proses ke Persediaan Barang Jadi | G47: BTKL | H47: ='Day 4.1 Akuntansi Biaya'!D26 -> 1500000
B48: Persediaan Produk Jadi | D48: =SUM(E49:E51) -> 20350000 | G48: BOP-Sesunguhnya | H48: =D35 -> 5500000 | I48: BOP-Di Bebankan | J48: =E42 -> 10050000
...

Sheet Day 5.1 PPh 21
A18: Bulan | B18: Gaji (Rp)
A19: Januari | B19: 12000000
A20: Februari | B20: 12000000
A21: Maret | B21: 12000000
A22: April | B22: 12000000
A23: Mei | B23: 12000000
A24: Juni | B24: 12000000
A25: Juli | B25: 12000000
A26: Agustus | B26: 12000000
A27: September | B27: 12000000
A28: Oktober | B28: 12000000
A29: November | B29: 12000000
A30: Desember | B30: 12000000
A31: Total | B31: 144000000
A38: No | B38: Lapisan Penghasilan Bruto | C38: TER A(%) | F38: No | G38: Lapisan Penghasilan Bruto | H38: TER B(%) | K38: No | L38: Lapisan Penghasilan Bruto | M38: TER C(%)
A39: 1 | B39: 0 s/d 5.400.000 | C39: 0.00 | F39: 1 | G39: 0 s/d 6.200.000 | H39: 0.00 | K39: 1 | L39: 0 s/d 6.600.000 | M39: 0.00
A40: 2 | B40: 5.400.001 s/d 5.650.000 | C40: 0.25 | F40: 2 | G40: 6.200.001 s/d 6.500.000 | H40: 0.25 | K40: 2 | L40: 6.600.001 s/d 6.950.000 | M40: 0.25
A41: 3 | B41: 5.650.001 s/d 5.950.000 | C41: 0.50 | F41: 3 | G41: 6.500.001 s/d 6.850.000 | H41: 0.50 | K41: 3 | L41: 6.950.001 s/d 7.350.000 | M41: 0.50
A42: 4 | B42: 5.950.001 s/d 6.300.000 | C42: 0.75 | F42: 4 | G42: 6.850.001 s/d 7.300.000 | H42: 0.75 | K42: 4 | L42: 7.350.001 s/d 7.800.000 | M42: 0.75
A43: 5 | B43: 6.300.001 s/d 6.750.000 | C43: 1.00 | F43: 5 | G43: 7.300.001 s/d 9.200.000 | H43: 1.00 | K43: 5 | L43: 7.800.001 s/d 8.850.000 | M43: 1.00
A44: 6 | B44: 6.750.001 s/d 7.500.000 | C44: 1.25 | F44: 6 | G44: 9.200.001 s/d 10.750.000 | H44: 1.50 | K44: 6 | L44: 8.850.001 s/d 9.800.000 | M44: 1.25
A45: 7 | B45: 7.500.001 s/d 8.550.000 | C45: 1.50 | F45: 7 | G45: 10.750.001 s/d 11.250.000 | H45: 2.00 | K45: 7 | L45: 9.800.001 s/d 10.950.000 | M45: 1.50
A46: 8 | B46: 8.550.001 s/d 9.650.000 | C46: 1.75 | F46: 8 | G46: 11.250.001 s/d 11.600.000 | H46: 2.50 | K46: 8 | L46: 10.950.001 s/d 11.200.000 | M46: 2.00
A47: 9 | B47: 9.650.001 s/d 10.050.000 | C47: 2.00 | F47: 9 | G47: 11.600.001 s/d 12.600.000 | H47: 3.00 | K47: 9 | L47: 11.200.001 s/d 12.050.000 | M47: 2.50
A48: 10 | B48: 10.050.001 s/d 10.350.000 | C48: 2.25 | F48: 10 | G48: 12.600.001 s/d 13.600.000 | H48: 4.00 | K48: 10 | L48: 12.050.001 s/d 12.950.000 | M48: 3.00
A49: 11 | B49: 10.350.001 s/d 10.700.000 | C49: 2.50 | F49: 11 | G49: 13.600.001 s/d 14.950.000 | H49: 5.00 | K49: 11 | L49: 12.950.001 s/d 14.150.000 | M49: 4.00
A50: 12 | B50: 10.700.001 s/d 11.050.000 | C50: 3.00 | F50: 12 | G50: 14.950.001 s/d 16.400.000 | H50: 6.00 | K50: 12 | L50: 14.150.001 s/d 15.550.000 | M50: 5.00
... A78: 40 | B78: 454.000.001 s/d 550.000.000 | C78: 30.00 | F78: 40 | G78: lebih dari 1.405.000.000 | H78: 34.00 | K78: 40 | L78: 965.000.001 s/d 1.419.000.000 | M78: 33.00
A79: 41 | B79: 550.000.001 s/d 695.000.000 | C79: 31.00 | K79: 41 | L79: lebih dari 1.419.000.000 | M79: 34.00
A80: 42 | B80: 695.000.001 s/d 910.000.000 | C80: 32.00
A81: 43 | B81: 910.000.001 s/d 1.400.000.000 | C81: 33.00
A82: 44 | B82: lebih dari 1.400.000.000 | C82: 34.00
A86: Lapisan Tarif | B86: Penghasilan Kena Pajak | C86: Tarif PPh 21
A87: I | B87: 0 – Rp 60 juta | C87: 0.05
A88: II | B88: > Rp 60 – 250 juta | C88: 0.15
A89: III | B89: > Rp 250 – 500 juta | C89: 0.25
A90: IV | B90: > Rp 500 juta – 5 miliar | C90: 0.3
A91: V | B91: > 5 miliar | C91: 0.35

Sheet Day 5.2 PPh 21
A1: BULAN | B1: PENDAPATAN BRUTO | C1: TER-KATEGORI B | D1: PPH 21
A2: Januari | B2: 12000000 | C2: 0.03 | D2: 360000
A3: Febuari | B3: 12000000 | C3: 0.03 | D3: 360000
A4: Maret | B4: 12000000 | C4: 0.03 | D4: 360000
A5: April | B5: 12000000 | C5: 0.03 | D5: 360000
A6: Mei | B6: 12000000 | C6: 0.03 | D6: 360000
A7: Juni | B7: 12000000 | C7: 0.03 | D7: 360000
A8: Juli | B8: 12000000 | C8: 0.03 | D8: 360000
A9: Agustus | B9: 12000000 | C9: 0.03 | D9: 360000
A10: September | B10: 12000000 | C10: 0.03 | D10: 360000
A11: Oktober | B11: 12000000 | C11: 0.03 | D11: 360000
A12: November | B12: 12000000 | C12: 0.03 | D12: 360000
A13: Desember | B13: 12000000 | C13: 0.03 | D13: =_xludf.NUMBERVALUE(LEFT(C37,FIND(" ",C37)-1)) -> #NAME?
A19: Perhitungan PPH :
A20: Gaji bruto setahun | C20: 144000000
A22: Pengurang
A23: Biaya jabatan | B23: 6000000
A24: iuran peniun | B24: 1200000
C25: =SUM(B23:B24) -> 7200000
A26: Penghasian neto setahun | C26: =C20-C25 -> 136800000
A27: PTKP setahun
A28: Untuk wajib pajak sendiri | B28: 54000000
A29: Tambahan untuk menikah | B29: 4500000
A30: Tambahan untuk satu tanggungan | B30: 4500000
C31: =SUM(B28:B30) -> 63000000
A32: Penghasilan kena pajak setahun | C32: =C26-C31 -> 73800000
A33: 60000000 | B33: =A33*5% -> 3000000
A34: =C32-A33 -> 13800000 | B34: =A34*15% -> 2070000
C35: =SUM(B33:B34) -> 5070000
A36: PPh 21 yang dipotong hingga november 2024 | C36: =SUM(D2:D12) -> 3960000
A37: PPh 21 yang dipotong dibulan desember 2025 | C37: =IF(C35-C36<0,_xludf.CONCAT(TEXT(C35-C36,"#.##0")," ","(Lebih Bayar)"),IF(C35-C36>0,_xludf.CONCAT(TEXT(C35-C36,"#.##0")," ","(Kurang Bayar)"),_xludf.CONCAT(TEXT(C35-C36,"#.##0")," ","(Tidak Bayar)"))) -> #NAME?

Sheet Day 6.1 PPh Badan
A8: Bulan | B8: Peredaran Bruto
A9: Januari | B9: 325000000
A10: Februari | B10: 275000000
A11: Maret | B11: 400000000
A12: April | B12: 325000000
A13: Mei | B13: 275000000
A14: Juni | B14: 400000000
A15: Juli | B15: 400000000
A16: Agustus | B16: 275000000
A17: September | B17: 325000000
A18: Oktober | B18: 325000000
A19: November | B19: 275000000
A20: Desember | B20: 400000000
B21: 4000000000
A23: Penyelesaian :
A24: Bulan | B24: Peredaran Bruto | C24: Tarif PPh Final | D24: PPh Final (Rp)
A25: Januari | B25: 325000000 | C25: 0.005 | D25: =B25*C25 -> 1625000
A26: Februari | B26: 275000000 | C26: 0.005 | D26: =B26*C26 -> 1375000
A27: Maret | B27: 400000000 | C27: 0.005 | D27: =B27*C27 -> 2000000
A28: April | B28: 325000000 | C28: 0.005 | D28: =B28*C28 -> 1625000
A29: Mei | B29: 275000000 | C29: 0.005 | D29: =B29*C29 -> 1375000
A30: Juni | B30: 400000000 | C30: 0.005 | D30: =B30*C30 -> 2000000
A31: Juli | B31: 400000000 | C31: 0.005 | D31: =B31*C31 -> 2000000
A32: Agustus | B32: 275000000 | C32: 0.005 | D32: =B32*C32 -> 1375000
A33: September | B33: 325000000 | C33: 0.005 | D33: =B33*C33 -> 1625000
A34: Oktober | B34: 325000000 | C34: 0.005 | D34: =B34*C34 -> 1625000
A35: November | B35: 275000000 | C35: 0.005 | D35: =B35*C35 -> 1375000
A36: Desember | B36: 400000000 | C36: 0.005 | D36: =B36*C36 -> 2000000
A37: Total | B37: 4000000000 | C37: 0.005 | D37: =SUM(D25:D36) -> 20000000

Sheet Day 6.2 PPH Badan
A4: PT YOLO YOLO
A5: LAPORAN LABA RUGI
A6: Per 31 Desember 2023
A7: Penjualan | B7: 40000000000
A8: Harga Pokok Penjualan | B8: 25000000000
A9: Laba Kotor | B9: 15000000000
A10: Beban Operasi
A11: Beban Gaji | B11: 2000000000
A12: Beban Transportasi | B12: 500000000
A13: Beban Penyusutan | B13: 500000000
A14: Beban Kantor | B14: 2900000000
A15: Beban Pemeliharaan | B15: 1000000000
A16: Beban Lain-Lain | B16: 100000000
A17: Total Beban | B17: 7000000000
A18: Laba Bersih | B18: 8000000000
A35: Penyelesaian
A36: Penghasilan Kena Pajak mendapat fasilitas :
A37: Predaran Usaha Bruto | B37: 40000000000
A38: Penghasilan Kena Pajak | B38: 8000000000
A39: Penghasilan Kena Pajak Mendapat Fasilitas | B39: =(4800000000/B37)*B38 -> 960000000
A41: Penghasilan Kena Pajak yang tidak mendapat fasilitas | B41: =B38-B39 -> 7040000000
A43: PPh Terhtang :
A44: Atas penghasilan kena pajak mendapat fasilitas :
A45: Tarif PPh Badan | B45: 0.22
A46: Penghasilan Kena Pajak Mendapat Fasilitas | B46: =50%*B45*B39 -> 105600000
A47: Atas penghasilan kena pajak yang tidak mendapat fasilitas : | B47: =B39*B45 -> 211200000
A48: Total PPh Terutang | B48: =B46+B47 -> 316800000

Sheet Day 7 Pengantar Audit
A54: Inherent Risk (IR) | B54: 0.7
A55: Control Risk | B55: 0.6
A56: Accepted Audit Risk Level | B56: 0.15
A57: Detection Risk | B57: =(B56/(B54*B55)) -> 0.35714286

Sheet Day 8 Trial Ballance
A2: Kas dan Setara Kas | B2: Sebelum | C2: Sesudah
A3: Kas Kecil | B3: 5000000 | C3: =B3-$I$8 -> 3000000 | E3: Penyesuain
A4: Bank | E4: Tanggal | F4: Akun | G4: Reff | H4: Debit | I4: Kredit
A5: PT Bank Mandiri (Persero) Tbk | B5: 30000000 | C5: =B5 -> 30000000
A6: PT Bank Negara Indonesia (Persero) Tbk | B6: 25000000 | C6: =B6 -> 25000000 | F6: Beban Operasional | H6: 7000000
A7: PT Bank Rakyat Indonesia (Persero) Tbk | B7: 10000000 | C7: =B7 -> 10000000 | F7: Hutang Usaha | I7: 5000000
A8: Deposito | F8: Kas Kecil | I8: 2000000
A9: PT Bank Mandiri (Persero) Tbk | B9: 10000000 | C9: =B9 -> 10000000
A10: Total Kas dan Setara Kas | B10: =SUM(B2:B9) -> 80000000 | C10: =SUM(C2:C9) -> 78000000 | F10: Piutang Usaha | H10: 10000000
A11: Piutang Usaha | B11: 20000000 | C11: =B11+H10 -> 30000000 | F11: Pendapatan Usaha | I11: 10000000
A12: Persediaan | B12: 25000000 | C12: =B12 -> 25000000
A13: Peralatan | B13: 80000000 | C13: =B13 -> 80000000 | F13: Beban Penyusuan Peralatan | H13: 5000000
A14: Akumulasi Penyusutan | B14: 10000000 | C14: =B14+I14 -> 15000000 | F14: Akumulasi Penyusutan Peralatan | I14: 5000000
A15: Total Aset | B15: =SUM(B10:B13)-B14 -> 195000000 | C15: =SUM(C10:C13)-C14 -> 198000000
A17: Hutang usaha | B17: 15000000 | C17: =B17+I7 -> 20000000
A19: Ekuitas
A20: Modal Saham | B20: 100000000 | C20: =B20 -> 100000000
A21: Laba ditahan | B21: =SUM(B22:B23) -> 80000000 | C21: =B21 -> 80000000
A22: Laba tahun berjalan | B22: 60000000 | C22: =B22 -> 60000000
A23: Laba periode lalu | B23: 20000000 | C23: =B23 -> 20000000
A24: Total Liabilitas dan Ekuitas | B24: =SUM(B20:B21,,B17) -> 195000000 | C24: =SUM(C20:C21,,C17) -> 200000000
A26: Pendapatan Usaha | B26: 120000000 | C26: =B26+I11 -> 130000000
A27: Biaya Operasional | B27: 45000000 | C27: =B27+H6 -> 52000000
A28: Beban Penvusutan | B28: 5000000 | C28: =B28+H13 -> 10000000
A29: Pajak Penghasillan | B29: 10000000 | C29: =B29 -> 10000000
A30: Laba Usaha setelah pajak | B30: =B26-SUM(B27:B29) -> 60000000 | C30: =C26-SUM(C27:C29) -> 58000000

Sheet Neraca Saldo
A1: JUARA NET
A2: NERACA SALDO
A3: JANUARI 2023
A5: Kode Akun | B5: Nama Akun | C5: Debit | D5: Kredit
A6: ='Day 1.1 Informasi'!E5 -> 101 | B6: ='Day 1.1 Informasi'!F5 -> Kas | C6: ='Day 1.3 Buku Besar'!F14
A7: ='Day 1.1 Informasi'!E6 -> 102 | B7: ='Day 1.1 Informasi'!F6 -> Piutang Usaha | C7: ='Day 1.3 Buku Besar'!F25
A8: ='Day 1.1 Informasi'!E7 -> 103 | B8: ='Day 1.1 Informasi'!F7 -> Perlengkapan | C8: ='Day 1.3 Buku Besar'!F35 -> 1000000
A9: ='Day 1.1 Informasi'!E8 -> 104 | B9: ='Day 1.1 Informasi'!F8 -> Sewa Dibayar Dimuka | C9: ='Day 1.3 Buku Besar'!F46 -> 12000000
A10: ='Day 1.1 Informasi'!E9 -> 121 | B10: ='Day 1.1 Informasi'!F9 -> Peralatan Jaringan | C10: ='Day 1.3 Buku Besar'!F57 -> 7000000
A11: ='Day 1.1 Informasi'!E10 -> 201 | B11: ='Day 1.1 Informasi'!F10 -> Utang Usaha | D11: ='Day 1.3 Buku Besar'!G69 -> 4000000
A12: ='Day 1.1 Informasi'!E11 -> 301 | B12: ='Day 1.1 Informasi'!F11 -> Modal Usaha | D12: ='Day 1.3 Buku Besar'!G80
A13: ='Day 1.1 Informasi'!E12 -> 302 | B13: ='Day 1.1 Informasi'!F12 -> Prive Bapak Andika | C13: ='Day 1.3 Buku Besar'!F90 -> 2000000
A14: ='Day 1.1 Informasi'!E13 -> 401 | B14: ='Day 1.1 Informasi'!F13 -> Pendapatan Usaha | D14: ='Day 1.3 Buku Besar'!G102 -> 12500000
A15: ='Day 1.1 Informasi'!E14 -> 501 | B15: ='Day 1.1 Informasi'!F14 -> Beban Gaji | C15: ='Day 1.3 Buku Besar'!F112 -> 4500000
A16: ='Day 1.1 Informasi'!E15 -> 502 | B16: ='Day 1.1 Informasi'!F15 -> Beban Sewa | C16: ='Day 1.3 Buku Besar'!F123 -> 0
A17: TOTAL | C17: =SUM(C6:C16) -> 26500000 | D17: =SUM(D6:D16) -> 16500000
