Workbook
Name Slicer_Jenis_item: #N/A
Name Slicer_Lokasi_pembeli: #N/A
Name Slicer_Marketplace: #N/A
Name Slicer_Months__Tanggal_terjual: #N/A
Name Slicer_Quarters__Tanggal_terjual: #N/A

Sheet Guide 
A1: Guide pengerjaan sheet Main Data dan Final Project
A2: 1. Mengisi data pada kolom OrderID dengan format = ORD-(Kode Marketplace)-(No)-(Tanggal Terjual dengan format dd/mm/yy)
B3: Contoh : | C3: ORD-BB-0001-05/04/23
C4: ORD-SP-0978-20/04/23
A5: 2. Merapihkan data item, quantity dan rating dari setiap transaksi | J5: `
A6: 3. Menghitung total quantity per transaksi dan total nilai transaksi
A7: 4. Melakukan pemrosesan untuk melengkapi data sebelum melakukan analisa (perhitungan, lookup, dll.)
A8: 5. Lakukan analisa terkait data transaksi untuk menghasilkan inisght penjualan, contoh:
A9: 6. Untuk menampilkan insight tersebut, buatlah visualisasi data dalam bentuk Dashboard (minimal 4 chart + 1 slicer dan gunakan Pivot Table)
A10: 7. Sajikan data dengan baik dan presentasikan tentang bagaimana cara mendapatkan insight dari data penjualan dalam 1 bulan ini dan apa saja yang akan dilakukan anda sebagai Brand Owner
A11: 8. Anda bebas menambahkan parameter lain di "Main Data" seperti pada file contoh (contoh: Total margin produksi, Total Profit, Jumlah item per Tansaksi, dll.)
A12: Ketentuan kode marketplace:
A13: Tokopedia | B13: TK
A14: Shopee | B14: SP
A15: BliBli | B15: BB
A16: Bukalapak | B16: BL
A18: Keterangan
A19: {=TRANSPOSE('Main Data'!A2:AM2)} -> No | B19: Nomor data
A20: Code_No | B20: ID pesanan
A21: OrderID | B21: Data item, quantity dan rating barang dalam transaksi
A22: Item | B22: Kode barang pembelian ke-1
A23: Item A | B23: Quantity barang pembelian ke-1
A24: Jenis item | B24: Rating barang pembelian ke-1
A25: Kategori | B25: Harga barang pembelian ke-1
A26: Qty A | B26: Kode barang pembelian ke-2
A27: Rating A | B27: Quantity barang pembelian ke-2
A28: Harga Barang A | B28: Rating barang pembelian ke-2
A29: Modal Barang A | B29: Harga barang pembelian ke-2
A30: Item B | B30: Kode barang pembelian ke-3
A31: Jenis Item | B31: Quantity barang pembelian ke-3
... A41: Rating C | B41: Tanggal dilakukannya pembelian
A42: Harga Barang C
A43: Modal Barang C
A44: Total Qty
A45: Total Transaksi
A46: Total Modal
A47: Kode diskon
A48: Diskon
A49: Potongan Diskon
A50: Harga Setelah Diskon
...

Sheet Kode Diskon
A1: Kode Diskon [NAMA BRAND] Bulan April 2023
A2: Platform | B2: Jenis Promo | C2: Kode Diskon | D2: Besar Diskon
A3: Shopee | B3: Promo 4.4 | C3: DISC10 | D3: 0.1
A4: Shopee | B4: Promo 4.4 | C4: DISC15 | D4: 0.15
A5: Shopee | B5: Promo Lebaran | C5: DISC20 | D5: 0.2
A6: Tokopedia | B6: Promo 4.4 | C6: DISCAPRIL | D6: 0.1
A7: Tokopedia | B7: Promo Lebaran | C7: LEBAR10 | D7: 0.1
A8: Bukalapak | B8: Promo Lebaran | C8: BUKALEBAR | D8: 0.15
A9: BliBli | B9: Promo 4.4 | C9: BELI44 | D9: 0.15

Sheet Katalog
A1: KATALOG [NAMA BRAND]
C2: 1 | D2: 2 | E2: 3 | F2: 4
A3: Kategori | B3: Nama Barang | C3: Kode Barang | D3: Harga Jual | E3: Harga Produksi | F3: Laba
A4: Pakaian Wanita | B4: Dress | C4: PW001 | D4: 150000 | E4: 55000 | F4: =D4-E4 -> 95000
A5: Pakaian Wanita | B5: Blouse | C5: PW002 | D5: 125000 | E5: 50000 | F5: =D5-E5 -> 75000
A6: Pakaian Wanita | B6: Kaftan | C6: PW003 | D6: 200000 | E6: 100000 | F6: =D6-E6 -> 100000
A7: Pakaian Pria | B7: Kaos Polo | C7: PP001 | D7: 80000 | E7: 30000 | F7: =D7-E7 -> 50000
A8: Pakaian Pria | B8: Celana Pendek | C8: PP002 | D8: 60000 | E8: 25000 | F8: =D8-E8 -> 35000
A9: Pakaian Pria | B9: Jaket Jeans | C9: PP003 | D9: 150000 | E9: 70000 | F9: =D9-E9 -> 80000
A10: Pakaian Unisex | B10: Jaket Hoodie | C10: PU001 | D10: 160000 | E10: 60000 | F10: =D10-E10 -> 100000
A11: Sepatu Pria | B11: Sneakers | C11: SP001 | D11: 300000 | E11: 100000 | F11: =D11-E11 -> 200000
A12: Sepatu Pria | B12: Sandal Slip On | C12: SP002 | D12: 120000 | E12: 60000 | F12: =D12-E12 -> 60000
A13: Sepatu Wanita | B13: Flat Shoes | C13: SW001 | D13: 150000 | E13: 70000 | F13: =D13-E13 -> 80000
A15: Kode Barang | B15: Kategori
A16: PW001 | B16: Pakaian Wanita
A17: PW002 | B17: Pakaian Wanita
A18: PW003 | B18: Pakaian Wanita
A19: PP001 | B19: Pakaian Pria
A20: PP002 | B20: Pakaian Pria
A21: PP003 | B21: Pakaian Pria
A22: PU001 | B22: Pakaian Unisex
A23: SP001 | B23: Sepatu Pria
A24: SP002 | B24: Sepatu Pria
A25: SW001 | B25: Sepatu Wanita

Sheet Tanggal
A1: =DATE(2024,RANDBETWEEN(1,12),RANDBETWEEN(1,31)) -> 45590 | B1: 45418
A2: =DATE(2024,RANDBETWEEN(1,12),RANDBETWEEN(1,31)) -> 45451 | B2: 45458
A3: =DATE(2024,RANDBETWEEN(1,12),RANDBETWEEN(1,31)) -> 45635 | B3: 45503
A4: =DATE(2024,RANDBETWEEN(1,12),RANDBETWEEN(1,31)) -> 45323 | B4: 45525
A5: =DATE(2024,RANDBETWEEN(1,12),RANDBETWEEN(1,31)) -> 45427 | B5: 45324
A6: =DATE(2024,RANDBETWEEN(1,12),RANDBETWEEN(1,31)) -> 45624 | B6: 45498
A7: =DATE(2024,RANDBETWEEN(1,12),RANDBETWEEN(1,31)) -> 45400 | B7: 45359
A8: =DATE(2024,RANDBETWEEN(1,12),RANDBETWEEN(1,31)) -> 45419 | B8: 45494
A9: =DATE(2024,RANDBETWEEN(1,12),RANDBETWEEN(1,31)) -> 45339 | B9: 45635
A10: =DATE(2024,RANDBETWEEN(1,12),RANDBETWEEN(1,31)) -> 45333 | B10: 45374
A11: =DATE(2024,RANDBETWEEN(1,12),RANDBETWEEN(1,31)) -> 45554 | B11: 45422
A12: =DATE(2024,RANDBETWEEN(1,12),RANDBETWEEN(1,31)) -> 45600 | B12: 45511
... A1000: =DATE(2024,RANDBETWEEN(1,12),RANDBETWEEN(1,31)) -> 45596 | B1000: 45566

Sheet Main Data
C1: =_xlfn.FORMULATEXT(C3) -> =CONCATENATE("ORD";"-";AK3;"-";B3;"-";TEXT(AM3;"dd/mm/yy")) | P1: =_xlfn.FORMULATEXT(K3) -> =VLOOKUP(E3;Katalog!$C$3:$F$13;3;0)
A2: No | B2: Code_No | C2: OrderID | D2: Item | E2: Item A | F2: Jenis item | G2: Kategori | H2: Qty A | I2: Rating A | J2: Harga Barang A | K2: Modal Barang A | L2: Item B | M2: Jenis Item | N2: Kategori | O2: Qty B | P2: Rating B | Q2: Harga Barang B | R2: Modal Barang B | S2: Item C | T2: Jenis Item | U2: Kategori | V2: Qty C | W2: Rating C | X2: Harga Barang C | Y2: Modal Barang C | Z2: Total Qty | AA2: Total Transaksi | AB2: Total Modal | AC2: Kode diskon | AD2: Diskon | AE2: Potongan Diskon | AF2: Harga Setelah Diskon | AG2: Laba | AH2: Laba (Descount) | AI2: Jenis promo | AJ2: Marketplace | AK2: Kode Marketplace | AL2: Lokasi pembeli | AM2: Tanggal Terjual | AN2: :2(a) | AO2: ,2(a) | AP2: :3(a) | AQ2: }(a) | AR2: :1(b) | AS2: ,1(b) | AT2: :1(a) | AU2: ,1(a) | AV2: :2(b) | AW2: ,2(b) | AX2: :3(b) | AY2: }(b) | AZ2: :1c | BA2: ,1c | BB2: :2c | BC2: ,2c | BD2: :3c | BE2: }c
A3: 246 | B3: =TEXT(A3,"0000") -> 0246 | C3: =CONCATENATE("ORD","-",AK3,"-",B3,"-",TEXT(AM3,"dd/mm/yy")) -> ORD-SP-0246-01/01/24 | D3: [{item_code: PP001, quantity: 2, rating: 3}, {item_code: PW002, quantity: 1, rating: 4}] | E3: =MID(D3,AT3+2,AU3-AT3-2) -> PP001 | F3: =INDEX(Katalog!$B$4:$B$13,MATCH('Main Data'!E3,Katalog!$C$4:$C$13,0)) -> Kaos Polo | G3: =VLOOKUP(E3,Katalog!$A$15:$B$25,2,0) -> Pakaian Pria | H3: =MID(D3,AN3+2,AO3-AN3-2) -> 2 | I3: =MID(D3,AP3+2,AQ3-AP3-2) -> 3 | J3: =VLOOKUP(E3,Katalog!$C$3:$F$13,2,0) -> 80000 | K3: =VLOOKUP(E3,Katalog!$C$3:$F$13,3,0) -> 30000 | L3: =IFERROR(MID(D3,AR3+2,AS3-AR3-2),"-") -> PW002 | M3: =IFERROR(INDEX(Katalog!$B$4:$B$13,MATCH('Main Data'!L3,Katalog!$C$4:$C$13,0)), "-") -> Blouse | N3: =IFERROR(VLOOKUP(L3,Katalog!$A$15:$B$25,2,0),"-") -> Pakaian Wanita | O3: =IFERROR(MID(D3,AV3+2,AW3-AV3-2),0) -> 1 | P3: =IFERROR(MID(D3,AX3+2,AY3-AX3-2),"-") -> 4 | Q3: =IFERROR(VLOOKUP(L3,Katalog!$C$3:$F$13,2,0),0) -> 125000 | R3: =IFERROR(VLOOKUP(L3,Katalog!$C$3:$F$13,3,0),0) -> 50000 | S3: =IFERROR(MID(D3,AZ3+2,BA3-AZ3-2),"-") -> - | T3: =IFERROR(INDEX(Katalog!$B$4:$B$13,MATCH('Main Data'!S3,Katalog!$C$4:$C$13,0)),"-") -> - | U3: =IFERROR(VLOOKUP(S3,Katalog!$A$15:$B$25,2,0),"-") -> - | V3: =IFERROR(MID(D3,BB3+2,BC3-BB3-2),0) -> 0 | W3: =IFERROR(MID(D3,BD3+2,BE3-BD3-2),"-") -> - | X3: =IFERROR(VLOOKUP(S3,Katalog!$C$3:$F$13,2,0),0) -> 0 | Y3: =IFERROR(VLOOKUP(S3,Katalog!$C$3:$F$13,3,0),0) -> 0 | Z3: =H3+O3+V3 -> 3 | AA3: =J3*H3+Q3*O3+X3*V3 -> 285000 | AB3: =K3*H3+R3*O3+Y3*V3 -> 110000 | AC3: DISC15 | AD3: =IFERROR(VLOOKUP(AC3,'Kode Diskon'!$C$2:$D$9,2,0),0) -> 0.15 | AE3: =AA3*AD3 -> 42750 | AF3: =AA3-AE3 -> 242250 | AG3: =AA3-AB3 -> 175000 | AH3: =AF3-AB3 -> 132250 | AI3: Promo 4.4 | AJ3: Shopee | AK3: =IFERROR(VLOOKUP(AJ3,'Guide '!$A$13:$B$16,2,0),"-") -> SP | AL3: Banten | AM3: 45292 | AN3: =FIND(":",D3,AT3+1) -> 29 | AO3: =FIND(",",D3,AU3+1) -> 32 | AP3: =FIND(":",D3,AN3+1) -> 40 | AQ3: =FIND("}",D3,AO3+1) -> 43 | AR3: =IFERROR(FIND(":",D3,AP3+1),"-") -> 56 | AS3: =IFERROR(FIND(",",D3,AQ3+2),"-") -> 63 | AT3: =FIND(":",D3) -> 12 | AU3: =FIND(",",D3) -> 19 | AV3: =IFERROR(FIND(":",D3,AR3+1),"-") -> 73 | AW3: =IFERROR(FIND(",",D3,AS3+1),"-") -> 76 | AX3: =IFERROR(FIND(":",D3,AV3+1),"-") -> 84 | AY3: =IFERROR(FIND("}",D3,AW3+1),"-") -> 87 | AZ3: =IFERROR(FIND(":",D3,AX3+1),"-") -> - | BA3: =IFERROR(FIND(",",D3,AY3+2),"-") -> - | BB3: =IFERROR(FIND(":",D3,AZ3+1),"-") -> - | BC3: =IFERROR(FIND(",",D3,BA3+1),"-") -> - | BD3: =IFERROR(FIND(":",D3,BB3+1),"-") -> - | BE3: =IFERROR(FIND("}",D3,BC3+1),"-") -> -
A4: 405 | B4: =TEXT(A4,"0000") -> 0405 | C4: =CONCATENATE("ORD","-",AK4,"-",B4,"-",TEXT(AM4,"dd/mm/yy")) -> ORD-SP-0405-01/01/24 | D4: [{item_code: PP001, quantity: 4, rating: 5}, {item_code: PW003, quantity: 1, rating: 2}, {item_code: PW002, quantity: 2, rating: 1}] | E4: =MID(D4,AT4+2,AU4-AT4-2) -> PP001 | F4: =INDEX(Katalog!$B$4:$B$13,MATCH('Main Data'!E4,Katalog!$C$4:$C$13,0)) -> Kaos Polo | G4: =VLOOKUP(E4,Katalog!$A$15:$B$25,2,0) -> Pakaian Pria | H4: =MID(D4,AN4+2,AO4-AN4-2) -> 4 | I4: =MID(D4,AP4+2,AQ4-AP4-2) -> 5 | J4: =VLOOKUP(E4,Katalog!$C$3:$F$13,2,0) -> 80000 | K4: =VLOOKUP(E4,Katalog!$C$3:$F$13,3,0) -> 30000 | L4: =IFERROR(MID(D4,AR4+2,AS4-AR4-2),"-") -> PW003 | M4: =IFERROR(INDEX(Katalog!$B$4:$B$13,MATCH('Main Data'!L4,Katalog!$C$4:$C$13,0)), "-") -> Kaftan | N4: =IFERROR(VLOOKUP(L4,Katalog!$A$15:$B$25,2,0),"-") -> Pakaian Wanita | O4: =IFERROR(MID(D4,AV4+2,AW4-AV4-2),0) -> 1 | P4: =IFERROR(MID(D4,AX4+2,AY4-AX4-2),"-") -> 2 | Q4: =IFERROR(VLOOKUP(L4,Katalog!$C$3:$F$13,2,0),0) -> 200000 | R4: =IFERROR(VLOOKUP(L4,Katalog!$C$3:$F$13,3,0),0) -> 100000 | S4: =IFERROR(MID(D4,AZ4+2,BA4-AZ4-2),"-") -> PW002 | T4: =IFERROR(INDEX(Katalog!$B$4:$B$13,MATCH('Main Data'!S4,Katalog!$C$4:$C$13,0)),"-") -> Blouse | U4: =IFERROR(VLOOKUP(S4,Katalog!$A$15:$B$25,2,0),"-") -> Pakaian Wanita | V4: =IFERROR(MID(D4,BB4+2,BC4-BB4-2),0) -> 2 | W4: =IFERROR(MID(D4,BD4+2,BE4-BD4-2),"-") -> 1 | X4: =IFERROR(VLOOKUP(S4,Katalog!$C$3:$F$13,2,0),0) -> 125000 | Y4: =IFERROR(VLOOKUP(S4,Katalog!$C$3:$F$13,3,0),0) -> 50000 | Z4: =H4+O4+V4 -> 7 | AA4: =J4*H4+Q4*O4+X4*V4 -> 770000 | AB4: =K4*H4+R4*O4+Y4*V4 -> 320000 | AC4: DISC20 | AD4: =IFERROR(VLOOKUP(AC4,'Kode Diskon'!$C$2:$D$9,2,0),0) -> 0.2 | AE4: =AA4*AD4 -> 154000 | AF4: =AA4-AE4 -> 616000 | AG4: =AA4-AB4 -> 450000 | AH4: =AF4-AB4 -> 296000 | AI4: Promo Lebaran | AJ4: Shopee | AK4: =IFERROR(VLOOKUP(AJ4,'Guide '!$A$13:$B$16,2,0),"-") -> SP | AL4: Jawa Tengah | AM4: 45292 | AN4: =FIND(":",D4,AT4+1) -> 29 | AO4: =FIND(",",D4,AU4+1) -> 32 | AP4: =FIND(":",D4,AN4+1) -> 40 | AQ4: =FIND("}",D4,AO4+1) -> 43 | AR4: =IFERROR(FIND(":",D4,AP4+1),"-") -> 56 | AS4: =IFERROR(FIND(",",D4,AQ4+2),"-") -> 63 | AT4: =FIND(":",D4) -> 12 | AU4: =FIND(",",D4) -> 19 | AV4: =IFERROR(FIND(":",D4,AR4+1),"-") -> 73 | AW4: =IFERROR(FIND(",",D4,AS4+1),"-") -> 76 | AX4: =IFERROR(FIND(":",D4,AV4+1),"-") -> 84 | AY4: =IFERROR(FIND("}",D4,AW4+1),"-") -> 87 | AZ4: =IFERROR(FIND(":",D4,AX4+1),"-") -> 100 | BA4: =IFERROR(FIND(",",D4,AY4+2),"-") -> 107 | BB4: =IFERROR(FIND(":",D4,AZ4+1),"-") -> 117 | BC4: =IFERROR(FIND(",",D4,BA4+1),"-") -> 120 | BD4: =IFERROR(FIND(":",D4,BB4+1),"-") -> 128 | BE4: =IFERROR(FIND("}",D4,BC4+1),"-") -> 131
A5: 610 | B5: =TEXT(A5,"0000") -> 0610 | C5: =CONCATENATE("ORD","-",AK5,"-",B5,"-",TEXT(AM5,"dd/mm/yy")) -> ORD-TK-0610-02/01/24 | D5: [{item_code: PP001, quantity: 6, rating: 1}, {item_code: PW003, quantity: 1, rating: 2}] | E5: =MID(D5,AT5+2,AU5-AT5-2) -> PP001 | F5: =INDEX(Katalog!$B$4:$B$13,MATCH('Main Data'!E5,Katalog!$C$4:$C$13,0)) -> Kaos Polo | G5: =VLOOKUP(E5,Katalog!$A$15:$B$25,2,0) -> Pakaian Pria | H5: =MID(D5,AN5+2,AO5-AN5-2) -> 6 | I5: =MID(D5,AP5+2,AQ5-AP5-2) -> 1 | J5: =VLOOKUP(E5,Katalog!$C$3:$F$13,2,0) -> 80000 | K5: =VLOOKUP(E5,Katalog!$C$3:$F$13,3,0) -> 30000 | L5: =IFERROR(MID(D5,AR5+2,AS5-AR5-2),"-") -> PW003 | M5: =IFERROR(INDEX(Katalog!$B$4:$B$13,MATCH('Main Data'!L5,Katalog!$C$4:$C$13,0)), "-") -> Kaftan | N5: =IFERROR(VLOOKUP(L5,Katalog!$A$15:$B$25,2,0),"-") -> Pakaian Wanita | O5: =IFERROR(MID(D5,AV5+2,AW5-AV5-2),0) -> 1 | P5: =IFERROR(MID(D5,AX5+2,AY5-AX5-2),"-") -> 2 | Q5: =IFERROR(VLOOKUP(L5,Katalog!$C$3:$F$13,2,0),0) -> 200000 | R5: =IFERROR(VLOOKUP(L5,Katalog!$C$3:$F$13,3,0),0) -> 100000 | S5: =IFERROR(MID(D5,AZ5+2,BA5-AZ5-2),"-") -> - | T5: =IFERROR(INDEX(Katalog!$B$4:$B$13,MATCH('Main Data'!S5,Katalog!$C$4:$C$13,0)),"-") -> - | U5: =IFERROR(VLOOKUP(S5,Katalog!$A$15:$B$25,2,0),"-") -> - | V5: =IFERROR(MID(D5,BB5+2,BC5-BB5-2),0) -> 0 | W5: =IFERROR(MID(D5,BD5+2,BE5-BD5-2),"-") -> - | X5: =IFERROR(VLOOKUP(S5,Katalog!$C$3:$F$13,2,0),0) -> 0 | Y5: =IFERROR(VLOOKUP(S5,Katalog!$C$3:$F$13,3,0),0) -> 0 | Z5: =H5+O5+V5 -> 7 | AA5: =J5*H5+Q5*O5+X5*V5 -> 680000 | AB5: =K5*H5+R5*O5+Y5*V5 -> 280000 | AC5: - | AD5: =IFERROR(VLOOKUP(AC5,'Kode Diskon'!$C$2:$D$9,2,0),0) -> 0 | AE5: =AA5*AD5 -> 0 | AF5: =AA5-AE5 -> 680000 | AG5: =AA5-AB5 -> 400000 | AH5: =AF5-AB5 -> 400000 | AI5: - | AJ5: Tokopedia | AK5: =IFERROR(VLOOKUP(AJ5,'Guide '!$A$13:$B$16,2,0),"-") -> TK | AL5: Jawa Timur | AM5: 45293 | AN5: =FIND(":",D5,AT5+1) -> 29 | AO5: =FIND(",",D5,AU5+1) -> 32 | AP5: =FIND(":",D5,AN5+1) -> 40 | AQ5: =FIND("}",D5,AO5+1) -> 43 | AR5: =IFERROR(FIND(":",D5,AP5+1),"-") -> 56 | AS5: =IFERROR(FIND(",",D5,AQ5+2),"-") -> 63 | AT5: =FIND(":",D5) -> 12 | AU5: =FIND(",",D5) -> 19 | AV5: =IFERROR(FIND(":",D5,AR5+1),"-") -> 73 | AW5: =IFERROR(FIND(",",D5,AS5+1),"-") -> 76 | AX5: =IFERROR(FIND(":",D5,AV5+1),"-") -> 84 | AY5: =IFERROR(FIND("}",D5,AW5+1),"-") -> 87 | AZ5: =IFERROR(FIND(":",D5,AX5+1),"-") -> - | BA5: =IFERROR(FIND(",",D5,AY5+2),"-") -> - | BB5: =IFERROR(FIND(":",D5,AZ5+1),"-") -> - | BC5: =IFERROR(FIND(",",D5,BA5+1),"-") -> - | BD5: =IFERROR(FIND(":",D5,BB5+1),"-") -> - | BE5: =IFERROR(FIND("}",D5,BC5+1),"-") -> -
A6: 820 | B6: =TEXT(A6,"0000") -> 0820 | C6: =CONCATENATE("ORD","-",AK6,"-",B6,"-",TEXT(AM6,"dd/mm/yy")) -> ORD-BL-0820-02/01/24 | D6: [{item_code: PP001, quantity: 3, rating: 1}, {item_code: PP002, quantity: 1, rating: 2}, {item_code: PW002, quantity: 1, rating: 1}] | E6: =MID(D6,AT6+2,AU6-AT6-2) -> PP001 | F6: =INDEX(Katalog!$B$4:$B$13,MATCH('Main Data'!E6,Katalog!$C$4:$C$13,0)) -> Kaos Polo | G6: =VLOOKUP(E6,Katalog!$A$15:$B$25,2,0) -> Pakaian Pria | H6: =MID(D6,AN6+2,AO6-AN6-2) -> 3 | I6: =MID(D6,AP6+2,AQ6-AP6-2) -> 1 | J6: =VLOOKUP(E6,Katalog!$C$3:$F$13,2,0) -> 80000 | K6: =VLOOKUP(E6,Katalog!$C$3:$F$13,3,0) -> 30000 | L6: =IFERROR(MID(D6,AR6+2,AS6-AR6-2),"-") -> PP002 | M6: =IFERROR(INDEX(Katalog!$B$4:$B$13,MATCH('Main Data'!L6,Katalog!$C$4:$C$13,0)), "-") -> Celana Pendek | N6: =IFERROR(VLOOKUP(L6,Katalog!$A$15:$B$25,2,0),"-") -> Pakaian Pria | O6: =IFERROR(MID(D6,AV6+2,AW6-AV6-2),0) -> 1 | P6: =IFERROR(MID(D6,AX6+2,AY6-AX6-2),"-") -> 2 | Q6: =IFERROR(VLOOKUP(L6,Katalog!$C$3:$F$13,2,0),0) -> 60000 | R6: =IFERROR(VLOOKUP(L6,Katalog!$C$3:$F$13,3,0),0) -> 25000 | S6: =IFERROR(MID(D6,AZ6+2,BA6-AZ6-2),"-") -> PW002 | T6: =IFERROR(INDEX(Katalog!$B$4:$B$13,MATCH('Main Data'!S6,Katalog!$C$4:$C$13,0)),"-") -> Blouse | U6: =IFERROR(VLOOKUP(S6,Katalog!$A$15:$B$25,2,0),"-") -> Pakaian Wanita | V6: =IFERROR(MID(D6,BB6+2,BC6-BB6-2),0) -> 1 | W6: =IFERROR(MID(D6,BD6+2,BE6-BD6-2),"-") -> 1 | X6: =IFERROR(VLOOKUP(S6,Katalog!$C$3:$F$13,2,0),0) -> 125000 | Y6: =IFERROR(VLOOKUP(S6,Katalog!$C$3:$F$13,3,0),0) -> 50000 | Z6: =H6+O6+V6 -> 5 | AA6: =J6*H6+Q6*O6+X6*V6 -> 425000 | AB6: =K6*H6+R6*O6+Y6*V6 -> 165000 | AC6: BUKALEBAR | AD6: =IFERROR(VLOOKUP(AC6,'Kode Diskon'!$C$2:$D$9,2,0),0) -> 0.15 | AE6: =AA6*AD6 -> 63750 | AF6: =AA6-AE6 -> 361250 | AG6: =AA6-AB6 -> 260000 | AH6: =AF6-AB6 -> 196250 | AI6: Promo Lebaran | AJ6: Bukalapak | AK6: =IFERROR(VLOOKUP(AJ6,'Guide '!$A$13:$B$16,2,0),"-") -> BL | AL6: Jabodetabek | AM6: 45293 | AN6: =FIND(":",D6,AT6+1) -> 29 | AO6: =FIND(",",D6,AU6+1) -> 32 | AP6: =FIND(":",D6,AN6+1) -> 40 | AQ6: =FIND("}",D6,AO6+1) -> 43 | AR6: =IFERROR(FIND(":",D6,AP6+1),"-") -> 56 | AS6: =IFERROR(FIND(",",D6,AQ6+2),"-") -> 63 | AT6: =FIND(":",D6) -> 12 | AU6: =FIND(",",D6) -> 19 | AV6: =IFERROR(FIND(":",D6,AR6+1),"-") -> 73 | AW6: =IFERROR(FIND(",",D6,AS6+1),"-") -> 76 | AX6: =IFERROR(FIND(":",D6,AV6+1),"-") -> 84 | AY6: =IFERROR(FIND("}",D6,AW6+1),"-") -> 87 | AZ6: =IFERROR(FIND(":",D6,AX6+1),"-") -> 100 | BA6: =IFERROR(FIND(",",D6,AY6+2),"-") -> 107 | BB6: =IFERROR(FIND(":",D6,AZ6+1),"-") -> 117 | BC6: =IFERROR(FIND(",",D6,BA6+1),"-") -> 120 | BD6: =IFERROR(FIND(":",D6,BB6+1),"-") -> 128 | BE6: =IFERROR(FIND("}",D6,BC6+1),"-") -> 131
A7: 143 | B7: =TEXT(A7,"0000") -> 0143 | C7: =CONCATENATE("ORD","-",AK7,"-",B7,"-",TEXT(AM7,"dd/mm/yy")) -> ORD-SP-0143-03/01/24 | D7: [{item_code: SP002, quantity: 2, rating: 5}, {item_code: PP002, quantity: 3, rating: 5}] | E7: =MID(D7,AT7+2,AU7-AT7-2) -> SP002 | F7: =INDEX(Katalog!$B$4:$B$13,MATCH('Main Data'!E7,Katalog!$C$4:$C$13,0)) -> Sandal Slip On | G7: =VLOOKUP(E7,Katalog!$A$15:$B$25,2,0) -> Sepatu Pria | H7: =MID(D7,AN7+2,AO7-AN7-2) -> 2 | I7: =MID(D7,AP7+2,AQ7-AP7-2) -> 5 | J7: =VLOOKUP(E7,Katalog!$C$3:$F$13,2,0) -> 120000 | K7: =VLOOKUP(E7,Katalog!$C$3:$F$13,3,0) -> 60000 | L7: =IFERROR(MID(D7,AR7+2,AS7-AR7-2),"-") -> PP002 | M7: =IFERROR(INDEX(Katalog!$B$4:$B$13,MATCH('Main Data'!L7,Katalog!$C$4:$C$13,0)), "-") -> Celana Pendek | N7: =IFERROR(VLOOKUP(L7,Katalog!$A$15:$B$25,2,0),"-") -> Pakaian Pria | O7: =IFERROR(MID(D7,AV7+2,AW7-AV7-2),0) -> 3 | P7: =IFERROR(MID(D7,AX7+2,AY7-AX7-2),"-") -> 5 | Q7: =IFERROR(VLOOKUP(L7,Katalog!$C$3:$F$13,2,0),0) -> 60000 | R7: =IFERROR(VLOOKUP(L7,Katalog!$C$3:$F$13,3,0),0) -> 25000 | S7: =IFERROR(MID(D7,AZ7+2,BA7-AZ7-2),"-") -> - | T7: =IFERROR(INDEX(Katalog!$B$4:$B$13,MATCH('Main Data'!S7,Katalog!$C$4:$C$13,0)),"-") -> - | U7: =IFERROR(VLOOKUP(S7,Katalog!$A$15:$B$25,2,0),"-") -> - | V7: =IFERROR(MID(D7,BB7+2,BC7-BB7-2),0) -> 0 | W7: =IFERROR(MID(D7,BD7+2,BE7-BD7-2),"-") -> - | X7: =IFERROR(VLOOKUP(S7,Katalog!$C$3:$F$13,2,0),0) -> 0 | Y7: =IFERROR(VLOOKUP(S7,Katalog!$C$3:$F$13,3,0),0) -> 0 | Z7: =H7+O7+V7 -> 5 | AA7: =J7*H7+Q7*O7+X7*V7 -> 420000 | AB7: =K7*H7+R7*O7+Y7*V7 -> 195000 | AC7: DISC20 | AD7: =IFERROR(VLOOKUP(AC7,'Kode Diskon'!$C$2:$D$9,2,0),0) -> 0.2 | AE7: =AA7*AD7 -> 84000 | AF7: =AA7-AE7 -> 336000 | AG7: =AA7-AB7 -> 225000 | AH7: =AF7-AB7 -> 141000 | AI7: Promo Lebaran | AJ7: Shopee | AK7: =IFERROR(VLOOKUP(AJ7,'Guide '!$A$13:$B$16,2,0),"-") -> SP | AL7: Jabodetabek | AM7: 45294 | AN7: =FIND(":",D7,AT7+1) -> 29 | AO7: =FIND(",",D7,AU7+1) -> 32 | AP7: =FIND(":",D7,AN7+1) -> 40 | AQ7: =FIND("}",D7,AO7+1) -> 43 | AR7: =IFERROR(FIND(":",D7,AP7+1),"-") -> 56 | AS7: =IFERROR(FIND(",",D7,AQ7+2),"-") -> 63 | AT7: =FIND(":",D7) -> 12 | AU7: =FIND(",",D7) -> 19 | AV7: =IFERROR(FIND(":",D7,AR7+1),"-") -> 73 | AW7: =IFERROR(FIND(",",D7,AS7+1),"-") -> 76 | AX7: =IFERROR(FIND(":",D7,AV7+1),"-") -> 84 | AY7: =IFERROR(FIND("}",D7,AW7+1),"-") -> 87 | AZ7: =IFERROR(FIND(":",D7,AX7+1),"-") -> - | BA7: =IFERROR(FIND(",",D7,AY7+2),"-") -> - | BB7: =IFERROR(FIND(":",D7,AZ7+1),"-") -> - | BC7: =IFERROR(FIND(",",D7,BA7+1),"-") -> - | BD7: =IFERROR(FIND(":",D7,BB7+1),"-") -> - | BE7: =IFERROR(FIND("}",D7,BC7+1),"-") -> -
A8: 192 | B8: =TEXT(A8,"0000") -> 0192 | C8: =CONCATENATE("ORD","-",AK8,"-",B8,"-",TEXT(AM8,"dd/mm/yy")) -> ORD-BB-0192-03/01/24 | D8: [{item_code: PW001, quantity: 1, rating: 2}, {item_code: SW001, quantity: 1, rating: 3}] | E8: =MID(D8,AT8+2,AU8-AT8-2) -> PW001 | F8: =INDEX(Katalog!$B$4:$B$13,MATCH('Main Data'!E8,Katalog!$C$4:$C$13,0)) -> Dress | G8: =VLOOKUP(E8,Katalog!$A$15:$B$25,2,0) -> Pakaian Wanita | H8: =MID(D8,AN8+2,AO8-AN8-2) -> 1 | I8: =MID(D8,AP8+2,AQ8-AP8-2) -> 2 | J8: =VLOOKUP(E8,Katalog!$C$3:$F$13,2,0) -> 150000 | K8: =VLOOKUP(E8,Katalog!$C$3:$F$13,3,0) -> 55000 | L8: =IFERROR(MID(D8,AR8+2,AS8-AR8-2),"-") -> SW001 | M8: =IFERROR(INDEX(Katalog!$B$4:$B$13,MATCH('Main Data'!L8,Katalog!$C$4:$C$13,0)), "-") -> Flat Shoes | N8: =IFERROR(VLOOKUP(L8,Katalog!$A$15:$B$25,2,0),"-") -> Sepatu Wanita | O8: =IFERROR(MID(D8,AV8+2,AW8-AV8-2),0) -> 1 | P8: =IFERROR(MID(D8,AX8+2,AY8-AX8-2),"-") -> 3 | Q8: =IFERROR(VLOOKUP(L8,Katalog!$C$3:$F$13,2,0),0) -> 150000 | R8: =IFERROR(VLOOKUP(L8,Katalog!$C$3:$F$13,3,0),0) -> 70000 | S8: =IFERROR(MID(D8,AZ8+2,BA8-AZ8-2),"-") -> - | T8: =IFERROR(INDEX(Katalog!$B$4:$B$13,MATCH('Main Data'!S8,Katalog!$C$4:$C$13,0)),"-") -> - | U8: =IFERROR(VLOOKUP(S8,Katalog!$A$15:$B$25,2,0),"-") -> - | V8: =IFERROR(MID(D8,BB8+2,BC8-BB8-2),0) -> 0 | W8: =IFERROR(MID(D8,BD8+2,BE8-BD8-2),"-") -> - | X8: =IFERROR(VLOOKUP(S8,Katalog!$C$3:$F$13,2,0),0) -> 0 | Y8: =IFERROR(VLOOKUP(S8,Katalog!$C$3:$F$13,3,0),0) -> 0 | Z8: =H8+O8+V8 -> 2 | AA8: =J8*H8+Q8*O8+X8*V8 -> 300000 | AB8: =K8*H8+R8*O8+Y8*V8 -> 125000 | AC8: BELI44 | AD8: =IFERROR(VLOOKUP(AC8,'Kode Diskon'!$C$2:$D$9,2,0),0) -> 0.15 | AE8: =AA8*AD8 -> 45000 | AF8: =AA8-AE8 -> 255000 | AG8: =AA8-AB8 -> 175000 | AH8: =AF8-AB8 -> 130000 | AI8: Promo 4.4 | AJ8: BliBli | AK8: =IFERROR(VLOOKUP(AJ8,'Guide '!$A$13:$B$16,2,0),"-") -> BB | AL8: Jabodetabek | AM8: 45294 | AN8: =FIND(":",D8,AT8+1) -> 29 | AO8: =FIND(",",D8,AU8+1) -> 32 | AP8: =FIND(":",D8,AN8+1) -> 40 | AQ8: =FIND("}",D8,AO8+1) -> 43 | AR8: =IFERROR(FIND(":",D8,AP8+1),"-") -> 56 | AS8: =IFERROR(FIND(",",D8,AQ8+2),"-") -> 63 | AT8: =FIND(":",D8) -> 12 | AU8: =FIND(",",D8) -> 19 | AV8: =IFERROR(FIND(":",D8,AR8+1),"-") -> 73 | AW8: =IFERROR(FIND(",",D8,AS8+1),"-") -> 76 | AX8: =IFERROR(FIND(":",D8,AV8+1),"-") -> 84 | AY8: =IFERROR(FIND("}",D8,AW8+1),"-") -> 87 | AZ8: =IFERROR(FIND(":",D8,AX8+1),"-") -> - | BA8: =IFERROR(FIND(",",D8,AY8+2),"-") -> - | BB8: =IFERROR(FIND(":",D8,AZ8+1),"-") -> - | BC8: =IFERROR(FIND(",",D8,BA8+1),"-") -> - | BD8: =IFERROR(FIND(":",D8,BB8+1),"-") -> - | BE8: =IFERROR(FIND("}",D8,BC8+1),"-") -> -
A9: 40 | B9: =TEXT(A9,"0000") -> 0040 | C9: =CONCATENATE("ORD","-",AK9,"-",B9,"-",TEXT(AM9,"dd/mm/yy")) -> ORD-TK-0040-04/01/24 | D9: [{item_code: PW003, quantity: 2, rating: 5}, {item_code: PP002, quantity: 3, rating: 3}, {item_code: PP001, quantity: 2, rating: 3}] | E9: =MID(D9,AT9+2,AU9-AT9-2) -> PW003 | F9: =INDEX(Katalog!$B$4:$B$13,MATCH('Main Data'!E9,Katalog!$C$4:$C$13,0)) -> Kaftan | G9: =VLOOKUP(E9,Katalog!$A$15:$B$25,2,0) -> Pakaian Wanita | H9: =MID(D9,AN9+2,AO9-AN9-2) -> 2 | I9: =MID(D9,AP9+2,AQ9-AP9-2) -> 5 | J9: =VLOOKUP(E9,Katalog!$C$3:$F$13,2,0) -> 200000 | K9: =VLOOKUP(E9,Katalog!$C$3:$F$13,3,0) -> 100000 | L9: =IFERROR(MID(D9,AR9+2,AS9-AR9-2),"-") -> PP002 | M9: =IFERROR(INDEX(Katalog!$B$4:$B$13,MATCH('Main Data'!L9,Katalog!$C$4:$C$13,0)), "-") -> Celana Pendek | N9: =IFERROR(VLOOKUP(L9,Katalog!$A$15:$B$25,2,0),"-") -> Pakaian Pria | O9: =IFERROR(MID(D9,AV9+2,AW9-AV9-2),0) -> 3 | P9: =IFERROR(MID(D9,AX9+2,AY9-AX9-2),"-") -> 3 | Q9: =IFERROR(VLOOKUP(L9,Katalog!$C$3:$F$13,2,0),0) -> 60000 | R9: =IFERROR(VLOOKUP(L9,Katalog!$C$3:$F$13,3,0),0) -> 25000 | S9: =IFERROR(MID(D9,AZ9+2,BA9-AZ9-2),"-") -> PP001 | T9: =IFERROR(INDEX(Katalog!$B$4:$B$13,MATCH('Main Data'!S9,Katalog!$C$4:$C$13,0)),"-") -> Kaos Polo | U9: =IFERROR(VLOOKUP(S9,Katalog!$A$15:$B$25,2,0),"-") -> Pakaian Pria | V9: =IFERROR(MID(D9,BB9+2,BC9-BB9-2),0) -> 2 | W9: =IFERROR(MID(D9,BD9+2,BE9-BD9-2),"-") -> 3 | X9: =IFERROR(VLOOKUP(S9,Katalog!$C$3:$F$13,2,0),0) -> 80000 | Y9: =IFERROR(VLOOKUP(S9,Katalog!$C$3:$F$13,3,0),0) -> 30000 | Z9: =H9+O9+V9 -> 7 | AA9: =J9*H9+Q9*O9+X9*V9 -> 740000 | AB9: =K9*H9+R9*O9+Y9*V9 -> 335000 | AC9: - | AD9: =IFERROR(VLOOKUP(AC9,'Kode Diskon'!$C$2:$D$9,2,0),0) -> 0 | AE9: =AA9*AD9 -> 0 | AF9: =AA9-AE9 -> 740000 | AG9: =AA9-AB9 -> 405000 | AH9: =AF9-AB9 -> 405000 | AI9: - | AJ9: Tokopedia | AK9: =IFERROR(VLOOKUP(AJ9,'Guide '!$A$13:$B$16,2,0),"-") -> TK | AL9: Jabodetabek | AM9: 45295 | AN9: =FIND(":",D9,AT9+1) -> 29 | AO9: =FIND(",",D9,AU9+1) -> 32 | AP9: =FIND(":",D9,AN9+1) -> 40 | AQ9: =FIND("}",D9,AO9+1) -> 43 | AR9: =IFERROR(FIND(":",D9,AP9+1),"-") -> 56 | AS9: =IFERROR(FIND(",",D9,AQ9+2),"-") -> 63 | AT9: =FIND(":",D9) -> 12 | AU9: =FIND(",",D9) -> 19 | AV9: =IFERROR(FIND(":",D9,AR9+1),"-") -> 73 | AW9: =IFERROR(FIND(",",D9,AS9+1),"-") -> 76 | AX9: =IFERROR(FIND(":",D9,AV9+1),"-") -> 84 | AY9: =IFERROR(FIND("}",D9,AW9+1),"-") -> 87 | AZ9: =IFERROR(FIND(":",D9,AX9+1),"-") -> 100 | BA9: =IFERROR(FIND(",",D9,AY9+2),"-") -> 107 | BB9: =IFERROR(FIND(":",D9,AZ9+1),"-") -> 117 | BC9: =IFERROR(FIND(",",D9,BA9+1),"-") -> 120 | BD9: =IFERROR(FIND(":",D9,BB9+1),"-") -> 128 | BE9: =IFERROR(FIND("}",D9,BC9+1),"-") -> 131
A10: 69 | B10: =TEXT(A10,"0000") -> 0069 | C10: =CONCATENATE("ORD","-",AK10,"-",B10,"-",TEXT(AM10,"dd/mm/yy")) -> ORD-TK-0069-04/01/24 | D10: [{item_code: PW002, quantity: 4, rating: 5}, {item_code: PP003, quantity: 3, rating: 1}] | E10: =MID(D10,AT10+2,AU10-AT10-2) -> PW002 | F10: =INDEX(Katalog!$B$4:$B$13,MATCH('Main Data'!E10,Katalog!$C$4:$C$13,0)) -> Blouse | G10: =VLOOKUP(E10,Katalog!$A$15:$B$25,2,0) -> Pakaian Wanita | H10: =MID(D10,AN10+2,AO10-AN10-2) -> 4 | I10: =MID(D10,AP10+2,AQ10-AP10-2) -> 5 | J10: =VLOOKUP(E10,Katalog!$C$3:$F$13,2,0) -> 125000 | K10: =VLOOKUP(E10,Katalog!$C$3:$F$13,3,0) -> 50000 | L10: =IFERROR(MID(D10,AR10+2,AS10-AR10-2),"-") -> PP003 | M10: =IFERROR(INDEX(Katalog!$B$4:$B$13,MATCH('Main Data'!L10,Katalog!$C$4:$C$13,0)), "-") -> Jaket Jeans | N10: =IFERROR(VLOOKUP(L10,Katalog!$A$15:$B$25,2,0),"-") -> Pakaian Pria | O10: =IFERROR(MID(D10,AV10+2,AW10-AV10-2),0) -> 3 | P10: =IFERROR(MID(D10,AX10+2,AY10-AX10-2),"-") -> 1 | Q10: =IFERROR(VLOOKUP(L10,Katalog!$C$3:$F$13,2,0),0) -> 150000 | R10: =IFERROR(VLOOKUP(L10,Katalog!$C$3:$F$13,3,0),0) -> 70000 | S10: =IFERROR(MID(D10,AZ10+2,BA10-AZ10-2),"-") -> - | T10: =IFERROR(INDEX(Katalog!$B$4:$B$13,MATCH('Main Data'!S10,Katalog!$C$4:$C$13,0)),"-") -> - | U10: =IFERROR(VLOOKUP(S10,Katalog!$A$15:$B$25,2,0),"-") -> - | V10: =IFERROR(MID(D10,BB10+2,BC10-BB10-2),0) -> 0 | W10: =IFERROR(MID(D10,BD10+2,BE10-BD10-2),"-") -> - | X10: =IFERROR(VLOOKUP(S10,Katalog!$C$3:$F$13,2,0),0) -> 0 | Y10: =IFERROR(VLOOKUP(S10,Katalog!$C$3:$F$13,3,0),0) -> 0 | Z10: =H10+O10+V10 -> 7 | AA10: =J10*H10+Q10*O10+X10*V10 -> 950000 | AB10: =K10*H10+R10*O10+Y10*V10 -> 410000 | AC10: LEBAR10 | AD10: =IFERROR(VLOOKUP(AC10,'Kode Diskon'!$C$2:$D$9,2,0),0) -> 0.1 | AE10: =AA10*AD10 -> 95000 | AF10: =AA10-AE10 -> 855000 | AG10: =AA10-AB10 -> 540000 | AH10: =AF10-AB10 -> 445000 | AI10: Promo Lebaran | AJ10: Tokopedia | AK10: =IFERROR(VLOOKUP(AJ10,'Guide '!$A$13:$B$16,2,0),"-") -> TK | AL10: Jawa Tengah | AM10: 45295 | AN10: =FIND(":",D10,AT10+1) -> 29 | AO10: =FIND(",",D10,AU10+1) -> 32 | AP10: =FIND(":",D10,AN10+1) -> 40 | AQ10: =FIND("}",D10,AO10+1) -> 43 | AR10: =IFERROR(FIND(":",D10,AP10+1),"-") -> 56 | AS10: =IFERROR(FIND(",",D10,AQ10+2),"-") -> 63 | AT10: =FIND(":",D10) -> 12 | AU10: =FIND(",",D10) -> 19 | AV10: =IFERROR(FIND(":",D10,AR10+1),"-") -> 73 | AW10: =IFERROR(FIND(",",D10,AS10+1),"-") -> 76 | AX10: =IFERROR(FIND(":",D10,AV10+1),"-") -> 84 | AY10: =IFERROR(FIND("}",D10,AW10+1),"-") -> 87 | AZ10: =IFERROR(FIND(":",D10,AX10+1),"-") -> - | BA10: =IFERROR(FIND(",",D10,AY10+2),"-") -> - | BB10: =IFERROR(FIND(":",D10,AZ10+1),"-") -> - | BC10: =IFERROR(FIND(",",D10,BA10+1),"-") -> - | BD10: =IFERROR(FIND(":",D10,BB10+1),"-") -> - | BE10: =IFERROR(FIND("}",D10,BC10+1),"-") -> -
A11: 317 | B11: =TEXT(A11,"0000") -> 0317 | C11: =CONCATENATE("ORD","-",AK11,"-",B11,"-",TEXT(AM11,"dd/mm/yy")) -> ORD-SP-0317-04/01/24 | D11: [{item_code: PP001, quantity: 6, rating: 1}] | E11: =MID(D11,AT11+2,AU11-AT11-2) -> PP001 | F11: =INDEX(Katalog!$B$4:$B$13,MATCH('Main Data'!E11,Katalog!$C$4:$C$13,0)) -> Kaos Polo | G11: =VLOOKUP(E11,Katalog!$A$15:$B$25,2,0) -> Pakaian Pria | H11: =MID(D11,AN11+2,AO11-AN11-2) -> 6 | I11: =MID(D11,AP11+2,AQ11-AP11-2) -> 1 | J11: =VLOOKUP(E11,Katalog!$C$3:$F$13,2,0) -> 80000 | K11: =VLOOKUP(E11,Katalog!$C$3:$F$13,3,0) -> 30000 | L11: =IFERROR(MID(D11,AR11+2,AS11-AR11-2),"-") -> - | M11: =IFERROR(INDEX(Katalog!$B$4:$B$13,MATCH('Main Data'!L11,Katalog!$C$4:$C$13,0)), "-") -> - | N11: =IFERROR(VLOOKUP(L11,Katalog!$A$15:$B$25,2,0),"-") -> - | O11: =IFERROR(MID(D11,AV11+2,AW11-AV11-2),0) -> 0 | P11: =IFERROR(MID(D11,AX11+2,AY11-AX11-2),"-") -> - | Q11: =IFERROR(VLOOKUP(L11,Katalog!$C$3:$F$13,2,0),0) -> 0 | R11: =IFERROR(VLOOKUP(L11,Katalog!$C$3:$F$13,3,0),0) -> 0 | S11: =IFERROR(MID(D11,AZ11+2,BA11-AZ11-2),"-") -> - | T11: =IFERROR(INDEX(Katalog!$B$4:$B$13,MATCH('Main Data'!S11,Katalog!$C$4:$C$13,0)),"-") -> - | U11: =IFERROR(VLOOKUP(S11,Katalog!$A$15:$B$25,2,0),"-") -> - | V11: =IFERROR(MID(D11,BB11+2,BC11-BB11-2),0) -> 0 | W11: =IFERROR(MID(D11,BD11+2,BE11-BD11-2),"-") -> - | X11: =IFERROR(VLOOKUP(S11,Katalog!$C$3:$F$13,2,0),0) -> 0 | Y11: =IFERROR(VLOOKUP(S11,Katalog!$C$3:$F$13,3,0),0) -> 0 | Z11: =H11+O11+V11 -> 6 | AA11: =J11*H11+Q11*O11+X11*V11 -> 480000 | AB11: =K11*H11+R11*O11+Y11*V11 -> 180000 | AC11: DISC20 | AD11: =IFERROR(VLOOKUP(AC11,'Kode Diskon'!$C$2:$D$9,2,0),0) -> 0.2 | AE11: =AA11*AD11 -> 96000 | AF11: =AA11-AE11 -> 384000 | AG11: =AA11-AB11 -> 300000 | AH11: =AF11-AB11 -> 204000 | AI11: Promo Lebaran | AJ11: Shopee | AK11: =IFERROR(VLOOKUP(AJ11,'Guide '!$A$13:$B$16,2,0),"-") -> SP | AL11: Jawa Timur | AM11: 45295 | AN11: =FIND(":",D11,AT11+1) -> 29 | AO11: =FIND(",",D11,AU11+1) -> 32 | AP11: =FIND(":",D11,AN11+1) -> 40 | AQ11: =FIND("}",D11,AO11+1) -> 43 | AR11: =IFERROR(FIND(":",D11,AP11+1),"-") -> - | AS11: =IFERROR(FIND(",",D11,AQ11+2),"-") -> - | AT11: =FIND(":",D11) -> 12 | AU11: =FIND(",",D11) -> 19 | AV11: =IFERROR(FIND(":",D11,AR11+1),"-") -> - | AW11: =IFERROR(FIND(",",D11,AS11+1),"-") -> - | AX11: =IFERROR(FIND(":",D11,AV11+1),"-") -> - | AY11: =IFERROR(FIND("}",D11,AW11+1),"-") -> - | AZ11: =IFERROR(FIND(":",D11,AX11+1),"-") -> - | BA11: =IFERROR(FIND(",",D11,AY11+2),"-") -> - | BB11: =IFERROR(FIND(":",D11,AZ11+1),"-") -> - | BC11: =IFERROR(FIND(",",D11,BA11+1),"-") -> - | BD11: =IFERROR(FIND(":",D11,BB11+1),"-") -> - | BE11: =IFERROR(FIND("}",D11,BC11+1),"-") -> -
A12: 691 | B12: =TEXT(A12,"0000") -> 0691 | C12: =CONCATENATE("ORD","-",AK12,"-",B12,"-",TEXT(AM12,"dd/mm/yy")) -> ORD-SP-0691-04/01/24 | D12: [{item_code: PW003, quantity: 3, rating: 4}, {item_code: SP001, quantity: 3, rating: 3}, {item_code: PW001, quantity: 1, rating: 2}] | E12: =MID(D12,AT12+2,AU12-AT12-2) -> PW003 | F12: =INDEX(Katalog!$B$4:$B$13,MATCH('Main Data'!E12,Katalog!$C$4:$C$13,0)) -> Kaftan | G12: =VLOOKUP(E12,Katalog!$A$15:$B$25,2,0) -> Pakaian Wanita | H12: =MID(D12,AN12+2,AO12-AN12-2) -> 3 | I12: =MID(D12,AP12+2,AQ12-AP12-2) -> 4 | J12: =VLOOKUP(E12,Katalog!$C$3:$F$13,2,0) -> 200000 | K12: =VLOOKUP(E12,Katalog!$C$3:$F$13,3,0) -> 100000 | L12: =IFERROR(MID(D12,AR12+2,AS12-AR12-2),"-") -> SP001 | M12: =IFERROR(INDEX(Katalog!$B$4:$B$13,MATCH('Main Data'!L12,Katalog!$C$4:$C$13,0)), "-") -> Sneakers | N12: =IFERROR(VLOOKUP(L12,Katalog!$A$15:$B$25,2,0),"-") -> Sepatu Pria | O12: =IFERROR(MID(D12,AV12+2,AW12-AV12-2),0) -> 3 | P12: =IFERROR(MID(D12,AX12+2,AY12-AX12-2),"-") -> 3 | Q12: =IFERROR(VLOOKUP(L12,Katalog!$C$3:$F$13,2,0),0) -> 300000 | R12: =IFERROR(VLOOKUP(L12,Katalog!$C$3:$F$13,3,0),0) -> 100000 | S12: =IFERROR(MID(D12,AZ12+2,BA12-AZ12-2),"-") -> PW001 | T12: =IFERROR(INDEX(Katalog!$B$4:$B$13,MATCH('Main Data'!S12,Katalog!$C$4:$C$13,0)),"-") -> Dress | U12: =IFERROR(VLOOKUP(S12,Katalog!$A$15:$B$25,2,0),"-") -> Pakaian Wanita | V12: =IFERROR(MID(D12,BB12+2,BC12-BB12-2),0) -> 1 | W12: =IFERROR(MID(D12,BD12+2,BE12-BD12-2),"-") -> 2 | X12: =IFERROR(VLOOKUP(S12,Katalog!$C$3:$F$13,2,0),0) -> 150000 | Y12: =IFERROR(VLOOKUP(S12,Katalog!$C$3:$F$13,3,0),0) -> 55000 | Z12: =H12+O12+V12 -> 7 | AA12: =J12*H12+Q12*O12+X12*V12 -> 1650000 | AB12: =K12*H12+R12*O12+Y12*V12 -> 655000 | AC12: DISC15 | AD12: =IFERROR(VLOOKUP(AC12,'Kode Diskon'!$C$2:$D$9,2,0),0) -> 0.15 | AE12: =AA12*AD12 -> 247500 | AF12: =AA12-AE12 -> 1402500 | AG12: =AA12-AB12 -> 995000 | AH12: =AF12-AB12 -> 747500 | AI12: Promo 4.4 | AJ12: Shopee | AK12: =IFERROR(VLOOKUP(AJ12,'Guide '!$A$13:$B$16,2,0),"-") -> SP | AL12: Jawa Tengah | AM12: 45295 | AN12: =FIND(":",D12,AT12+1) -> 29 | AO12: =FIND(",",D12,AU12+1) -> 32 | AP12: =FIND(":",D12,AN12+1) -> 40 | AQ12: =FIND("}",D12,AO12+1) -> 43 | AR12: =IFERROR(FIND(":",D12,AP12+1),"-") -> 56 | AS12: =IFERROR(FIND(",",D12,AQ12+2),"-") -> 63 | AT12: =FIND(":",D12) -> 12 | AU12: =FIND(",",D12) -> 19 | AV12: =IFERROR(FIND(":",D12,AR12+1),"-") -> 73 | AW12: =IFERROR(FIND(",",D12,AS12+1),"-") -> 76 | AX12: =IFERROR(FIND(":",D12,AV12+1),"-") -> 84 | AY12: =IFERROR(FIND("}",D12,AW12+1),"-") -> 87 | AZ12: =IFERROR(FIND(":",D12,AX12+1),"-") -> 100 | BA12: =IFERROR(FIND(",",D12,AY12+2),"-") -> 107 | BB12: =IFERROR(FIND(":",D12,AZ12+1),"-") -> 117 | BC12: =IFERROR(FIND(",",D12,BA12+1),"-") -> 120 | BD12: =IFERROR(FIND(":",D12,BB12+1),"-") -> 128 | BE12: =IFERROR(FIND("}",D12,BC12+1),"-") -> 131
A13: 305 | B13: =TEXT(A13,"0000") -> 0305 | C13: =CONCATENATE("ORD","-",AK13,"-",B13,"-",TEXT(AM13,"dd/mm/yy")) -> ORD-SP-0305-05/01/24 | D13: [{item_code: PP002, quantity: 1, rating: 2}, {item_code: PW003, quantity: 4, rating: 3}] | E13: =MID(D13,AT13+2,AU13-AT13-2) -> PP002 | F13: =INDEX(Katalog!$B$4:$B$13,MATCH('Main Data'!E13,Katalog!$C$4:$C$13,0)) -> Celana Pendek | G13: =VLOOKUP(E13,Katalog!$A$15:$B$25,2,0) -> Pakaian Pria | H13: =MID(D13,AN13+2,AO13-AN13-2) -> 1 | I13: =MID(D13,AP13+2,AQ13-AP13-2) -> 2 | J13: =VLOOKUP(E13,Katalog!$C$3:$F$13,2,0) -> 60000 | K13: =VLOOKUP(E13,Katalog!$C$3:$F$13,3,0) -> 25000 | L13: =IFERROR(MID(D13,AR13+2,AS13-AR13-2),"-") -> PW003 | M13: =IFERROR(INDEX(Katalog!$B$4:$B$13,MATCH('Main Data'!L13,Katalog!$C$4:$C$13,0)), "-") -> Kaftan | N13: =IFERROR(VLOOKUP(L13,Katalog!$A$15:$B$25,2,0),"-") -> Pakaian Wanita | O13: =IFERROR(MID(D13,AV13+2,AW13-AV13-2),0) -> 4 | P13: =IFERROR(MID(D13,AX13+2,AY13-AX13-2),"-") -> 3 | Q13: =IFERROR(VLOOKUP(L13,Katalog!$C$3:$F$13,2,0),0) -> 200000 | R13: =IFERROR(VLOOKUP(L13,Katalog!$C$3:$F$13,3,0),0) -> 100000 | S13: =IFERROR(MID(D13,AZ13+2,BA13-AZ13-2),"-") -> - | T13: =IFERROR(INDEX(Katalog!$B$4:$B$13,MATCH('Main Data'!S13,Katalog!$C$4:$C$13,0)),"-") -> - | U13: =IFERROR(VLOOKUP(S13,Katalog!$A$15:$B$25,2,0),"-") -> - | V13: =IFERROR(MID(D13,BB13+2,BC13-BB13-2),0) -> 0 | W13: =IFERROR(MID(D13,BD13+2,BE13-BD13-2),"-") -> - | X13: =IFERROR(VLOOKUP(S13,Katalog!$C$3:$F$13,2,0),0) -> 0 | Y13: =IFERROR(VLOOKUP(S13,Katalog!$C$3:$F$13,3,0),0) -> 0 | Z13: =H13+O13+V13 -> 5 | AA13: =J13*H13+Q13*O13+X13*V13 -> 860000 | AB13: =K13*H13+R13*O13+Y13*V13 -> 425000 | AC13: DISC10 | AD13: =IFERROR(VLOOKUP(AC13,'Kode Diskon'!$C$2:$D$9,2,0),0) -> 0.1 | AE13: =AA13*AD13 -> 86000 | AF13: =AA13-AE13 -> 774000 | AG13: =AA13-AB13 -> 435000 | AH13: =AF13-AB13 -> 349000 | AI13: Promo 4.4 | AJ13: Shopee | AK13: =IFERROR(VLOOKUP(AJ13,'Guide '!$A$13:$B$16,2,0),"-") -> SP | AL13: Jawa Timur | AM13: 45296 | AN13: =FIND(":",D13,AT13+1) -> 29 | AO13: =FIND(",",D13,AU13+1) -> 32 | AP13: =FIND(":",D13,AN13+1) -> 40 | AQ13: =FIND("}",D13,AO13+1) -> 43 | AR13: =IFERROR(FIND(":",D13,AP13+1),"-") -> 56 | AS13: =IFERROR(FIND(",",D13,AQ13+2),"-") -> 63 | AT13: =FIND(":",D13) -> 12 | AU13: =FIND(",",D13) -> 19 | AV13: =IFERROR(FIND(":",D13,AR13+1),"-") -> 73 | AW13: =IFERROR(FIND(",",D13,AS13+1),"-") -> 76 | AX13: =IFERROR(FIND(":",D13,AV13+1),"-") -> 84 | AY13: =IFERROR(FIND("}",D13,AW13+1),"-") -> 87 | AZ13: =IFERROR(FIND(":",D13,AX13+1),"-") -> - | BA13: =IFERROR(FIND(",",D13,AY13+2),"-") -> - | BB13: =IFERROR(FIND(":",D13,AZ13+1),"-") -> - | BC13: =IFERROR(FIND(",",D13,BA13+1),"-") -> - | BD13: =IFERROR(FIND(":",D13,BB13+1),"-") -> - | BE13: =IFERROR(FIND("}",D13,BC13+1),"-") -> -
A14: 632 | B14: =TEXT(A14,"0000") -> 0632 | C14: =CONCATENATE("ORD","-",AK14,"-",B14,"-",TEXT(AM14,"dd/mm/yy")) -> ORD-SP-0632-05/01/24 | D14: [{item_code: PW003, quantity: 1, rating: 4}, {item_code: PW001, quantity: 3, rating: 2}] | E14: =MID(D14,AT14+2,AU14-AT14-2) -> PW003 | F14: =INDEX(Katalog!$B$4:$B$13,MATCH('Main Data'!E14,Katalog!$C$4:$C$13,0)) -> Kaftan | G14: =VLOOKUP(E14,Katalog!$A$15:$B$25,2,0) -> Pakaian Wanita | H14: =MID(D14,AN14+2,AO14-AN14-2) -> 1 | I14: =MID(D14,AP14+2,AQ14-AP14-2) -> 4 | J14: =VLOOKUP(E14,Katalog!$C$3:$F$13,2,0) -> 200000 | K14: =VLOOKUP(E14,Katalog!$C$3:$F$13,3,0) -> 100000 | L14: =IFERROR(MID(D14,AR14+2,AS14-AR14-2),"-") -> PW001 | M14: =IFERROR(INDEX(Katalog!$B$4:$B$13,MATCH('Main Data'!L14,Katalog!$C$4:$C$13,0)), "-") -> Dress | N14: =IFERROR(VLOOKUP(L14,Katalog!$A$15:$B$25,2,0),"-") -> Pakaian Wanita | O14: =IFERROR(MID(D14,AV14+2,AW14-AV14-2),0) -> 3 | P14: =IFERROR(MID(D14,AX14+2,AY14-AX14-2),"-") -> 2 | Q14: =IFERROR(VLOOKUP(L14,Katalog!$C$3:$F$13,2,0),0) -> 150000 | R14: =IFERROR(VLOOKUP(L14,Katalog!$C$3:$F$13,3,0),0) -> 55000 | S14: =IFERROR(MID(D14,AZ14+2,BA14-AZ14-2),"-") -> - | T14: =IFERROR(INDEX(Katalog!$B$4:$B$13,MATCH('Main Data'!S14,Katalog!$C$4:$C$13,0)),"-") -> - | U14: =IFERROR(VLOOKUP(S14,Katalog!$A$15:$B$25,2,0),"-") -> - | V14: =IFERROR(MID(D14,BB14+2,BC14-BB14-2),0) -> 0 | W14: =IFERROR(MID(D14,BD14+2,BE14-BD14-2),"-") -> - | X14: =IFERROR(VLOOKUP(S14,Katalog!$C$3:$F$13,2,0),0) -> 0 | Y14: =IFERROR(VLOOKUP(S14,Katalog!$C$3:$F$13,3,0),0) -> 0 | Z14: =H14+O14+V14 -> 4 | AA14: =J14*H14+Q14*O14+X14*V14 -> 650000 | AB14: =K14*H14+R14*O14+Y14*V14 -> 265000 | AC14: DISC20 | AD14: =IFERROR(VLOOKUP(AC14,'Kode Diskon'!$C$2:$D$9,2,0),0) -> 0.2 | AE14: =AA14*AD14 -> 130000 | AF14: =AA14-AE14 -> 520000 | AG14: =AA14-AB14 -> 385000 | AH14: =AF14-AB14 -> 255000 | AI14: Promo Lebaran | AJ14: Shopee | AK14: =IFERROR(VLOOKUP(AJ14,'Guide '!$A$13:$B$16,2,0),"-") -> SP | AL14: Jabodetabek | AM14: 45296 | AN14: =FIND(":",D14,AT14+1) -> 29 | AO14: =FIND(",",D14,AU14+1) -> 32 | AP14: =FIND(":",D14,AN14+1) -> 40 | AQ14: =FIND("}",D14,AO14+1) -> 43 | AR14: =IFERROR(FIND(":",D14,AP14+1),"-") -> 56 | AS14: =IFERROR(FIND(",",D14,AQ14+2),"-") -> 63 | AT14: =FIND(":",D14) -> 12 | AU14: =FIND(",",D14) -> 19 | AV14: =IFERROR(FIND(":",D14,AR14+1),"-") -> 73 | AW14: =IFERROR(FIND(",",D14,AS14+1),"-") -> 76 | AX14: =IFERROR(FIND(":",D14,AV14+1),"-") -> 84 | AY14: =IFERROR(FIND("}",D14,AW14+1),"-") -> 87 | AZ14: =IFERROR(FIND(":",D14,AX14+1),"-") -> - | BA14: =IFERROR(FIND(",",D14,AY14+2),"-") -> - | BB14: =IFERROR(FIND(":",D14,AZ14+1),"-") -> - | BC14: =IFERROR(FIND(",",D14,BA14+1),"-") -> - | BD14: =IFERROR(FIND(":",D14,BB14+1),"-") -> - | BE14: =IFERROR(FIND("}",D14,BC14+1),"-") -> -
... A1002: 793 | B1002: =TEXT(A1002,"0000") -> 0793 | C1002: =CONCATENATE("ORD","-",AK1002,"-",B1002,"-",TEXT(AM1002,"dd/mm/yy")) -> ORD-BL-0793-31/12/24 | D1002: [{item_code: SW001, quantity: 2, rating: 2}] | E1002: =MID(D1002,AT1002+2,AU1002-AT1002-2) -> SW001 | F1002: =INDEX(Katalog!$B$4:$B$13,MATCH('Main Data'!E1002,Katalog!$C$4:$C$13,0)) -> Flat Shoes | G1002: =VLOOKUP(E1002,Katalog!$A$15:$B$25,2,0) -> Sepatu Wanita | H1002: =MID(D1002,AN1002+2,AO1002-AN1002-2) -> 2 | I1002: =MID(D1002,AP1002+2,AQ1002-AP1002-2) -> 2 | J1002: =VLOOKUP(E1002,Katalog!$C$3:$F$13,2,0) -> 150000 | K1002: =VLOOKUP(E1002,Katalog!$C$3:$F$13,3,0) -> 70000 | L1002: =IFERROR(MID(D1002,AR1002+2,AS1002-AR1002-2),"-") -> - | M1002: =IFERROR(INDEX(Katalog!$B$4:$B$13,MATCH('Main Data'!L1002,Katalog!$C$4:$C$13,0)), "-") -> - | N1002: =IFERROR(VLOOKUP(L1002,Katalog!$A$15:$B$25,2,0),"-") -> - | O1002: =IFERROR(MID(D1002,AV1002+2,AW1002-AV1002-2),0) -> 0 | P1002: =IFERROR(MID(D1002,AX1002+2,AY1002-AX1002-2),"-") -> - | Q1002: =IFERROR(VLOOKUP(L1002,Katalog!$C$3:$F$13,2,0),0) -> 0 | R1002: =IFERROR(VLOOKUP(L1002,Katalog!$C$3:$F$13,3,0),0) -> 0 | S1002: =IFERROR(MID(D1002,AZ1002+2,BA1002-AZ1002-2),"-") -> - | T1002: =IFERROR(INDEX(Katalog!$B$4:$B$13,MATCH('Main Data'!S1002,Katalog!$C$4:$C$13,0)),"-") -> - | U1002: =IFERROR(VLOOKUP(S1002,Katalog!$A$15:$B$25,2,0),"-") -> - | V1002: =IFERROR(MID(D1002,BB1002+2,BC1002-BB1002-2),0) -> 0 | W1002: =IFERROR(MID(D1002,BD1002+2,BE1002-BD1002-2),"-") -> - | X1002: =IFERROR(VLOOKUP(S1002,Katalog!$C$3:$F$13,2,0),0) -> 0 | Y1002: =IFERROR(VLOOKUP(S1002,Katalog!$C$3:$F$13,3,0),0) -> 0 | Z1002: =H1002+O1002+V1002 -> 2 | AA1002: =J1002*H1002+Q1002*O1002+X1002*V1002 -> 300000 | AB1002: =K1002*H1002+R1002*O1002+Y1002*V1002 -> 140000 | AC1002: BUKALEBAR | AD1002: =IFERROR(VLOOKUP(AC1002,'Kode Diskon'!$C$2:$D$9,2,0),0) -> 0.15 | AE1002: =AA1002*AD1002 -> 45000 | AF1002: =AA1002-AE1002 -> 255000 | AG1002: =AA1002-AB1002 -> 160000 | AH1002: =AF1002-AB1002 -> 115000 | AI1002: Promo Lebaran | AJ1002: Bukalapak | AK1002: =IFERROR(VLOOKUP(AJ1002,'Guide '!$A$13:$B$16,2,0),"-") -> BL | AL1002: Jawa Timur | AM1002: 45657 | AN1002: =FIND(":",D1002,AT1002+1) -> 29 | AO1002: =FIND(",",D1002,AU1002+1) -> 32 | AP1002: =FIND(":",D1002,AN1002+1) -> 40 | AQ1002: =FIND("}",D1002,AO1002+1) -> 43 | AR1002: =IFERROR(FIND(":",D1002,AP1002+1),"-") -> - | AS1002: =IFERROR(FIND(",",D1002,AQ1002+2),"-") -> - | AT1002: =FIND(":",D1002) -> 12 | AU1002: =FIND(",",D1002) -> 19 | AV1002: =IFERROR(FIND(":",D1002,AR1002+1),"-") -> - | AW1002: =IFERROR(FIND(",",D1002,AS1002+1),"-") -> - | AX1002: =IFERROR(FIND(":",D1002,AV1002+1),"-") -> - | AY1002: =IFERROR(FIND("}",D1002,AW1002+1),"-") -> - | AZ1002: =IFERROR(FIND(":",D1002,AX1002+1),"-") -> - | BA1002: =IFERROR(FIND(",",D1002,AY1002+2),"-") -> - | BB1002: =IFERROR(FIND(":",D1002,AZ1002+1),"-") -> - | BC1002: =IFERROR(FIND(",",D1002,BA1002+1),"-") -> - | BD1002: =IFERROR(FIND(":",D1002,BB1002+1),"-") -> - | BE1002: =IFERROR(FIND("}",D1002,BC1002+1),"-") -> -

Sheet Pivot Table
A1: Sum of Total Qty | B1: Sum of Laba (Descount) | D1: Sum of Total Modal | E1: Sum of Total Transaksi | H1: Row Labels | I1: Sum of Total Transaksi | J1: Sum of Total Qty
A2: 4080 | B2: 284175250 | D2: 251530000 | E2: 607450000 | H2: Banten | I2: 61395000 | J2: 394 | M2: Row Labels | N2: Sum of Total Transaksi
H3: Jabodetabek | I3: 216340000 | J3: 1421 | M3: BliBli | N3: 5605000
H4: Jawa Barat | I4: 37200000 | J4: 266 | M4: Bukalapak | N4: 5855000
A5: Row Labels | B5: Sum of Total Transaksi | D5: Row Labels | E5: Sum of Total Qty | H5: Jawa Tengah | I5: 92640000 | J5: 645 | M5: Shopee | N5: 23470000
A6: BliBli | B6: 93190000 | D6: BliBli | E6: 0.14852941 | H6: Jawa Timur | I6: 92725000 | J6: 643 | M6: Tokopedia | N6: 12885000
A7: Bukalapak | B7: 83220000 | D7: Bukalapak | E7: 0.14215686 | H7: Yogyakarta | I7: 107150000 | J7: 711 | M7: Grand Total | N7: 47815000
A8: Shopee | B8: 259575000 | D8: Shopee | E8: 0.42769608 | H8: Grand Total | I8: 607450000 | J8: 4080
A9: Tokopedia | B9: 171465000 | D9: Tokopedia | E9: 0.28161765 | N9: Sum of Total Qty | O9: Sum of Total Transaksi
A10: Grand Total | B10: 607450000 | D10: Grand Total | E10: 1 | M10: Jan | N10: 334 | O10: 47815000
M11: 45292 | N11: 10 | O11: 1055000
M12: 45293 | N12: 12 | O12: 1105000
E13: Row Labels | F13: Sum of Total Transaksi | M13: 45294 | N13: 7 | O13: 720000
E14: Jawa Barat | F14: 37200000 | M14: 45295 | N14: 27 | O14: 3820000
E15: Banten | F15: 61395000 | M15: 45296 | N15: 9 | O15: 1510000
E16: Jawa Tengah | F16: 92640000 | M16: 45297 | N16: 8 | O16: 1150000
E17: Jawa Timur | F17: 92725000 | M17: 45299 | N17: 30 | O17: 4470000
E18: Yogyakarta | F18: 107150000 | M18: 45300 | N18: 11 | O18: 1570000
A19: Penjulan terbanyak | B19: Sum of Total Transaksi | E19: Jabodetabek | F19: 216340000 | M19: 45301 | N19: 9 | O19: 1435000
A20: Kaos Polo | B20: 41130000 | E20: Grand Total | F20: 607450000 | M20: 45302 | N20: 24 | O20: 4180000
A21: Celana Pendek | B21: 42970000 | M21: 45303 | N21: 12 | O21: 1040000
A22: Flat Shoes | B22: 55015000 | M22: 45305 | N22: 4 | O22: 525000
A23: Blouse | B23: 55015000 | M23: 45306 | N23: 2 | O23: 360000
A24: Dress | B24: 56560000 | M24: 45307 | N24: 9 | O24: 1040000
A25: Kaftan | B25: 57450000 | M25: 45308 | N25: 11 | O25: 1610000
A26: Sandal Slip On | B26: 59570000 | M26: 45309 | N26: 4 | O26: 560000
A27: Jaket Hoodie | B27: 64260000 | M27: 45310 | N27: 17 | O27: 2055000
A28: Jaket Jeans | B28: 75140000 | M28: 45312 | N28: 9 | O28: 1020000
A29: Sneakers | B29: 100340000 | H29: Sum of Total Transaksi | M29: 45313 | N29: 7 | O29: 950000
A30: Grand Total | B30: 607450000 | G30: Banten | H30: 6285000 | M30: 45314 | N30: 13 | O30: 2570000
G31: Yogyakarta | H31: 3995000 | M31: 45315 | N31: 23 | O31: 3150000
G32: Jabodetabek | H32: 16205000 | M32: 45316 | N32: 23 | O32: 4565000
G33: Jawa Barat | H33: 1620000 | M33: 45317 | N33: 21 | O33: 2945000
G34: Jawa Tengah | H34: 8610000 | M34: 45319 | N34: 6 | O34: 930000
G35: Jawa Timur | H35: 11100000 | M35: 45320 | N35: 6 | O35: 800000
G36: Grand Total | H36: 47815000 | M36: 45321 | N36: 10 | O36: 1285000
M37: 45322 | N37: 10 | O37: 1395000
M38: Feb | N38: 339 | O38: 53475000
H39: 8 | M39: 45323 | N39: 13 | O39: 1990000
A40: Sum of Total Modal | B40: Sum of Laba | C40: Sum of Laba (Descount) | D40: Sum of Potongan Diskon | M40: 45324 | N40: 5 | O40: 460000
...

Sheet Dashboard FIX
AR32: ='Dashboard FIX'!AW21 -> 0

Sheet Nama_Kelompok
A1: No | B1: Nama Kelompok
A2: 1 | B2: Muladi Ajisasmito
A3: 2 | B3: Ruly Nurhendri
A4: 3 | B4: Maulana Yahya
A5: 4 | B5: Gayatri Apsarini Hisanah
